Workbook

Sheet 1__Matriz_ASR
B1: Matriz ASR: identificación y especificación
A5: Trazabilidad | E5: Requisito | I5: Escenario de calidad (6 partes) | O5: Impacto en la arquitectura | Q5: Priorización (solo 2 ejes) | S5: Dictamen y verificación | W5: Enrutamiento automático
A6: ID | B6: Nombre corto del escenario | C6: Stakeholder | D6: Evidencia o fuente | E6: Tipo de requisito | F6: Requisito base (enunciado verificable) | G6: Característica de calidad (ISO/IEC 25010) | H6: Subcaracterística o concern | I6: 1. Fuente | J6: 2. Estímulo | K6: 3. Entorno | L6: 4. Artefacto | M6: 5. Respuesta | N6: 6. Medida de la respuesta | O6: Elemento arquitectónico afectado | P6: Decisión o cambio que obliga | Q6: Valor de negocio (VN) | R6: Impacto y dificultad arquitectónica (IA) | S6: Dictamen ASR | T6: Justificación del dictamen | U6: Método de verificación | V6: Trazabilidad | W6: ¿A dónde va este ASR? | X6: Campos diligenciados
A7: ASR-01 | B7: Autenticación con segundo factor por correo | C7: Administrador, Empleado, Verificador | D7: Documento requerimientos funcionales y no funcionales | E7: Funcional | F7: El sistema debe autenticar al usuario mediante credenciales corporativas y un token de un solo uso enviado al correo, con vigencia de 5 minutos y máximo un reenvío cada 60 segundos. | G7: Seguridad | H7: Autenticidad | I7: Usuario registrado (cualquier rol) | J7: Ingresa correo y contraseña y solicita el token | K7: Operación normal, servidor de correo disponible | L7: Servicio de autenticación (backend) | M7: Envía el token al correo registrado, valida credenciales y token antes de otorgar acceso | N7: El token expira a los 5 min en el 100% de los casos; se permite máximo 1 reenvío cada 60 s; validación del token p95 ≤ 2 s sobre 50 intentos | O7: Componente | P7: Definir el proveedor de correo, el formato y vigencia del token, y el almacenamiento temporal del OTP. | Q7: Alta | R7: Alta | S7: Sí | T7: Es la puerta de entrada a toda la plataforma; sin 2FA no se cumple el modelo de autenticación segura exigido por RNF-002 y define contratos entre el backend y el servicio de correo. | U7: Prueba funcional del flujo completo con 50 intentos y medición del tiempo de expiración y validación del token. | V7: RF-002; RF-003; RF-004; RNF-002 | W7: =IF(OR($E7="",$S7=""),"",IF($S7="No","No es ASR: gestionar fuera de la arquitectura",IF($S7="Por validar","Falta evidencia: conseguirla antes de decidir",IF($E7="Calidad","Va al Utility Tree (hoja 3)",IF($E7="Restricción","Va a Restricciones (hoja 4)","Va a Funciones críticas (hoja 4)"))))) -> Va a Funciones críticas (hoja 4) | X7: =IF(COUNTA($A7:$V7)=0,"",COUNTA($A7:$V7)&"/22") -> 22/22
A8: ASR-02 | B8: Protección de contraseñas con hashing y salt | C8: Administrador, Empleado, Verificador | D8: Documento requerimientos funcionales y no funcionales | E8: Funcional | F8: El sistema debe almacenar las contraseñas usando un algoritmo de hashing seguro con salt y no debe almacenarlas en texto plano. | G8: Seguridad | H8: Confidencialidad e integridad | I8: Usuario que registra o cambia su contraseña | J8: Envía su contraseña a través del formulario de registro o de cambio | K8: Operación normal, cualquier volumen de usuarios | L8: Base de datos de usuarios / servicio de autenticación | M8: Genera el hash con salt antes de persistir la contraseña | N8: 100% de las contraseñas almacenadas quedan como hash con salt, verificado por inspección directa sobre 20 cuentas de prueba; 0 ocurrencias de texto plano | O8: Modelo o almacenamiento de datos | P8: Elegir el algoritmo de hashing (bcrypt o similar), su factor de costo y el manejo del salt. | Q8: Alta | R8: Alta | S8: Sí | T8: Cambiarlo luego exige migración de datos y rotación forzada de credenciales; afecta directamente la persistencia y el servicio de autenticación. | U8: Revisión de código del módulo de autenticación e inspección directa de la colección de usuarios en MongoDB. | V8: RNF-001 | W8: =IF(OR($E8="",$S8=""),"",IF($S8="No","No es ASR: gestionar fuera de la arquitectura",IF($S8="Por validar","Falta evidencia: conseguirla antes de decidir",IF($E8="Calidad","Va al Utility Tree (hoja 3)",IF($E8="Restricción","Va a Restricciones (hoja 4)","Va a Funciones críticas (hoja 4)"))))) -> Va a Funciones críticas (hoja 4) | X8: =IF(COUNTA($A8:$V8)=0,"",COUNTA($A8:$V8)&"/22") -> 22/22
A9: ASR-03 | B9: Bloqueo temporal por intentos fallidos | C9: Administrador, Empleado, Verificador | D9: Documento requerimientos funcionales y no funcionales | E9: Funcional | F9: El sistema debe bloquear temporalmente una cuenta durante 15 minutos tras 5 intentos consecutivos fallidos de autenticación. | G9: Seguridad | H9: Autenticidad y no repudio | I9: Usuario o atacante | J9: Ingresa credenciales incorrectas repetidamente | K9: Operación normal y prueba de fuerza bruta simulada | L9: Servicio de autenticación | M9: Bloquea la cuenta exactamente en el quinto intento fallido y la libera después de 15 min | N9: Bloqueo activado en el intento 5 (±0) con duración de 15 min (±5 s), verificado en 10 ejecuciones consecutivas; registro del intento fallido en 100% de los casos | O9: Componente | P9: Diseñar el contador de intentos con expiración y el registro de los intentos fallidos con correo, fecha, hora y motivo. | Q9: Media | R9: Media | S9: Sí | T9: Mecanismo estándar contra fuerza bruta; se localiza en el servicio de autenticación y en el registro de trazabilidad de accesos definido en RNF-006. | U9: Prueba automatizada de 5 intentos fallidos consecutivos con verificación del tiempo de bloqueo y del registro de intentos. | V9: RF-054; RNF-006 | W9: =IF(OR($E9="",$S9=""),"",IF($S9="No","No es ASR: gestionar fuera de la arquitectura",IF($S9="Por validar","Falta evidencia: conseguirla antes de decidir",IF($E9="Calidad","Va al Utility Tree (hoja 3)",IF($E9="Restricción","Va a Restricciones (hoja 4)","Va a Funciones críticas (hoja 4)"))))) -> Va a Funciones críticas (hoja 4) | X9: =IF(COUNTA($A9:$V9)=0,"",COUNTA($A9:$V9)&"/22") -> 22/22
A10: ASR-04 | B10: Control de acceso basado en roles (RBAC) | C10: Administrador, Empleado, Verificador | D10: Documento requerimientos funcionales y no funcionales | E10: Funcional | F10: El sistema debe aplicar RBAC de forma que cada usuario acceda únicamente a las funcionalidades y datos autorizados para su rol (Administrador, Empleado o Verificador). | G10: Seguridad | H10: Confidencialidad y control de acceso | I10: Cualquier usuario autenticado | J10: Intenta acceder a una ruta o endpoint protegido | K10: Operación normal con los tres roles existentes | L10: Backend / capa de autorización | M10: Permite o rechaza el acceso según el rol asignado a la cuenta | N10: 100% de los accesos con rol no autorizado son rechazados, probado en 30 intentos sobre endpoints de los tres roles | O10: Política transversal | P10: Definir el middleware de autorización por rol y centralizar los permisos en una política única del backend. | Q10: Alta | R10: Alta | S10: Sí | T10: RBAC atraviesa todos los módulos y endpoints; introducirlo tarde obliga a reescribir controladores y modelos de permisos. | U10: Pruebas de autorización con tokens de cada rol contra los endpoints de los demás roles. | V10: RF-005; RF-006; RNF-003 | W10: =IF(OR($E10="",$S10=""),"",IF($S10="No","No es ASR: gestionar fuera de la arquitectura",IF($S10="Por validar","Falta evidencia: conseguirla antes de decidir",IF($E10="Calidad","Va al Utility Tree (hoja 3)",IF($E10="Restricción","Va a Restricciones (hoja 4)","Va a Funciones críticas (hoja 4)"))))) -> Va a Funciones críticas (hoja 4) | X10: =IF(COUNTA($A10:$V10)=0,"",COUNTA($A10:$V10)&"/22") -> 22/22
A11: ASR-05 | B11: Gestión segura de sesiones con cierre por inactividad | C11: Administrador, Empleado, Verificador | D11: Documento requerimientos funcionales y no funcionales | E11: Funcional | F11: El sistema debe cerrar automáticamente la sesión tras 15 minutos de inactividad e impedir el acceso con una sesión finalizada o expirada. | G11: Seguridad | H11: Integridad y confidencialidad de sesión | I11: Usuario autenticado | J11: Permanece inactivo durante 15 minutos o cierra sesión manualmente | K11: Operación normal, incluyendo equipos compartidos | L11: Servicio de autenticación / gestor de sesiones | M11: Invalida el token y rechaza las solicitudes posteriores que lo usen | N11: 100% de los tokens expirados son rechazados en 50 intentos; cierre por inactividad ocurre entre 14 min 55 s y 15 min 05 s | O11: Componente | P11: Definir el mecanismo de expiración de tokens (JWT con TTL o store de sesiones) y la invalidación explícita en el cierre. | Q11: Media | R11: Media | S11: Sí | T11: El manejo de sesiones condiciona el diseño de autenticación y debe decidirse al inicio para evitar reescribir el flujo entero. | U11: Prueba de reutilización del token después de cierre e inactividad, con 50 intentos cronometrados. | V11: RF-007; RNF-007 | W11: =IF(OR($E11="",$S11=""),"",IF($S11="No","No es ASR: gestionar fuera de la arquitectura",IF($S11="Por validar","Falta evidencia: conseguirla antes de decidir",IF($E11="Calidad","Va al Utility Tree (hoja 3)",IF($E11="Restricción","Va a Restricciones (hoja 4)","Va a Funciones críticas (hoja 4)"))))) -> Va a Funciones críticas (hoja 4) | X11: =IF(COUNTA($A11:$V11)=0,"",COUNTA($A11:$V11)&"/22") -> 22/22
A12: ASR-06 | B12: Generación automática de huella SHA-256 | C12: Empleado, Verificador | D12: Documento requerimientos funcionales y no funcionales | E12: Funcional | F12: El sistema debe generar automáticamente la huella SHA-256 de todo documento cargado, sin intervención manual del usuario. | G12: Seguridad | H12: Integridad | I12: Empleado o Verificador | J12: Carga un documento PDF al sistema | K12: Operación normal, archivos PDF ≤ 20 MB | L12: Servicio de hashing del backend | M12: Calcula el hash SHA-256 del contenido y lo asocia al registro del documento | N12: 100% de las cargas generan un hash SHA-256 válido (64 hex) en ≤ 2 s para archivos de 20 MB, medido en 20 pruebas | O12: Componente | P12: Definir el componente de hashing y su ubicación en el pipeline de carga (antes del registro en MongoDB y en la red). | Q12: Alta | R12: Media | S12: Sí | T12: El hash es la evidencia que viaja a la blockchain; el componente debe estar diseñado desde el inicio y no puede cambiarse sin reescribir los registros existentes. | U12: Prueba funcional de 20 cargas con documentos de distinto tamaño y verificación del hash contra una herramienta externa (sha256sum). | V12: RF-014; RF-015; RF-030; RNF-011 | W12: =IF(OR($E12="",$S12=""),"",IF($S12="No","No es ASR: gestionar fuera de la arquitectura",IF($S12="Por validar","Falta evidencia: conseguirla antes de decidir",IF($E12="Calidad","Va al Utility Tree (hoja 3)",IF($E12="Restricción","Va a Restricciones (hoja 4)","Va a Funciones críticas (hoja 4)"))))) -> Va a Funciones críticas (hoja 4) | X12: =IF(COUNTA($A12:$V12)=0,"",COUNTA($A12:$V12)&"/22") -> 22/22
A13: ASR-07 | B13: Registro en blockchain sin almacenar el PDF | C13: Empleado, Verificador, Administrador | D13: Documento requerimientos funcionales y no funcionales | E13: Funcional | F13: El sistema debe registrar en Hyperledger Fabric únicamente la huella criptográfica y los eventos del documento, sin almacenar el archivo PDF ni datos personales en la red. | G13: Seguridad | H13: Confidencialidad e integridad | I13: Módulo de integración con blockchain | J13: Recibe un documento registrado o verificado | K13: Operación normal, red Hyperledger Fabric de pruebas disponible | L13: Red blockchain permisionada / chaincode | M13: Escribe en el ledger el hash, el identificador del documento, el usuario, la acción y la fecha | N13: 100% de 30 transacciones auditadas contienen solo hash y metadatos permitidos; 0 cargas de PDF en el ledger | O13: Modelo o almacenamiento de datos | P13: Definir el esquema del asset en el chaincode y la frontera entre lo que se persiste en MongoDB y lo que se envía al ledger. | Q13: Alta | R13: Alta | S13: Sí | T13: La frontera de datos entre MongoDB y Hyperledger no es reversible: lo que entra a la blockchain queda inmutable, por lo que debe decidirse antes del primer registro. | U13: Auditoría manual del contenido de 30 transacciones del ledger contra el catálogo de campos permitidos. | V13: RF-016; RNF-004; RNF-008 | W13: =IF(OR($E13="",$S13=""),"",IF($S13="No","No es ASR: gestionar fuera de la arquitectura",IF($S13="Por validar","Falta evidencia: conseguirla antes de decidir",IF($E13="Calidad","Va al Utility Tree (hoja 3)",IF($E13="Restricción","Va a Restricciones (hoja 4)","Va a Funciones críticas (hoja 4)"))))) -> Va a Funciones críticas (hoja 4) | X13: =IF(COUNTA($A13:$V13)=0,"",COUNTA($A13:$V13)&"/22") -> 22/22
A14: ASR-08 | B14: Verificación de integridad por comparación de hashes | C14: Verificador | D14: Documento requerimientos funcionales y no funcionales | E14: Funcional | F14: El sistema debe determinar automáticamente si un documento es Verificado o Alterado comparando la huella registrada con la generada a partir del archivo cargado. | G14: Fiabilidad | H14: Correctitud funcional | I14: Verificador autenticado | J14: Carga el PDF a verificar y ejecuta la comparación | K14: Operación normal, documento previamente registrado | L14: Módulo de verificación / servicio de hashing | M14: Compara el hash recalculado contra el registrado en el ledger y muestra el resultado | N14: 100% de los resultados coinciden con la operación de referencia (sha256sum) en 20 pruebas; actualización del estado en ≤ 2 s | O14: Componente | P14: Definir el flujo de comparación, la fuente de verdad (ledger) y la actualización coordinada del estado en MongoDB. | Q14: Alta | R14: Media | S14: Sí | T14: Es la funcionalidad central del producto; su diseño define la cadena hash → ledger → UI y condiciona la trazabilidad. | U14: Prueba funcional sobre 20 documentos, 10 íntegros y 10 alterados, con verificación cruzada contra sha256sum. | V14: RF-031; RF-032; RF-033; RF-034 | W14: =IF(OR($E14="",$S14=""),"",IF($S14="No","No es ASR: gestionar fuera de la arquitectura",IF($S14="Por validar","Falta evidencia: conseguirla antes de decidir",IF($E14="Calidad","Va al Utility Tree (hoja 3)",IF($E14="Restricción","Va a Restricciones (hoja 4)","Va a Funciones críticas (hoja 4)"))))) -> Va a Funciones críticas (hoja 4) | X14: =IF(COUNTA($A14:$V14)=0,"",COUNTA($A14:$V14)&"/22") -> 22/22
A15: ASR-09 | B15: Trazabilidad con txID de Hyperledger | C15: Administrador, Verificador, Auditor | D15: Documento requerimientos funcionales y no funcionales | E15: Funcional | F15: El sistema debe conservar el identificador de transacción (txID) generado por Hyperledger para cada acción registrada y mostrarlo en la trazabilidad. | G15: Seguridad | H15: No repudio y auditabilidad | I15: Backend al confirmar una operación en el ledger | J15: Recibe el txID devuelto por Hyperledger | K15: Operación normal, ledger disponible | L15: Base de datos de trazabilidad (MongoDB) y vista de trazabilidad | M15: Guarda el txID junto al evento y lo expone en la consulta del rol correspondiente | N15: 100% de los eventos registrados en el ledger quedan con su txID en MongoDB; recuperación del txID por evento en ≤ 1 s sobre 50 consultas | O15: Modelo o almacenamiento de datos | P15: Definir el campo txID en el esquema de trazabilidad y el momento de persistencia respecto a la confirmación del ledger. | Q15: Alta | R15: Media | S15: Sí | T15: El txID es la ancla de auditoría contra la blockchain; omitirlo rompe la reconstrucción cronológica y la evidencia frente a terceros. | U15: Consulta cruzada entre la trazabilidad en MongoDB y las transacciones del ledger para 30 eventos. | V15: RF-022; RF-035; RF-040; RF-051; RNF-026; RNF-027 | W15: =IF(OR($E15="",$S15=""),"",IF($S15="No","No es ASR: gestionar fuera de la arquitectura",IF($S15="Por validar","Falta evidencia: conseguirla antes de decidir",IF($E15="Calidad","Va al Utility Tree (hoja 3)",IF($E15="Restricción","Va a Restricciones (hoja 4)","Va a Funciones críticas (hoja 4)"))))) -> Va a Funciones críticas (hoja 4) | X15: =IF(COUNTA($A15:$V15)=0,"",COUNTA($A15:$V15)&"/22") -> 22/22
A16: ASR-10 | B16: Aceptación trazable de la política de tratamiento de datos | C16: Administrador, Oficial de protección de datos, Empleado, Verificador | D16: Documento requerimientos funcionales y no funcionales | E16: Funcional | F16: El sistema debe presentar la política de tratamiento de datos en el primer inicio de sesión de cada usuario y condicionar el acceso a su aceptación, registrando usuario, fecha, hora y versión aceptada. | G16: Seguridad | H16: No repudio y cumplimiento | I16: Usuario que inicia sesión por primera vez (o después de un cambio de versión) | J16: Autentica correctamente pero aún no ha aceptado la versión vigente de la política | K16: Operación normal; existe una versión vigente publicada | L16: Servicio de autenticación / módulo de consentimiento | M16: Bloquea el acceso al resto de funcionalidades hasta aceptar y registra la aceptación con metadatos | N16: 100% de los usuarios nuevos quedan bloqueados hasta aceptar; 100% de las aceptaciones registran usuario, fecha, hora y versión, verificado en 20 pruebas | O16: Componente | P16: Definir el versionado de la política, el almacenamiento de los consentimientos y su integración en el flujo de login. | Q16: Alta | R16: Media | S16: Sí | T16: El consentimiento versionado atraviesa el flujo de login y es exigible por ley (habeas data) y por el alcance ISO 27001; omitirlo exige reescribir el flujo de autenticación. | U16: Prueba funcional del primer login con usuarios nuevos y verificación en MongoDB de los campos de consentimiento registrados. | V16: RF-055 | W16: =IF(OR($E16="",$S16=""),"",IF($S16="No","No es ASR: gestionar fuera de la arquitectura",IF($S16="Por validar","Falta evidencia: conseguirla antes de decidir",IF($E16="Calidad","Va al Utility Tree (hoja 3)",IF($E16="Restricción","Va a Restricciones (hoja 4)","Va a Funciones críticas (hoja 4)"))))) -> Va a Funciones críticas (hoja 4) | X16: =IF(COUNTA($A16:$V16)=0,"",COUNTA($A16:$V16)&"/22") -> 22/22
A17: ASR-11 | B17: Baja lógica de usuarios preservando trazabilidad histórica | C17: Administrador | D17: Documento requerimientos funcionales y no funcionales | E17: Funcional | F17: El sistema debe permitir desactivar un usuario (baja lógica) sin eliminar físicamente su información ni afectar la trazabilidad histórica de sus acciones previas. | G17: Seguridad | H17: No repudio e integridad | I17: Administrador autenticado | J17: Desactiva una cuenta existente | K17: Operación normal, usuario con eventos previos en MongoDB y en el ledger | L17: Backend / modelo de usuarios | M17: Marca la cuenta como inactiva y bloquea nuevos inicios de sesión, sin modificar sus eventos pasados | N17: 0 cambios en los eventos previos del usuario sobre 20 desactivaciones; 100% de los intentos de login posteriores son rechazados | O17: Modelo o almacenamiento de datos | P17: Decidir el modelo de borrado lógico (campo estado) y la relación entre identificador de usuario y trazabilidad inmutable del ledger. | Q17: Media | R17: Media | S17: Sí | T17: El borrado lógico condiciona el modelo de datos y la relación con los eventos inmutables del ledger; no se puede introducir después sin romper referencias. | U17: Prueba funcional de desactivación y verificación de que los eventos del usuario permanecen íntegros en MongoDB y en Fabric. | V17: RF-047; RNF-003 | W17: =IF(OR($E17="",$S17=""),"",IF($S17="No","No es ASR: gestionar fuera de la arquitectura",IF($S17="Por validar","Falta evidencia: conseguirla antes de decidir",IF($E17="Calidad","Va al Utility Tree (hoja 3)",IF($E17="Restricción","Va a Restricciones (hoja 4)","Va a Funciones críticas (hoja 4)"))))) -> Va a Funciones críticas (hoja 4) | X17: =IF(COUNTA($A17:$V17)=0,"",COUNTA($A17:$V17)&"/22") -> 22/22
A18: ASR-12 | B18: Rendimiento de consultas de documentos y trazabilidad | C18: Empleado, Verificador, Administrador | D18: Documento requerimientos funcionales y no funcionales | E18: Calidad | F18: Las operaciones de consulta de documentos y trazabilidad deben responder dentro del tiempo acordado para el entorno de pruebas del MVP. | G18: Eficiencia de desempeño | H18: Comportamiento temporal | I18: Usuario autenticado | J18: Ejecuta una consulta de documentos o de trazabilidad | K18: Entorno Docker local de pruebas, hasta 1.000 documentos registrados | L18: Capa de consulta sobre MongoDB | M18: Devuelve la lista con los filtros aplicados | N18: p95 ≤ 3.000 ms en 50 peticiones consecutivas por endpoint, con tasa de error < 1% | O18: Componente | P18: Definir los índices de MongoDB y la paginación para los endpoints de consulta. | Q18: Media | R18: Media | S18: Sí | T18: El dimensionamiento de índices y paginación debe planearse en el diseño del modelo de datos; cambiarlo después implica migración. | U18: Prueba de carga con 50 peticiones consecutivas sobre los endpoints RF-018, RF-021, RF-037 y RF-039. | V18: RF-018; RF-021; RF-037; RF-039; RNF-009 | W18: =IF(OR($E18="",$S18=""),"",IF($S18="No","No es ASR: gestionar fuera de la arquitectura",IF($S18="Por validar","Falta evidencia: conseguirla antes de decidir",IF($E18="Calidad","Va al Utility Tree (hoja 3)",IF($E18="Restricción","Va a Restricciones (hoja 4)","Va a Funciones críticas (hoja 4)"))))) -> Va al Utility Tree (hoja 3) | X18: =IF(COUNTA($A18:$V18)=0,"",COUNTA($A18:$V18)&"/22") -> 22/22
... A29: ASR-23 | B29: SHA-256 como algoritmo de hashing obligatorio | C29: Equipo de desarrollo, Director de tesis | D29: Documento requerimientos funcionales y no funcionales | E29: Restricción | F29: La generación de huellas documentales debe realizarse exclusivamente mediante el algoritmo SHA-256. | G29: Seguridad | H29: Integridad | I29: Equipo de desarrollo | J29: Define el algoritmo de hashing al cargar o verificar un documento | K29: Fase de desarrollo y pruebas del MVP | L29: Servicio de hashing del backend | M29: Produce la huella SHA-256 que se almacena y se compara | N29: 100% de las huellas generadas corresponden a SHA-256 (64 caracteres hex), verificado en 20 documentos de prueba | O29: Componente | P29: Fijar el algoritmo de hashing y evitar que otros algoritmos convivan en el pipeline. | Q29: Alta | R29: Media | S29: Sí | T29: Es una restricción técnica del alcance del proyecto; cualquier cambio futuro invalida los registros ya almacenados en el ledger. | U29: Revisión de código del componente de hashing y verificación cruzada con sha256sum sobre 20 archivos. | V29: RF-014; RF-030 | W29: =IF(OR($E29="",$S29=""),"",IF($S29="No","No es ASR: gestionar fuera de la arquitectura",IF($S29="Por validar","Falta evidencia: conseguirla antes de decidir",IF($E29="Calidad","Va al Utility Tree (hoja 3)",IF($E29="Restricción","Va a Restricciones (hoja 4)","Va a Funciones críticas (hoja 4)"))))) -> Va a Restricciones (hoja 4) | X29: =IF(COUNTA($A29:$V29)=0,"",COUNTA($A29:$V29)&"/22") -> 22/22
A30: ASR-24 | B30: Formato PDF y tamaño máximo de 20 MB | C30: Empleado, Verificador | D30: Documento requerimientos funcionales y no funcionales | E30: Restricción | F30: El sistema debe aceptar exclusivamente archivos en formato PDF con tamaño ≤ 20 MB y rechazar cargas masivas o por lotes. | G30: Adecuación funcional | H30: Pertinencia | I30: Empleado o Verificador | J30: Intenta cargar un archivo | K30: Operación normal del MVP | L30: Validador de carga del backend | M30: Rechaza cualquier archivo que no sea PDF, exceda 20 MB o venga por lotes | N30: 100% de las cargas aceptadas son PDF individuales ≤ 20 MB; 100% de los archivos fuera del criterio son rechazados en 20 intentos | O30: Componente | P30: Fijar los validadores de formato y tamaño en el backend antes del hashing. | Q30: Media | R30: Baja | S30: Sí | T30: Es una restricción del alcance; se acata y limita el diseño del validador y del servicio de hashing. | U30: Prueba de carga con archivos válidos e inválidos (otro formato, >20 MB, lote) y verificación del rechazo. | V30: RF-009; RF-010; RF-011; RNF-023; RNF-024 | W30: =IF(OR($E8="",$S8=""),"",IF($S8="No","No es ASR: gestionar fuera de la arquitectura",IF($S8="Por validar","Falta evidencia: conseguirla antes de decidir",IF($E8="Calidad","Va al Utility Tree (hoja 3)",IF($E8="Restricción","Va a Restricciones (hoja 4)","Va a Funciones críticas (hoja 4)"))))) -> Va a Funciones críticas (hoja 4) | X30: =IF(COUNTA($A30:$V30)=0,"",COUNTA($A30:$V30)&"/22") -> 22/22
A31: ASR-25 | B31: Alineación con ISO/IEC 27001:2022 Anexo A | C31: Director de tesis, Responsable de seguridad | D31: Documento requerimientos funcionales y no funcionales | E31: Restricción | F31: El diseño debe considerar los controles de acceso, criptografía, integridad y protección de la información del Anexo A de ISO/IEC 27001:2022 contemplados en el alcance. | G31: Seguridad | H31: Cumplimiento | I31: Director de tesis / revisor académico | J31: Audita el diseño frente a los controles seleccionados del Anexo A | K31: Evaluación académica del MVP | L31: Documentación de diseño y controles implementados | M31: Mapea cada control del alcance a su mecanismo en el sistema | N31: 100% de los controles del alcance aparecen implementados o justificados en el documento de diseño | O31: Política transversal | P31: Documentar la trazabilidad entre los controles del Anexo A seleccionados y las decisiones de arquitectura. | Q31: Alta | R31: Media | S31: Sí | T31: El alcance de la tesis exige referencia explícita a ISO/IEC 27001; condiciona decisiones de autenticación, cifrado, trazabilidad y manejo de credenciales. | U31: Revisión documental de la matriz controles-decisiones firmada con el director de tesis. | V31: RNF-030 | W31: =IF(OR($E8="",$S8=""),"",IF($S8="No","No es ASR: gestionar fuera de la arquitectura",IF($S8="Por validar","Falta evidencia: conseguirla antes de decidir",IF($E8="Calidad","Va al Utility Tree (hoja 3)",IF($E8="Restricción","Va a Restricciones (hoja 4)","Va a Funciones críticas (hoja 4)"))))) -> Va a Funciones críticas (hoja 4) | X31: =IF(COUNTA($A31:$V31)=0,"",COUNTA($A31:$V31)&"/22") -> 22/22
A32: ASR-26 | B32: Compatibilidad con navegadores web modernos | C32: Empleado, Verificador, Administrador | D32: Documento requerimientos funcionales y no funcionales | E32: Restricción | F32: El sistema debe ser accesible mediante navegadores web modernos que soporten las tecnologías utilizadas (HTML5, ES2020 y superior). | G32: Compatibilidad | H32: Interoperabilidad | I32: Equipo de desarrollo | J32: Elige el stack del frontend y las APIs del navegador que puede usar | K32: Fase de desarrollo del MVP | L32: Frontend de la aplicación | M32: El frontend se ejecuta correctamente en versiones actuales de Chrome, Edge y Firefox | N32: 100% de los 3 flujos principales (carga, verificación, consulta) funcionan en las versiones vigentes de Chrome, Edge y Firefox, probado en 3 equipos distintos | O32: Componente | P32: Fijar el nivel de soporte de navegadores y evitar APIs no estándar que obliguen a polyfills complejos. | Q32: Media | R32: Baja | S32: Sí | T32: Es una restricción del alcance que acota el stack del frontend; se acata y limita el conjunto de APIs utilizables. | U32: Verificación manual de los 3 flujos principales en las tres últimas versiones estables de los navegadores de referencia. | V32: RNF-025 | W32: =IF(OR($E8="",$S8=""),"",IF($S8="No","No es ASR: gestionar fuera de la arquitectura",IF($S8="Por validar","Falta evidencia: conseguirla antes de decidir",IF($E8="Calidad","Va al Utility Tree (hoja 3)",IF($E8="Restricción","Va a Restricciones (hoja 4)","Va a Funciones críticas (hoja 4)"))))) -> Va a Funciones críticas (hoja 4) | X32: =IF(COUNTA($A32:$V32)=0,"",COUNTA($A32:$V32)&"/22") -> 22/22
A33: ASR-27 | B33: Panel resumen de documentos del Administrador | C33: Administrador | D33: Documento requerimientos funcionales y no funcionales | E33: Funcional | F33: El panel general del Administrador debe mostrar los conteos de documentos registrados, verificados, pendientes y alterados. | G33: Eficiencia de desempeño | H33: Comportamiento temporal | I33: Administrador autenticado | J33: Abre el panel general | K33: Operación normal, hasta 1.000 documentos registrados | L33: Módulo de reportes del panel administrativo | M33: Muestra los cuatro conteos agregados | N33: Los conteos se muestran en ≤ 3 s después de abrir el panel, sobre 20 ejecuciones | O33: Componente | P33: Resolver los conteos con consultas agregadas sobre la colección de documentos en MongoDB. | Q33: Media | R33: Baja | S33: No | T33: El escenario es medible y legítimo, pero se resuelve con consultas de agregación dentro del módulo de reportes sin afectar contratos ni despliegue. | U33: Prueba funcional con medición del tiempo de carga del panel. | V33: RF-041; RF-042 | W33: =IF(OR($E8="",$S8=""),"",IF($S8="No","No es ASR: gestionar fuera de la arquitectura",IF($S8="Por validar","Falta evidencia: conseguirla antes de decidir",IF($E8="Calidad","Va al Utility Tree (hoja 3)",IF($E8="Restricción","Va a Restricciones (hoja 4)","Va a Funciones críticas (hoja 4)"))))) -> Va a Funciones críticas (hoja 4) | X33: =IF(COUNTA($A33:$V33)=0,"",COUNTA($A33:$V33)&"/22") -> 22/22
W34: =IF(OR($E30="",$S30=""),"",IF($S30="No","No es ASR: gestionar fuera de la arquitectura",IF($S30="Por validar","Falta evidencia: conseguirla antes de decidir",IF($E30="Calidad","Va al Utility Tree (hoja 3)",IF($E30="Restricción","Va a Restricciones (hoja 4)","Va a Funciones críticas (hoja 4)"))))) -> Va a Restricciones (hoja 4) | X34: =IF(COUNTA($A30:$V30)=0,"",COUNTA($A30:$V30)&"/22") -> 22/22
A45: Universidad Católica de Colombia | Facultad de Ingeniería | Arquitectura de Software (CT10073) | Solangie Garavito

Sheet 3__Utility_Tree
B1: Utility Tree
B2: Solo escenarios de calidad con dictamen Sí. Escriba el ID y el resto se completa desde la hoja 1.
B5: Qué es el Utility Tree y cómo se lee
B6: Es un árbol de cuatro niveles. La raíz es Utilidad, es decir, la utilidad total del sistema para los stakeholders. El nivel 1 son las características de calidad. El nivel 2 son refinamientos o subcaracterísticas. Las hojas son escenarios concretos y medibles, y cada hoja lleva un par de etiquetas: (VN, IA). El par no es decoración: es el criterio para decidir qué se analiza primero. Las hojas (Alta, Alta) son las que se evalúan y prototipan primero, porque valen mucho y son difíciles de cambiar después.
B8: Su árbol: escriba los ID en la columna B
B9: ID | C9: Nivel 1: característica de calidad | D9: Nivel 2: refinamiento | E9: Hoja: escenario | F9: VN | G9: IA | H9: Par (VN, IA) | I9: Control: ¿esta hoja pertenece al árbol?
B10: ASR-12 | C10: =IF($B10="","",IFERROR(INDEX('1__Matriz_ASR'!$G$7:$G$33,MATCH($B10,'1__Matriz_ASR'!$A$7:$A$33,0)),"ID no encontrado")) -> Eficiencia de desempeño | D10: =IF($B10="","",IFERROR(INDEX('1__Matriz_ASR'!$H$7:$H$33,MATCH($B10,'1__Matriz_ASR'!$A$7:$A$33,0)),"ID no encontrado")) -> Comportamiento temporal | E10: =IF($B10="","",IFERROR(INDEX('1__Matriz_ASR'!$B$7:$B$33,MATCH($B10,'1__Matriz_ASR'!$A$7:$A$33,0)),"ID no encontrado")) -> Rendimiento de consultas de documentos y trazabilidad | F10: =IF($B10="","",IFERROR(INDEX('1__Matriz_ASR'!$Q$7:$Q$33,MATCH($B10,'1__Matriz_ASR'!$A$7:$A$33,0)),"ID no encontrado")) -> Media | G10: =IF($B10="","",IFERROR(INDEX('1__Matriz_ASR'!$R$7:$R$33,MATCH($B10,'1__Matriz_ASR'!$A$7:$A$33,0)),"ID no encontrado")) -> Media | H10: =IF($B10="","","("&$F10&", "&$G10&")") -> (Media, Media) | I10: =IF($B10="","",IF(ISERROR(MATCH($B10,'1__Matriz_ASR'!$A$7:$A$33,0)),"Ese ID no existe en la hoja 1",IF(AND(INDEX('1__Matriz_ASR'!$E$7:$E$33,MATCH($B10,'1__Matriz_ASR'!$A$7:$A$33,0))="Calidad",INDEX('1__Matriz_ASR'!$S$7:$S$33,MATCH($B10,'1__Matriz_ASR'!$A$7:$A$33,0))="Sí"),"Correcto: es escenario de calidad aprobado","Retirar: solo van escenarios de tipo Calidad con dictamen Sí"))) -> Correcto: es escenario de calidad aprobado
B11: ASR-13 | C11: =IF($B11="","",IFERROR(INDEX('1__Matriz_ASR'!$G$7:$G$33,MATCH($B11,'1__Matriz_ASR'!$A$7:$A$33,0)),"ID no encontrado")) -> Eficiencia de desempeño | D11: =IF($B11="","",IFERROR(INDEX('1__Matriz_ASR'!$H$7:$H$33,MATCH($B11,'1__Matriz_ASR'!$A$7:$A$33,0)),"ID no encontrado")) -> Comportamiento temporal | E11: =IF($B11="","",IFERROR(INDEX('1__Matriz_ASR'!$B$7:$B$33,MATCH($B11,'1__Matriz_ASR'!$A$7:$A$33,0)),"ID no encontrado")) -> Rendimiento de la verificación de integridad | F11: =IF($B11="","",IFERROR(INDEX('1__Matriz_ASR'!$Q$7:$Q$33,MATCH($B11,'1__Matriz_ASR'!$A$7:$A$33,0)),"ID no encontrado")) -> Alta | G11: =IF($B11="","",IFERROR(INDEX('1__Matriz_ASR'!$R$7:$R$33,MATCH($B11,'1__Matriz_ASR'!$A$7:$A$33,0)),"ID no encontrado")) -> Media | H11: =IF($B11="","","("&$F11&", "&$G11&")") -> (Alta, Media) | I11: =IF($B11="","",IF(ISERROR(MATCH($B11,'1__Matriz_ASR'!$A$7:$A$33,0)),"Ese ID no existe en la hoja 1",IF(AND(INDEX('1__Matriz_ASR'!$E$7:$E$33,MATCH($B11,'1__Matriz_ASR'!$A$7:$A$33,0))="Calidad",INDEX('1__Matriz_ASR'!$S$7:$S$33,MATCH($B11,'1__Matriz_ASR'!$A$7:$A$33,0))="Sí"),"Correcto: es escenario de calidad aprobado","Retirar: solo van escenarios de tipo Calidad con dictamen Sí"))) -> Correcto: es escenario de calidad aprobado
B12: ASR-14 | C12: =IF($B12="","",IFERROR(INDEX('1__Matriz_ASR'!$G$7:$G$33,MATCH($B12,'1__Matriz_ASR'!$A$7:$A$33,0)),"ID no encontrado")) -> Fiabilidad | D12: =IF($B12="","",IFERROR(INDEX('1__Matriz_ASR'!$H$7:$H$33,MATCH($B12,'1__Matriz_ASR'!$A$7:$A$33,0)),"ID no encontrado")) -> Disponibilidad | E12: =IF($B12="","",IFERROR(INDEX('1__Matriz_ASR'!$B$7:$B$33,MATCH($B12,'1__Matriz_ASR'!$A$7:$A$33,0)),"ID no encontrado")) -> Disponibilidad del MVP ≥ 95% | F12: =IF($B12="","",IFERROR(INDEX('1__Matriz_ASR'!$Q$7:$Q$33,MATCH($B12,'1__Matriz_ASR'!$A$7:$A$33,0)),"ID no encontrado")) -> Alta | G12: =IF($B12="","",IFERROR(INDEX('1__Matriz_ASR'!$R$7:$R$33,MATCH($B12,'1__Matriz_ASR'!$A$7:$A$33,0)),"ID no encontrado")) -> Media | H12: =IF($B12="","","("&$F12&", "&$G12&")") -> (Alta, Media) | I12: =IF($B12="","",IF(ISERROR(MATCH($B12,'1__Matriz_ASR'!$A$7:$A$33,0)),"Ese ID no existe en la hoja 1",IF(AND(INDEX('1__Matriz_ASR'!$E$7:$E$33,MATCH($B12,'1__Matriz_ASR'!$A$7:$A$33,0))="Calidad",INDEX('1__Matriz_ASR'!$S$7:$S$33,MATCH($B12,'1__Matriz_ASR'!$A$7:$A$33,0))="Sí"),"Correcto: es escenario de calidad aprobado","Retirar: solo van escenarios de tipo Calidad con dictamen Sí"))) -> Correcto: es escenario de calidad aprobado
B13: ASR-15 | C13: =IF($B13="","",IFERROR(INDEX('1__Matriz_ASR'!$G$7:$G$33,MATCH($B13,'1__Matriz_ASR'!$A$7:$A$33,0)),"ID no encontrado")) -> Fiabilidad | D13: =IF($B13="","",IFERROR(INDEX('1__Matriz_ASR'!$H$7:$H$33,MATCH($B13,'1__Matriz_ASR'!$A$7:$A$33,0)),"ID no encontrado")) -> Tolerancia a fallos | E13: =IF($B13="","",IFERROR(INDEX('1__Matriz_ASR'!$B$7:$B$33,MATCH($B13,'1__Matriz_ASR'!$A$7:$A$33,0)),"ID no encontrado")) -> Consistencia entre MongoDB y Hyperledger Fabric | F13: =IF($B13="","",IFERROR(INDEX('1__Matriz_ASR'!$Q$7:$Q$33,MATCH($B13,'1__Matriz_ASR'!$A$7:$A$33,0)),"ID no encontrado")) -> Alta | G13: =IF($B13="","",IFERROR(INDEX('1__Matriz_ASR'!$R$7:$R$33,MATCH($B13,'1__Matriz_ASR'!$A$7:$A$33,0)),"ID no encontrado")) -> Alta | H13: =IF($B13="","","("&$F13&", "&$G13&")") -> (Alta, Alta) | I13: =IF($B13="","",IF(ISERROR(MATCH($B13,'1__Matriz_ASR'!$A$7:$A$33,0)),"Ese ID no existe en la hoja 1",IF(AND(INDEX('1__Matriz_ASR'!$E$7:$E$33,MATCH($B13,'1__Matriz_ASR'!$A$7:$A$33,0))="Calidad",INDEX('1__Matriz_ASR'!$S$7:$S$33,MATCH($B13,'1__Matriz_ASR'!$A$7:$A$33,0))="Sí"),"Correcto: es escenario de calidad aprobado","Retirar: solo van escenarios de tipo Calidad con dictamen Sí"))) -> Correcto: es escenario de calidad aprobado
B14: ASR-16 | C14: =IF($B14="","",IFERROR(INDEX('1__Matriz_ASR'!$G$7:$G$33,MATCH($B14,'1__Matriz_ASR'!$A$7:$A$33,0)),"ID no encontrado")) -> Seguridad | D14: =IF($B14="","",IFERROR(INDEX('1__Matriz_ASR'!$H$7:$H$33,MATCH($B14,'1__Matriz_ASR'!$A$7:$A$33,0)),"ID no encontrado")) -> Integridad y no repudio | E14: =IF($B14="","",IFERROR(INDEX('1__Matriz_ASR'!$B$7:$B$33,MATCH($B14,'1__Matriz_ASR'!$A$7:$A$33,0)),"ID no encontrado")) -> Inmutabilidad de la evidencia en blockchain | F14: =IF($B14="","",IFERROR(INDEX('1__Matriz_ASR'!$Q$7:$Q$33,MATCH($B14,'1__Matriz_ASR'!$A$7:$A$33,0)),"ID no encontrado")) -> Alta | G14: =IF($B14="","",IFERROR(INDEX('1__Matriz_ASR'!$R$7:$R$33,MATCH($B14,'1__Matriz_ASR'!$A$7:$A$33,0)),"ID no encontrado")) -> Alta | H14: =IF($B14="","","("&$F14&", "&$G14&")") -> (Alta, Alta) | I14: =IF($B14="","",IF(ISERROR(MATCH($B14,'1__Matriz_ASR'!$A$7:$A$33,0)),"Ese ID no existe en la hoja 1",IF(AND(INDEX('1__Matriz_ASR'!$E$7:$E$33,MATCH($B14,'1__Matriz_ASR'!$A$7:$A$33,0))="Calidad",INDEX('1__Matriz_ASR'!$S$7:$S$33,MATCH($B14,'1__Matriz_ASR'!$A$7:$A$33,0))="Sí"),"Correcto: es escenario de calidad aprobado","Retirar: solo van escenarios de tipo Calidad con dictamen Sí"))) -> Correcto: es escenario de calidad aprobado
B15: ASR-17 | C15: =IF($B15="","",IFERROR(INDEX('1__Matriz_ASR'!$G$7:$G$33,MATCH($B15,'1__Matriz_ASR'!$A$7:$A$33,0)),"ID no encontrado")) -> Fiabilidad | D15: =IF($B15="","",IFERROR(INDEX('1__Matriz_ASR'!$H$7:$H$33,MATCH($B15,'1__Matriz_ASR'!$A$7:$A$33,0)),"ID no encontrado")) -> Correctitud y confiabilidad | E15: =IF($B15="","",IFERROR(INDEX('1__Matriz_ASR'!$B$7:$B$33,MATCH($B15,'1__Matriz_ASR'!$A$7:$A$33,0)),"ID no encontrado")) -> Detección confiable de alteraciones documentales | F15: =IF($B15="","",IFERROR(INDEX('1__Matriz_ASR'!$Q$7:$Q$33,MATCH($B15,'1__Matriz_ASR'!$A$7:$A$33,0)),"ID no encontrado")) -> Alta | G15: =IF($B15="","",IFERROR(INDEX('1__Matriz_ASR'!$R$7:$R$33,MATCH($B15,'1__Matriz_ASR'!$A$7:$A$33,0)),"ID no encontrado")) -> Media | H15: =IF($B15="","","("&$F15&", "&$G15&")") -> (Alta, Media) | I15: =IF($B15="","",IF(ISERROR(MATCH($B15,'1__Matriz_ASR'!$A$7:$A$33,0)),"Ese ID no existe en la hoja 1",IF(AND(INDEX('1__Matriz_ASR'!$E$7:$E$33,MATCH($B15,'1__Matriz_ASR'!$A$7:$A$33,0))="Calidad",INDEX('1__Matriz_ASR'!$S$7:$S$33,MATCH($B15,'1__Matriz_ASR'!$A$7:$A$33,0))="Sí"),"Correcto: es escenario de calidad aprobado","Retirar: solo van escenarios de tipo Calidad con dictamen Sí"))) -> Correcto: es escenario de calidad aprobado
B16: ASR-18 | C16: =IF($B16="","",IFERROR(INDEX('1__Matriz_ASR'!$G$7:$G$33,MATCH($B16,'1__Matriz_ASR'!$A$7:$A$33,0)),"ID no encontrado")) -> Capacidad de interacción | D16: =IF($B16="","",IFERROR(INDEX('1__Matriz_ASR'!$H$7:$H$33,MATCH($B16,'1__Matriz_ASR'!$A$7:$A$33,0)),"ID no encontrado")) -> Aprendizaje y operabilidad | E16: =IF($B16="","",IFERROR(INDEX('1__Matriz_ASR'!$B$7:$B$33,MATCH($B16,'1__Matriz_ASR'!$A$7:$A$33,0)),"ID no encontrado")) -> Facilidad de uso de las tareas principales | F16: =IF($B16="","",IFERROR(INDEX('1__Matriz_ASR'!$Q$7:$Q$33,MATCH($B16,'1__Matriz_ASR'!$A$7:$A$33,0)),"ID no encontrado")) -> Media | G16: =IF($B16="","",IFERROR(INDEX('1__Matriz_ASR'!$R$7:$R$33,MATCH($B16,'1__Matriz_ASR'!$A$7:$A$33,0)),"ID no encontrado")) -> Baja | H16: =IF($B16="","","("&$F16&", "&$G16&")") -> (Media, Baja) | I16: =IF($B16="","",IF(ISERROR(MATCH($B16,'1__Matriz_ASR'!$A$7:$A$33,0)),"Ese ID no existe en la hoja 1",IF(AND(INDEX('1__Matriz_ASR'!$E$7:$E$33,MATCH($B16,'1__Matriz_ASR'!$A$7:$A$33,0))="Calidad",INDEX('1__Matriz_ASR'!$S$7:$S$33,MATCH($B16,'1__Matriz_ASR'!$A$7:$A$33,0))="Sí"),"Correcto: es escenario de calidad aprobado","Retirar: solo van escenarios de tipo Calidad con dictamen Sí"))) -> Correcto: es escenario de calidad aprobado
B17: ASR-19 | C17: =IF($B17="","",IFERROR(INDEX('1__Matriz_ASR'!$G$7:$G$33,MATCH($B17,'1__Matriz_ASR'!$A$7:$A$33,0)),"ID no encontrado")) -> Mantenibilidad | D17: =IF($B17="","",IFERROR(INDEX('1__Matriz_ASR'!$H$7:$H$33,MATCH($B17,'1__Matriz_ASR'!$A$7:$A$33,0)),"ID no encontrado")) -> Modularidad | E17: =IF($B17="","",IFERROR(INDEX('1__Matriz_ASR'!$B$7:$B$33,MATCH($B17,'1__Matriz_ASR'!$A$7:$A$33,0)),"ID no encontrado")) -> Arquitectura modular por capas | F17: =IF($B17="","",IFERROR(INDEX('1__Matriz_ASR'!$Q$7:$Q$33,MATCH($B17,'1__Matriz_ASR'!$A$7:$A$33,0)),"ID no encontrado")) -> Alta | G17: =IF($B17="","",IFERROR(INDEX('1__Matriz_ASR'!$R$7:$R$33,MATCH($B17,'1__Matriz_ASR'!$A$7:$A$33,0)),"ID no encontrado")) -> Alta | H17: =IF($B17="","","("&$F17&", "&$G17&")") -> (Alta, Alta) | I17: =IF($B17="","",IF(ISERROR(MATCH($B17,'1__Matriz_ASR'!$A$7:$A$33,0)),"Ese ID no existe en la hoja 1",IF(AND(INDEX('1__Matriz_ASR'!$E$7:$E$33,MATCH($B17,'1__Matriz_ASR'!$A$7:$A$33,0))="Calidad",INDEX('1__Matriz_ASR'!$S$7:$S$33,MATCH($B17,'1__Matriz_ASR'!$A$7:$A$33,0))="Sí"),"Correcto: es escenario de calidad aprobado","Retirar: solo van escenarios de tipo Calidad con dictamen Sí"))) -> Correcto: es escenario de calidad aprobado
B18: ASR-20 | C18: =IF($B18="","",IFERROR(INDEX('1__Matriz_ASR'!$G$7:$G$33,MATCH($B18,'1__Matriz_ASR'!$A$7:$A$33,0)),"ID no encontrado")) -> Flexibilidad | D18: =IF($B18="","",IFERROR(INDEX('1__Matriz_ASR'!$H$7:$H$33,MATCH($B18,'1__Matriz_ASR'!$A$7:$A$33,0)),"ID no encontrado")) -> Instalabilidad | E18: =IF($B18="","",IFERROR(INDEX('1__Matriz_ASR'!$B$7:$B$33,MATCH($B18,'1__Matriz_ASR'!$A$7:$A$33,0)),"ID no encontrado")) -> Contenerización con Docker y Docker Compose | F18: =IF($B18="","",IFERROR(INDEX('1__Matriz_ASR'!$Q$7:$Q$33,MATCH($B18,'1__Matriz_ASR'!$A$7:$A$33,0)),"ID no encontrado")) -> Media | G18: =IF($B18="","",IFERROR(INDEX('1__Matriz_ASR'!$R$7:$R$33,MATCH($B18,'1__Matriz_ASR'!$A$7:$A$33,0)),"ID no encontrado")) -> Media | H18: =IF($B18="","","("&$F18&", "&$G18&")") -> (Media, Media) | I18: =IF($B18="","",IF(ISERROR(MATCH($B18,'1__Matriz_ASR'!$A$7:$A$33,0)),"Ese ID no existe en la hoja 1",IF(AND(INDEX('1__Matriz_ASR'!$E$7:$E$33,MATCH($B18,'1__Matriz_ASR'!$A$7:$A$33,0))="Calidad",INDEX('1__Matriz_ASR'!$S$7:$S$33,MATCH($B18,'1__Matriz_ASR'!$A$7:$A$33,0))="Sí"),"Correcto: es escenario de calidad aprobado","Retirar: solo van escenarios de tipo Calidad con dictamen Sí"))) -> Correcto: es escenario de calidad aprobado
B19: ASR-21 | C19: =IF($B19="","",IFERROR(INDEX('1__Matriz_ASR'!$G$7:$G$33,MATCH($B19,'1__Matriz_ASR'!$A$7:$A$33,0)),"ID no encontrado")) -> Flexibilidad | D19: =IF($B19="","",IFERROR(INDEX('1__Matriz_ASR'!$H$7:$H$33,MATCH($B19,'1__Matriz_ASR'!$A$7:$A$33,0)),"ID no encontrado")) -> Escalabilidad y adaptabilidad | E19: =IF($B19="","",IFERROR(INDEX('1__Matriz_ASR'!$B$7:$B$33,MATCH($B19,'1__Matriz_ASR'!$A$7:$A$33,0)),"ID no encontrado")) -> Escalabilidad del diseño para nuevos módulos | F19: =IF($B19="","",IFERROR(INDEX('1__Matriz_ASR'!$Q$7:$Q$33,MATCH($B19,'1__Matriz_ASR'!$A$7:$A$33,0)),"ID no encontrado")) -> Media | G19: =IF($B19="","",IFERROR(INDEX('1__Matriz_ASR'!$R$7:$R$33,MATCH($B19,'1__Matriz_ASR'!$A$7:$A$33,0)),"ID no encontrado")) -> Alta | H19: =IF($B19="","","("&$F19&", "&$G19&")") -> (Media, Alta) | I19: =IF($B19="","",IF(ISERROR(MATCH($B19,'1__Matriz_ASR'!$A$7:$A$33,0)),"Ese ID no existe en la hoja 1",IF(AND(INDEX('1__Matriz_ASR'!$E$7:$E$33,MATCH($B19,'1__Matriz_ASR'!$A$7:$A$33,0))="Calidad",INDEX('1__Matriz_ASR'!$S$7:$S$33,MATCH($B19,'1__Matriz_ASR'!$A$7:$A$33,0))="Sí"),"Correcto: es escenario de calidad aprobado","Retirar: solo van escenarios de tipo Calidad con dictamen Sí"))) -> Correcto: es escenario de calidad aprobado
C20: =IF($B20="","",IFERROR(INDEX('1__Matriz_ASR'!$G$7:$G$33,MATCH($B20,'1__Matriz_ASR'!$A$7:$A$33,0)),"ID no encontrado")) | D20: =IF($B20="","",IFERROR(INDEX('1__Matriz_ASR'!$H$7:$H$33,MATCH($B20,'1__Matriz_ASR'!$A$7:$A$33,0)),"ID no encontrado")) | E20: =IF($B20="","",IFERROR(INDEX('1__Matriz_ASR'!$B$7:$B$33,MATCH($B20,'1__Matriz_ASR'!$A$7:$A$33,0)),"ID no encontrado")) | F20: =IF($B20="","",IFERROR(INDEX('1__Matriz_ASR'!$Q$7:$Q$33,MATCH($B20,'1__Matriz_ASR'!$A$7:$A$33,0)),"ID no encontrado")) | G20: =IF($B20="","",IFERROR(INDEX('1__Matriz_ASR'!$R$7:$R$33,MATCH($B20,'1__Matriz_ASR'!$A$7:$A$33,0)),"ID no encontrado")) | H20: =IF($B20="","","("&$F20&", "&$G20&")") | I20: =IF($B20="","",IF(ISERROR(MATCH($B20,'1__Matriz_ASR'!$A$7:$A$33,0)),"Ese ID no existe en la hoja 1",IF(AND(INDEX('1__Matriz_ASR'!$E$7:$E$33,MATCH($B20,'1__Matriz_ASR'!$A$7:$A$33,0))="Calidad",INDEX('1__Matriz_ASR'!$S$7:$S$33,MATCH($B20,'1__Matriz_ASR'!$A$7:$A$33,0))="Sí"),"Correcto: es escenario de calidad aprobado","Retirar: solo van escenarios de tipo Calidad con dictamen Sí")))
C21: =IF($B21="","",IFERROR(INDEX('1__Matriz_ASR'!$G$7:$G$33,MATCH($B21,'1__Matriz_ASR'!$A$7:$A$33,0)),"ID no encontrado")) | D21: =IF($B21="","",IFERROR(INDEX('1__Matriz_ASR'!$H$7:$H$33,MATCH($B21,'1__Matriz_ASR'!$A$7:$A$33,0)),"ID no encontrado")) | E21: =IF($B21="","",IFERROR(INDEX('1__Matriz_ASR'!$B$7:$B$33,MATCH($B21,'1__Matriz_ASR'!$A$7:$A$33,0)),"ID no encontrado")) | F21: =IF($B21="","",IFERROR(INDEX('1__Matriz_ASR'!$Q$7:$Q$33,MATCH($B21,'1__Matriz_ASR'!$A$7:$A$33,0)),"ID no encontrado")) | G21: =IF($B21="","",IFERROR(INDEX('1__Matriz_ASR'!$R$7:$R$33,MATCH($B21,'1__Matriz_ASR'!$A$7:$A$33,0)),"ID no encontrado")) | H21: =IF($B21="","","("&$F21&", "&$G21&")") | I21: =IF($B21="","",IF(ISERROR(MATCH($B21,'1__Matriz_ASR'!$A$7:$A$33,0)),"Ese ID no existe en la hoja 1",IF(AND(INDEX('1__Matriz_ASR'!$E$7:$E$33,MATCH($B21,'1__Matriz_ASR'!$A$7:$A$33,0))="Calidad",INDEX('1__Matriz_ASR'!$S$7:$S$33,MATCH($B21,'1__Matriz_ASR'!$A$7:$A$33,0))="Sí"),"Correcto: es escenario de calidad aprobado","Retirar: solo van escenarios de tipo Calidad con dictamen Sí")))
C22: =IF($B22="","",IFERROR(INDEX('1__Matriz_ASR'!$G$7:$G$33,MATCH($B22,'1__Matriz_ASR'!$A$7:$A$33,0)),"ID no encontrado")) | D22: =IF($B22="","",IFERROR(INDEX('1__Matriz_ASR'!$H$7:$H$33,MATCH($B22,'1__Matriz_ASR'!$A$7:$A$33,0)),"ID no encontrado")) | E22: =IF($B22="","",IFERROR(INDEX('1__Matriz_ASR'!$B$7:$B$33,MATCH($B22,'1__Matriz_ASR'!$A$7:$A$33,0)),"ID no encontrado")) | F22: =IF($B22="","",IFERROR(INDEX('1__Matriz_ASR'!$Q$7:$Q$33,MATCH($B22,'1__Matriz_ASR'!$A$7:$A$33,0)),"ID no encontrado")) | G22: =IF($B22="","",IFERROR(INDEX('1__Matriz_ASR'!$R$7:$R$33,MATCH($B22,'1__Matriz_ASR'!$A$7:$A$33,0)),"ID no encontrado")) | H22: =IF($B22="","","("&$F22&", "&$G22&")") | I22: =IF($B22="","",IF(ISERROR(MATCH($B22,'1__Matriz_ASR'!$A$7:$A$33,0)),"Ese ID no existe en la hoja 1",IF(AND(INDEX('1__Matriz_ASR'!$E$7:$E$33,MATCH($B22,'1__Matriz_ASR'!$A$7:$A$33,0))="Calidad",INDEX('1__Matriz_ASR'!$S$7:$S$33,MATCH($B22,'1__Matriz_ASR'!$A$7:$A$33,0))="Sí"),"Correcto: es escenario de calidad aprobado","Retirar: solo van escenarios de tipo Calidad con dictamen Sí")))
C23: =IF($B23="","",IFERROR(INDEX('1__Matriz_ASR'!$G$7:$G$33,MATCH($B23,'1__Matriz_ASR'!$A$7:$A$33,0)),"ID no encontrado")) | D23: =IF($B23="","",IFERROR(INDEX('1__Matriz_ASR'!$H$7:$H$33,MATCH($B23,'1__Matriz_ASR'!$A$7:$A$33,0)),"ID no encontrado")) | E23: =IF($B23="","",IFERROR(INDEX('1__Matriz_ASR'!$B$7:$B$33,MATCH($B23,'1__Matriz_ASR'!$A$7:$A$33,0)),"ID no encontrado")) | F23: =IF($B23="","",IFERROR(INDEX('1__Matriz_ASR'!$Q$7:$Q$33,MATCH($B23,'1__Matriz_ASR'!$A$7:$A$33,0)),"ID no encontrado")) | G23: =IF($B23="","",IFERROR(INDEX('1__Matriz_ASR'!$R$7:$R$33,MATCH($B23,'1__Matriz_ASR'!$A$7:$A$33,0)),"ID no encontrado")) | H23: =IF($B23="","","("&$F23&", "&$G23&")") | I23: =IF($B23="","",IF(ISERROR(MATCH($B23,'1__Matriz_ASR'!$A$7:$A$33,0)),"Ese ID no existe en la hoja 1",IF(AND(INDEX('1__Matriz_ASR'!$E$7:$E$33,MATCH($B23,'1__Matriz_ASR'!$A$7:$A$33,0))="Calidad",INDEX('1__Matriz_ASR'!$S$7:$S$33,MATCH($B23,'1__Matriz_ASR'!$A$7:$A$33,0))="Sí"),"Correcto: es escenario de calidad aprobado","Retirar: solo van escenarios de tipo Calidad con dictamen Sí")))
C24: =IF($B24="","",IFERROR(INDEX('1__Matriz_ASR'!$G$7:$G$33,MATCH($B24,'1__Matriz_ASR'!$A$7:$A$33,0)),"ID no encontrado")) | D24: =IF($B24="","",IFERROR(INDEX('1__Matriz_ASR'!$H$7:$H$33,MATCH($B24,'1__Matriz_ASR'!$A$7:$A$33,0)),"ID no encontrado")) | E24: =IF($B24="","",IFERROR(INDEX('1__Matriz_ASR'!$B$7:$B$33,MATCH($B24,'1__Matriz_ASR'!$A$7:$A$33,0)),"ID no encontrado")) | F24: =IF($B24="","",IFERROR(INDEX('1__Matriz_ASR'!$Q$7:$Q$33,MATCH($B24,'1__Matriz_ASR'!$A$7:$A$33,0)),"ID no encontrado")) | G24: =IF($B24="","",IFERROR(INDEX('1__Matriz_ASR'!$R$7:$R$33,MATCH($B24,'1__Matriz_ASR'!$A$7:$A$33,0)),"ID no encontrado")) | H24: =IF($B24="","","("&$F24&", "&$G24&")") | I24: =IF($B24="","",IF(ISERROR(MATCH($B24,'1__Matriz_ASR'!$A$7:$A$33,0)),"Ese ID no existe en la hoja 1",IF(AND(INDEX('1__Matriz_ASR'!$E$7:$E$33,MATCH($B24,'1__Matriz_ASR'!$A$7:$A$33,0))="Calidad",INDEX('1__Matriz_ASR'!$S$7:$S$33,MATCH($B24,'1__Matriz_ASR'!$A$7:$A$33,0))="Sí"),"Correcto: es escenario de calidad aprobado","Retirar: solo van escenarios de tipo Calidad con dictamen Sí")))
C25: =IF($B25="","",IFERROR(INDEX('1__Matriz_ASR'!$G$7:$G$33,MATCH($B25,'1__Matriz_ASR'!$A$7:$A$33,0)),"ID no encontrado")) | D25: =IF($B25="","",IFERROR(INDEX('1__Matriz_ASR'!$H$7:$H$33,MATCH($B25,'1__Matriz_ASR'!$A$7:$A$33,0)),"ID no encontrado")) | E25: =IF($B25="","",IFERROR(INDEX('1__Matriz_ASR'!$B$7:$B$33,MATCH($B25,'1__Matriz_ASR'!$A$7:$A$33,0)),"ID no encontrado")) | F25: =IF($B25="","",IFERROR(INDEX('1__Matriz_ASR'!$Q$7:$Q$33,MATCH($B25,'1__Matriz_ASR'!$A$7:$A$33,0)),"ID no encontrado")) | G25: =IF($B25="","",IFERROR(INDEX('1__Matriz_ASR'!$R$7:$R$33,MATCH($B25,'1__Matriz_ASR'!$A$7:$A$33,0)),"ID no encontrado")) | H25: =IF($B25="","","("&$F25&", "&$G25&")") | I25: =IF($B25="","",IF(ISERROR(MATCH($B25,'1__Matriz_ASR'!$A$7:$A$33,0)),"Ese ID no existe en la hoja 1",IF(AND(INDEX('1__Matriz_ASR'!$E$7:$E$33,MATCH($B25,'1__Matriz_ASR'!$A$7:$A$33,0))="Calidad",INDEX('1__Matriz_ASR'!$S$7:$S$33,MATCH($B25,'1__Matriz_ASR'!$A$7:$A$33,0))="Sí"),"Correcto: es escenario de calidad aprobado","Retirar: solo van escenarios de tipo Calidad con dictamen Sí")))
C26: =IF($B26="","",IFERROR(INDEX('1__Matriz_ASR'!$G$7:$G$33,MATCH($B26,'1__Matriz_ASR'!$A$7:$A$33,0)),"ID no encontrado")) | D26: =IF($B26="","",IFERROR(INDEX('1__Matriz_ASR'!$H$7:$H$33,MATCH($B26,'1__Matriz_ASR'!$A$7:$A$33,0)),"ID no encontrado")) | E26: =IF($B26="","",IFERROR(INDEX('1__Matriz_ASR'!$B$7:$B$33,MATCH($B26,'1__Matriz_ASR'!$A$7:$A$33,0)),"ID no encontrado")) | F26: =IF($B26="","",IFERROR(INDEX('1__Matriz_ASR'!$Q$7:$Q$33,MATCH($B26,'1__Matriz_ASR'!$A$7:$A$33,0)),"ID no encontrado")) | G26: =IF($B26="","",IFERROR(INDEX('1__Matriz_ASR'!$R$7:$R$33,MATCH($B26,'1__Matriz_ASR'!$A$7:$A$33,0)),"ID no encontrado")) | H26: =IF($B26="","","("&$F26&", "&$G26&")") | I26: =IF($B26="","",IF(ISERROR(MATCH($B26,'1__Matriz_ASR'!$A$7:$A$33,0)),"Ese ID no existe en la hoja 1",IF(AND(INDEX('1__Matriz_ASR'!$E$7:$E$33,MATCH($B26,'1__Matriz_ASR'!$A$7:$A$33,0))="Calidad",INDEX('1__Matriz_ASR'!$S$7:$S$33,MATCH($B26,'1__Matriz_ASR'!$A$7:$A$33,0))="Sí"),"Correcto: es escenario de calidad aprobado","Retirar: solo van escenarios de tipo Calidad con dictamen Sí")))
C27: =IF($B27="","",IFERROR(INDEX('1__Matriz_ASR'!$G$7:$G$33,MATCH($B27,'1__Matriz_ASR'!$A$7:$A$33,0)),"ID no encontrado")) | D27: =IF($B27="","",IFERROR(INDEX('1__Matriz_ASR'!$H$7:$H$33,MATCH($B27,'1__Matriz_ASR'!$A$7:$A$33,0)),"ID no encontrado")) | E27: =IF($B27="","",IFERROR(INDEX('1__Matriz_ASR'!$B$7:$B$33,MATCH($B27,'1__Matriz_ASR'!$A$7:$A$33,0)),"ID no encontrado")) | F27: =IF($B27="","",IFERROR(INDEX('1__Matriz_ASR'!$Q$7:$Q$33,MATCH($B27,'1__Matriz_ASR'!$A$7:$A$33,0)),"ID no encontrado")) | G27: =IF($B27="","",IFERROR(INDEX('1__Matriz_ASR'!$R$7:$R$33,MATCH($B27,'1__Matriz_ASR'!$A$7:$A$33,0)),"ID no encontrado")) | H27: =IF($B27="","","("&$F27&", "&$G27&")") | I27: =IF($B27="","",IF(ISERROR(MATCH($B27,'1__Matriz_ASR'!$A$7:$A$33,0)),"Ese ID no existe en la hoja 1",IF(AND(INDEX('1__Matriz_ASR'!$E$7:$E$33,MATCH($B27,'1__Matriz_ASR'!$A$7:$A$33,0))="Calidad",INDEX('1__Matriz_ASR'!$S$7:$S$33,MATCH($B27,'1__Matriz_ASR'!$A$7:$A$33,0))="Sí"),"Correcto: es escenario de calidad aprobado","Retirar: solo van escenarios de tipo Calidad con dictamen Sí")))
B29: Cómo se ve el árbol dibujado (ejemplo con los casos de la hoja 2)
B30: Utilidad
B31: |
B32: |-- Eficiencia de desempeño
B33: | |-- Comportamiento temporal
B34: | | |-- ASR-12 Rendimiento de consultas de documentos y trazabilidad ...... (Alta, Media)
B35: | | |-- ASR-13 Rendimiento de la verificación de integridad ................ (Alta, Media)
B36: |
B37: |-- Fiabilidad
B38: | |-- Disponibilidad
B39: | | |-- ASR-14 Disponibilidad del MVP ≥ 95% ................................. (Alta, Media)
B40: | |-- Tolerancia a fallos
... B64: Qué hacer con cada par (VN, IA)
B65: Par | C65: Qué significa | D65: Qué hace usted primero
B66: (Alta, Alta) | C66: Vale mucho y es difícil de cambiar después. | D66: Prioridad 1. Diseñe, prototipe y evalúe este escenario antes que los demás.
B67: (Alta, Media) | C67: Vale mucho pero la decisión es localizable. | D67: Prioridad 2. Diseñe con cuidado, pero no bloquee el proyecto por esto.
...

Sheet Medición_Características
B1: Cómo escribir una medida que sirva
B2: La medida es la parte del escenario que más se hace mal.
B5: Fórmula de una medida correcta
B6: número + unidad + estadístico o porcentaje + ventana de tiempo Ejemplo: "p95 <= 2 s durante 30 minutos continuos". Tiene número (2), unidad (segundos), estadístico (percentil 95) y ventana (30 minutos). Sin uno de los cuatro, la medida no se puede verificar y el escenario no está terminado.
B8: Formas de medida por característica de calidad
B9: Característica | C9: Qué se mide | D9: Así se escribe bien | E9: Así se escribe mal (y por qué) | F9: Con qué se verifica
B10: Eficiencia de desempeño | C10: Tiempo de respuesta, throughput, uso de recursos | D10: p95 <= 2 s con 1.500 solicitudes por minuto durante 30 min | E10: "Debe ser rápido": no hay número, unidad ni carga | F10: Prueba de carga con perfil y datos representativos
B11: Eficiencia de desempeño | C11: Capacidad concurrente | D11: Soporta 8.000 usuarios concurrentes con error < 1% durante 60 min | E11: "Debe soportar muchos usuarios": no define cuántos ni por cuánto tiempo | F11: Prueba de carga escalonada hasta el objetivo
B12: Fiabilidad | C12: Disponibilidad, recuperación | D12: Disponibilidad mensual 99,95%; RTO <= 5 min; RPO <= 1 min | E12: "Debe estar siempre disponible": 100% no es verificable ni alcanzable | F12: Ejercicio de recuperación con medición real
B13: Fiabilidad5 | C13: Tolerancia a fallos | D13: Ante la caída de una réplica, degrada sin perder transacciones confirmadas | E13: "No debe fallar": no describe la falla ni la respuesta esperada | F13: Inyección de fallos en ambiente controlado
B14: Seguridad6 | C14: Cobertura de control, tiempo de decisión | D14: 100% de transferencias evaluadas antes de contabilizar; decisión p95 <= 800 ms | E14: "Debe ser seguro": no nombra amenaza, control ni cobertura | F14: Pruebas de integración y revisión de registros
B15: Mantenibilidad7 | C15: Esfuerzo o alcance del cambio | D15: Agregar un nuevo medio de pago toca 1 módulo y no altera contratos existentes | E15: "Debe ser fácil de mantener": no define qué cambio ni qué esfuerzo | F15: Ejercicio de cambio guiado sobre el código real
B16: Flexibilidad8 | C16: Tiempo y forma del cambio en operación | D16: Nueva regla disponible en <= 15 min sin redespliegue | E16: "Debe ser configurable": no dice qué se configura ni en cuánto tiempo | F16: Prueba de cambio en ambiente equivalente
B17: Compatibilidad3 | C17: Interoperabilidad y versiones | D17: Consume la versión v2 del contrato sin romper clientes de v1 durante 6 meses | E17: "Debe integrarse con todo": no nombra sistemas ni contratos | F17: Pruebas de contrato entre versiones
B18: Capacidad de interacción4 | C18: Accesibilidad y eficiencia de uso | D18: Cumple WCAG 2.2 nivel AA en los 5 flujos principales | E18: "Debe ser usable": no define criterio ni alcance | F18: Auditoría de accesibilidad y pruebas con usuarios
B20: Advertencias sobre las cifras
B21: Ningún número de esta hoja es un estándar. Son ejemplos de forma, no de valor.
B22: Un umbral se justifica con tres cosas: objetivo de negocio, dato de operación y acuerdo del stakeholder. Si le falta alguno, márquelo como supuesto.
B23: Prefiera percentiles (p95, p99) sobre promedios. El promedio esconde los casos que molestan al usuario.
B24: Toda medida necesita una ventana de tiempo. Un dato instantáneo no demuestra comportamiento.
B26: Universidad Católica de Colombia | Facultad de Ingeniería | Arquitectura de Software (CT10073) | Solangie Garavito

Sheet 7__Escalas_VN_e_IA
B1: Escalas de priorización: solo dos ejes
B2: Valor de negocio (VN) e Impacto y dificultad arquitectónica (IA).
B5: Por qué solo dos ejes
B6: Cada eje adicional multiplica los juicios y no mejora la decisión. Con dos ejes se responde lo único que importa para ordenar el trabajo: cuánto vale acertar y cuánto cuesta equivocarse. El riesgo no es un tercer eje de priorización: el riesgo aparece después, cuando se evalúa la arquitectura y se descubre que una decisión no satisface un escenario.
B8: Valor de negocio (VN): qué pasa si no se cumple
B9: Nivel | C9: Descriptor observable | D9: Pregunta que lo confirma
B10: Alta | C10: Incumplirlo compromete un objetivo estratégico, una obligación regulatoria o la continuidad del servicio principal. | D10: ¿Alguien externo a TI escalaría el incumplimiento? ¿Hay sanción, pérdida de ingreso o riesgo para las personas?
B11: Media | C11: Incumplirlo degrada la calidad percibida o la eficiencia operativa, pero el negocio sigue funcionando. | D11: ¿El negocio puede operar una semana así, con molestia pero sin daño?
B12: Baja | C12: Incumplirlo genera una molestia local, contenida y con alternativa manual. | D12: ¿Existe una forma de trabajo alterna que nadie considera inaceptable?
B13: Por validar | C13: No hay evidencia suficiente para asignar valor. El stakeholder aún no lo ha cuantificado. | D13: ¿Puedo nombrar la fuente del valor? Si no, no invente el nivel.
B15: Impacto y dificultad arquitectónica (IA): qué tan costoso es cambiarlo
B16: Nivel | C16: Descriptor observable | D16: Pregunta que lo confirma
B17: Alta | C17: Obliga a decidir sobre estructuras, contratos entre partes, tecnología base, distribución de datos o despliegue, y revertirlo es costoso. | D17: ¿Corregir esto en seis meses implicaría rehacer más de un componente o renegociar un contrato de integración?
B18: Media | C18: Exige tácticas concretas, pero la decisión se localiza dentro de un componente o un contrato ya existente. | D18: ¿Puedo cambiar de opinión sin tocar otros equipos ni otros módulos?
B19: Baja | C19: Se resuelve dentro de un módulo, sin afectar contratos, datos compartidos ni despliegue. | D19: ¿Esto lo resuelve una persona en su módulo sin coordinar con nadie?
B20: Por validar | C20: Falta información técnica para estimar el impacto. Requiere prototipo, medición o análisis previo. | D20: ¿Puedo nombrar el elemento arquitectónico afectado? Si no, todavía no sé el impacto.
B22: Matriz de decisión: qué hacer con cada combinación
B23: VN \ IA | E23: IA Alta | F23: IA Media | G23: IA Baja
B24: VN Alta | E24: Prioridad 1: diseñar, prototipar y evaluar primero | F24: Prioridad 2: diseñar con cuidado, no bloquear el proyecto | G24: Prioridad 3: cumplir sin ceremonia arquitectónica
B25: VN Media | E25: Prioridad 2: decidir temprano aunque no urja | F25: Prioridad 3: documentar y seguir | G25: Probablemente no es ASR: revisar el dictamen
B26: VN Baja | E26: Prioridad 3: vigilar, puede volverse trampa técnica | F26: No es ASR: gestionar como requisito común | G26: No es ASR: gestionar como requisito común
B28: Señal de alarma en la revisión: si todo su trabajo quedó en (Alta, Alta), no priorizó. Vuelva a leer los descriptores y compare los requisitos entre sí, no cada uno por separado.
B30: Universidad Católica de Colombia | Facultad de Ingeniería | Arquitectura de Software (CT10073) | Vigilada Mineducación

Sheet 10__Catálogos_y_fuentes
B1: Catálogos y fuentes
B2: Vocabulario controlado y trazabilidad bibliográfica.
B5: Tipos de requisito
B6: Tipo | C6: Qué es | D6: Ejemplo | E6: A dónde va si es ASR
B7: Funcional | C7: Un comportamiento o servicio que el sistema debe prestar. | D7: Evaluar el riesgo de fraude antes de autorizar una transferencia. | E7: Lista de funciones críticas (hoja 4)
