Workbook

Sheet Portada
A1: Pruebas de QA/QC · TrazaDoc
A2: Registro de aseguramiento (QA) y control (QC) de calidad del MVP, con la estructura de documentación de ISO/IEC/IEEE 29119-3
A4: Proyecto | B4: MVP de un sistema web para la verificación de integridad y trazabilidad documental en contratos laborales mediante blockchain permisionada (TrazaDoc).
A5: Versión del libro | B5: 1.0 · 25 de octubre de 2026
A6: Autoras | B6: Laura Sofia Diaz Suarez (interfaz, usabilidad y documentación) · Sofia Ortiz Daza (backend, blockchain, infraestructura y pruebas técnicas)
A7: Dirección | B7: Director: Juan Carlos Navarro Beltrán · Codirectora: Solangie Paola Garavito Mendivelso
A8: Documento base | B8: Plan de Pruebas de Software (docs/Plan de Pruebas de Software - TrazaDoc.docx). Los casos de este libro son los mismos del Anexo A del plan.
A9: Entorno local (Ciclo 1) | B9: http://localhost:5173 · Windows 11, Docker Desktop · pruebas del 11 al 25 de octubre de 2026
A10: Entorno de validación (Ciclo 2) | B10: https://trazadoc-tesis.eastus2.cloudapp.azure.com · Azure, Ubuntu 24.04, VM Standard_B2s · pruebas del 25 al 29 de octubre de 2026
A12: ¿Qué es QA? | B12: Aseguramiento de la calidad: revisa el PROCESO con el que se construye y prueba el sistema, para PREVENIR defectos (planes, revisiones, control de versiones, gestión de defectos). Hoja "QA Proceso".
A13: ¿Qué es QC? | B13: Control de la calidad: revisa el PRODUCTO terminado, para DETECTAR defectos (ejecutar pruebas, medir, inspeccionar). Hojas "Casos de prueba" y "QC Producto". Las pruebas son una actividad de QC dentro del sistema de QA.
A15: Hojas del libro
A16: Resumen y métricas | B16: Indicadores calculados automáticamente: ejecución, % PASS, KPI del OE4 y defectos. No se edita: se actualiza solo.
A17: Casos de prueba | B17: 62 casos (51 funcionales + 11 de integridad, trazabilidad y rendimiento) con su resultado en el Ciclo 1 (local) y columnas para el Ciclo 2 (Azure).
A18: Defectos | B18: Registro de defectos (incidentes) con severidad, prioridad, estado y responsable.
A19: Trazabilidad | B19: Matriz de cumplimiento: cada historia de usuario y requerimiento con sus casos y su estado (calculado).
A20: QA Proceso | B20: Lista de control del proceso de pruebas (25 criterios) con la evaluación actual y las acciones de mejora.
A21: QC Producto | B21: Lista de control del producto según las 9 características de calidad de ISO/IEC 25010:2023.
A22: Bitácora | B22: Registro cronológico de la ejecución (fecha, actividad, resultado e impacto).
A24: Cómo se llena | B24: Solo se escriben las celdas con fondo amarillo claro. Las columnas con lista desplegable aceptan únicamente los valores de la lista. Los totales y porcentajes se calculan solos.
A25: Estados de un caso | B25: PASS: el resultado obtenido es igual al esperado. FAIL: es distinto (se registra un defecto). Bloqueado: no se pudo ejecutar por una causa externa. No ejecutado: todavía no se ha corrido. N/A: no aplica en ese ciclo.
A26: Ejemplo de registro (Ciclo 2) | B26: Fecha: 26/10/2026 · Ejecutado por: Laura Sofia Diaz Suarez · Resultado obtenido: "Se pidió el código de 6 dígitos" · Estado: PASS · Evidencia: captura CP-01_azure.png · Defecto: (vacío)
A28: Referencias
A29: ISO/IEC/IEEE 29119-3 | B29: Estructura de la documentación de pruebas: especificación de casos, registro de ejecución, informe de incidentes. https://en.wikipedia.org/wiki/ISO/IEC_29119
A30: ISO/IEC 25010:2023 | B30: Modelo de calidad del producto (9 características). https://www.iso.org/standard/78176.html
A31: Plantilla de casos de prueba | B31: Campos mínimos de un caso de prueba en Excel. https://www.guru99.com/download-sample-test-case-template-with-explanation-of-important-fields.html
A32: QA vs QC | B32: Diferencia entre aseguramiento y control de calidad. https://synoptek.com/insights/it-blogs/qa-testing-vs-qc-testing-whats-the-difference/
A33: Métricas de prueba | B33: Fórmulas de % de ejecución y % PASS. https://www.accelq.com/blog/software-testing-metrics/
B35: ← Así se ven las celdas que se deben llenar.

Sheet Resumen y métricas
A1: Resumen de pruebas y métricas
A2: Se calcula solo a partir de las demás hojas. Las únicas celdas a llenar son las amarillas (mediciones que salen de los scripts).
A4: 1. Ejecución de casos | B4: Ciclo 1 (local) | C4: Ciclo 2 (Azure)
A5: Casos planeados | B5: =COUNTA('Casos de prueba'!$A$5:$A$66) -> 62 | C5: =COUNTA('Casos de prueba'!$A$5:$A$66) -> 62
A6: PASS | B6: =COUNTIF('Casos de prueba'!$R$5:$R$66,"PASS") -> 50 | C6: =COUNTIF('Casos de prueba'!$X$5:$X$66,"PASS") -> 0
A7: FAIL | B7: =COUNTIF('Casos de prueba'!$R$5:$R$66,"FAIL") -> 0 | C7: =COUNTIF('Casos de prueba'!$X$5:$X$66,"FAIL") -> 0
A8: Bloqueados | B8: =COUNTIF('Casos de prueba'!$R$5:$R$66,"Bloqueado") -> 0 | C8: =COUNTIF('Casos de prueba'!$X$5:$X$66,"Bloqueado") -> 0
A9: No ejecutados | B9: =COUNTIF('Casos de prueba'!$R$5:$R$66,"No ejecutado") -> 12 | C9: =COUNTIF('Casos de prueba'!$X$5:$X$66,"No ejecutado") -> 62
A10: Ejecutados (PASS + FAIL) | B10: =B6+B7 -> 50 | C10: =C6+C7 -> 0
A11: % de ejecución = ejecutados / planeados | B11: =IF(B5=0,0,B10/B5) -> 0.80645161 | C11: =IF(C5=0,0,C10/C5) -> 0
A12: % PASS = PASS / ejecutados | B12: =IF(B10=0,0,B6/B10) -> 1 | C12: =IF(C10=0,0,C6/C10) -> 0
A14: 2. Indicadores del OE4 | B14: Ciclo 1 (local) | C14: Ciclo 2 (Azure) | D14: Meta | E14: Resultado ciclo 2 | F14: Cómo se obtiene
A15: Casos funcionales en PASS (de 51) | B15: =COUNTIFS('Casos de prueba'!$B$5:$B$66,"Funcional",'Casos de prueba'!$R$5:$R$66,"PASS") -> 45 | C15: =COUNTIFS('Casos de prueba'!$B$5:$B$66,"Funcional",'Casos de prueba'!$X$5:$X$66,"PASS") -> 0 | D15: 0.9 | E15: =IF(COUNTIFS('Casos de prueba'!$B$5:$B$66,"Funcional",'Casos de prueba'!$X$5:$X$66,"No ejecutado")=COUNTIF('Casos de prueba'!$B$5:$B$66,"Funcional"),"Pendiente",IF(C16>=D15,"Cumple","No cumple")) -> Pendiente | F15: Conteo de la hoja Casos de prueba.
A16: % de casos funcionales en PASS | B16: =B15/COUNTIF('Casos de prueba'!$B$5:$B$66,"Funcional") -> 0.88235294 | C16: =C15/COUNTIF('Casos de prueba'!$B$5:$B$66,"Funcional") -> 0 | D16: ≥ 90 % | F16: Meta del KPI de OE4: al menos 46 de 51.
A17: Alteraciones detectadas (de 20) | B17: 20 | D17: 20 | E17: =IF(C17="","Pendiente",IF(C17>=D17,"Cumple","No cumple")) -> Pendiente | F17: Dato del informe de tests/integrity (línea "Detección").
A18: Falsos positivos (originales marcados como alterados) | B18: 0 | D18: 0 | E18: =IF(C18="","Pendiente",IF(C18<=D18,"Cumple","No cumple")) -> Pendiente | F18: Dato del informe de tests/integrity.
A19: Latencia de verificación P95 (ms) | B19: 2059 | D19: 3000 | E19: =IF(C19="","Pendiente",IF(C19<=D19,"Cumple","No cumple")) -> Pendiente | F19: Dato del informe de tests/perf (50 peticiones).
A20: Actividades del PPS cerradas en plazo (de 20) | D20: 17 | E20: =IF(C20="","Pendiente",IF(C20>=D20,"Cumple","No cumple")) -> Pendiente | F20: Conteo de la Tabla 15 del plan de pruebas (meta: 85 %).
A22: 3. Defectos | B22: Abiertos | C22: Cerrados | D22: Total | E22: % cerrados
A23: Crítica | B23: =COUNTIFS(Defectos!$K$5:$K$40,"Crítica",Defectos!$N$5:$N$40,"<>Cerrado",Defectos!$N$5:$N$40,"<>Rechazado") -> 0 | C23: =COUNTIFS(Defectos!$K$5:$K$40,"Crítica",Defectos!$N$5:$N$40,"Cerrado") -> 0 | D23: =COUNTIF(Defectos!$K$5:$K$40,"Crítica") -> 0 | E23: =IF(D23=0,0,C23/D23) -> 0
A24: Alta | B24: =COUNTIFS(Defectos!$K$5:$K$40,"Alta",Defectos!$N$5:$N$40,"<>Cerrado",Defectos!$N$5:$N$40,"<>Rechazado") -> 1 | C24: =COUNTIFS(Defectos!$K$5:$K$40,"Alta",Defectos!$N$5:$N$40,"Cerrado") -> 0 | D24: =COUNTIF(Defectos!$K$5:$K$40,"Alta") -> 1 | E24: =IF(D24=0,0,C24/D24) -> 0
A25: Media | B25: =COUNTIFS(Defectos!$K$5:$K$40,"Media",Defectos!$N$5:$N$40,"<>Cerrado",Defectos!$N$5:$N$40,"<>Rechazado") -> 3 | C25: =COUNTIFS(Defectos!$K$5:$K$40,"Media",Defectos!$N$5:$N$40,"Cerrado") -> 0 | D25: =COUNTIF(Defectos!$K$5:$K$40,"Media") -> 3 | E25: =IF(D25=0,0,C25/D25) -> 0
A26: Baja | B26: =COUNTIFS(Defectos!$K$5:$K$40,"Baja",Defectos!$N$5:$N$40,"<>Cerrado",Defectos!$N$5:$N$40,"<>Rechazado") -> 2 | C26: =COUNTIFS(Defectos!$K$5:$K$40,"Baja",Defectos!$N$5:$N$40,"Cerrado") -> 0 | D26: =COUNTIF(Defectos!$K$5:$K$40,"Baja") -> 2 | E26: =IF(D26=0,0,C26/D26) -> 0
A27: Total | B27: =SUM(B23:B26) -> 6 | C27: =SUM(C23:C26) -> 0 | D27: =SUM(D23:D26) -> 6 | E27: =IF(D27=0,0,C27/D27) -> 0
A28: ¿Hay defectos críticos abiertos? (criterio de salida) | B28: =IF(B23>0,"Sí: no se puede cerrar","No") -> No
A30: 4. Resultados por épica | B30: Casos | C30: PASS ciclo 1 | D30: PASS ciclo 2 | E30: FAIL ciclo 2 | F30: % PASS ciclo 2
A31: EP-01 Autenticación y control de acceso | B31: =COUNTIF('Casos de prueba'!$C$5:$C$66,A31) -> 15 | C31: =COUNTIFS('Casos de prueba'!$C$5:$C$66,A31,'Casos de prueba'!$R$5:$R$66,"PASS") -> 14 | D31: =COUNTIFS('Casos de prueba'!$C$5:$C$66,A31,'Casos de prueba'!$X$5:$X$66,"PASS") -> 0 | E31: =COUNTIFS('Casos de prueba'!$C$5:$C$66,A31,'Casos de prueba'!$X$5:$X$66,"FAIL") -> 0 | F31: =IF(B31=0,0,D31/B31) -> 0
A32: EP-02 Registro y gestión documental (Empleado) | B32: =COUNTIF('Casos de prueba'!$C$5:$C$66,A32) -> 10 | C32: =COUNTIFS('Casos de prueba'!$C$5:$C$66,A32,'Casos de prueba'!$R$5:$R$66,"PASS") -> 9 | D32: =COUNTIFS('Casos de prueba'!$C$5:$C$66,A32,'Casos de prueba'!$X$5:$X$66,"PASS") -> 0 | E32: =COUNTIFS('Casos de prueba'!$C$5:$C$66,A32,'Casos de prueba'!$X$5:$X$66,"FAIL") -> 0 | F32: =IF(B32=0,0,D32/B32) -> 0
A33: EP-03 Verificación de integridad documental (Verificador) | B33: =COUNTIF('Casos de prueba'!$C$5:$C$66,A33) -> 14 | C33: =COUNTIFS('Casos de prueba'!$C$5:$C$66,A33,'Casos de prueba'!$R$5:$R$66,"PASS") -> 13 | D33: =COUNTIFS('Casos de prueba'!$C$5:$C$66,A33,'Casos de prueba'!$X$5:$X$66,"PASS") -> 0 | E33: =COUNTIFS('Casos de prueba'!$C$5:$C$66,A33,'Casos de prueba'!$X$5:$X$66,"FAIL") -> 0 | F33: =IF(B33=0,0,D33/B33) -> 0
A34: EP-04 Administración del sistema | B34: =COUNTIF('Casos de prueba'!$C$5:$C$66,A34) -> 10 | C34: =COUNTIFS('Casos de prueba'!$C$5:$C$66,A34,'Casos de prueba'!$R$5:$R$66,"PASS") -> 7 | D34: =COUNTIFS('Casos de prueba'!$C$5:$C$66,A34,'Casos de prueba'!$X$5:$X$66,"PASS") -> 0 | E34: =COUNTIFS('Casos de prueba'!$C$5:$C$66,A34,'Casos de prueba'!$X$5:$X$66,"FAIL") -> 0 | F34: =IF(B34=0,0,D34/B34) -> 0
A35: EP-05 Infraestructura y despliegue | B35: =COUNTIF('Casos de prueba'!$C$5:$C$66,A35) -> 2 | C35: =COUNTIFS('Casos de prueba'!$C$5:$C$66,A35,'Casos de prueba'!$R$5:$R$66,"PASS") -> 2 | D35: =COUNTIFS('Casos de prueba'!$C$5:$C$66,A35,'Casos de prueba'!$X$5:$X$66,"PASS") -> 0 | E35: =COUNTIFS('Casos de prueba'!$C$5:$C$66,A35,'Casos de prueba'!$X$5:$X$66,"FAIL") -> 0 | F35: =IF(B35=0,0,D35/B35) -> 0
A36: Transversal | B36: =COUNTIF('Casos de prueba'!$C$5:$C$66,A36) -> 11 | C36: =COUNTIFS('Casos de prueba'!$C$5:$C$66,A36,'Casos de prueba'!$R$5:$R$66,"PASS") -> 5 | D36: =COUNTIFS('Casos de prueba'!$C$5:$C$66,A36,'Casos de prueba'!$X$5:$X$66,"PASS") -> 0 | E36: =COUNTIFS('Casos de prueba'!$C$5:$C$66,A36,'Casos de prueba'!$X$5:$X$66,"FAIL") -> 0 | F36: =IF(B36=0,0,D36/B36) -> 0
A38: 5. Estado de QA y QC | B38: Valor
A39: Nivel de cumplimiento del proceso (QA) | B39: ='QA Proceso'!C31 -> 0.92
A40: Nivel de calidad del producto (QC, ISO/IEC 25010) | B40: ='QC Producto'!D41 -> 0.84848485
A41: Requerimientos que cumplen en el ciclo 2 | B41: =Trazabilidad!M35 -> 0 de 30 cumplen

Sheet Casos de prueba
A1: Especificación y ejecución de casos de prueba
A2: Un caso por escenario de aceptación (Dado / Cuando / Entonces). Ciclo 1 = entorno local (ya ejecutado). Ciclo 2 = Azure (celdas amarillas, por llenar).
O3: CICLO 1 · LOCAL (11 al 25/10/2026) | U3: CICLO 2 · AZURE (25 al 29/10/2026)
A4: ID | B4: Tipo de prueba | C4: Épica / módulo | D4: Historia o requerimiento | E4: Escenario | F4: Requerimientos (RF / RNF) | G4: Caso | H4: Prioridad | I4: Precondiciones | J4: Pasos | K4: Datos de prueba | L4: Resultado esperado | M4: Técnica de diseño | N4: Forma de ejecución | O4: Fecha | P4: Ejecutado por | Q4: Resultado obtenido | R4: Estado | S4: Evidencia | T4: Defecto | U4: Fecha | V4: Ejecutado por | W4: Resultado obtenido | X4: Estado | Y4: Evidencia | Z4: Defecto
A5: CP-01 | B5: Funcional | C5: EP-01 Autenticación y control de acceso | D5: HU-001 | E5: CA-01 | F5: RF-001, RF-002, RNF-02 | G5: Inicio de sesión con credenciales válidas | H5: Alta | I5: El usuario está en la pantalla de inicio de sesión, sin sesión activa. | J5: Ingresar correo y contraseña válidos y pulsar Iniciar sesión. | K5: Usuario Empleado de prueba | L5: El sistema pide el código de verificación de 6 dígitos enviado al correo. | M5: Casos de uso | N5: Manual + automatizada (e2e) | O5: 25/10/2026 | P5: Sofia Ortiz Daza (asistida por Claude) | Q5: Con correo y contraseña válidos se pidió el código de 6 dígitos. | R5: PASS | S5: tests/e2e/e2e.sh, 47/47 pasos (25/10/2026); Recorrido en navegador con capturas (Figuras del plan de pruebas), Fig. 2 y 3 | X5: No ejecutado
A6: CP-02 | B6: Funcional | C6: EP-01 Autenticación y control de acceso | D6: HU-001 | E6: CA-02 | F6: RF-001, RF-002, RNF-02 | G6: Inicio de sesión con credenciales inválidas | H6: Alta | I6: El usuario está en la pantalla de inicio de sesión. | J6: Ingresar un correo registrado con una contraseña errada y enviar. | K6: Contraseña: "clave-erronea" | L6: Mensaje "Credenciales inválidas." sin indicar cuál dato está mal. No se envía código. | M6: Partición de equivalencia | N6: Manual + automatizada (e2e) | O6: 25/10/2026 | P6: Sofia Ortiz Daza (asistida por Claude) | Q6: HTTP 401 con el mensaje "Credenciales inválidas."; no se envió código. | R6: PASS | S6: tests/e2e/e2e.sh, 47/47 pasos (25/10/2026); backend/tests/auth.login.test.ts | X6: No ejecutado
A7: CP-03 | B7: Funcional | C7: EP-01 Autenticación y control de acceso | D7: HU-002 | E7: CA-01 | F7: RF-003 a RF-006, RNF-02, RNF-03 | G7: Código de verificación válido | H7: Alta | I7: El usuario recibió en su correo un código vigente (5 minutos). | J7: Escribir el código de 6 dígitos y pulsar Verificar código. | K7: Código recibido por correo | L7: El sistema abre el panel que corresponde al rol del usuario. | M7: Casos de uso | N7: Manual + automatizada (e2e) | O7: 25/10/2026 | P7: Sofia Ortiz Daza (asistida por Claude) | Q7: Con el código válido se abrió el panel de cada rol (Empleado, Verificador y Administrador). | R7: PASS | S7: Recorrido en navegador con capturas (Figuras del plan de pruebas), Fig. 4, 9 y 13; tests/e2e/e2e.sh, 47/47 pasos (25/10/2026) | X7: No ejecutado
A8: CP-04 | B8: Funcional | C8: EP-01 Autenticación y control de acceso | D8: HU-002 | E8: CA-02 | F8: RF-003 a RF-006, RNF-02, RNF-03 | G8: Acceso a un panel de otro rol | H8: Alta | I8: El Empleado tiene una sesión activa. (El rol se toma de la cuenta: no hay selector de rol.) | J8: Escribir en la barra de direcciones la ruta del panel de Administrador. | K8: Ruta /administrador/dashboard | L8: El sistema no muestra el panel y devuelve al usuario al inicio de sesión. La API responde 403 a cualquier acción de otro rol. | M8: Tabla de decisión | N8: Manual + automatizada (e2e) | Q8: Evidencia parcial: la API responde 403 a acciones de otro rol (e2e). Falta comprobar la redirección en pantalla. | R8: No ejecutado | X8: No ejecutado
A9: CP-05 | B9: Funcional | C9: EP-01 Autenticación y control de acceso | D9: HU-003 | E9: CA-01 | F9: RF-007, RNF-07 | G9: Cierre de sesión | H9: Alta | I9: El usuario tiene una sesión activa. | J9: Abrir el menú de usuario y elegir Cerrar sesión. | K9: Cualquier rol | L9: Se invalida la sesión en el servidor y aparece la pantalla de sesión cerrada. | M9: Casos de uso | N9: Manual + automatizada (e2e) | O9: 25/10/2026 | P9: Sofia Ortiz Daza (asistida por Claude) | Q9: El cierre de sesión respondió 204 y eliminó la sesión. | R9: PASS | S9: tests/e2e/e2e.sh, 47/47 pasos (25/10/2026). Pendiente ver la pantalla de sesión cerrada en el Ciclo 2. | X9: No ejecutado
A10: CP-06 | B10: Funcional | C10: EP-01 Autenticación y control de acceso | D10: HU-003 | E10: CA-02 | F10: RF-007, RNF-07 | G10: Acceso después de cerrar sesión | H10: Alta | I10: El usuario cerró sesión. | J10: Intentar abrir de nuevo una pantalla protegida (por ejemplo, Mis documentos). | K10: Ruta /empleado/documentos | L10: El sistema redirige al inicio de sesión. El token anterior ya no sirve (401). | M10: Transición de estados | N10: Manual + automatizada (e2e) | O10: 25/10/2026 | P10: Sofia Ortiz Daza (asistida por Claude) | Q10: El token de la sesión cerrada respondió 401. | R10: PASS | S10: tests/e2e/e2e.sh, 47/47 pasos (25/10/2026). Pendiente ver la redirección en pantalla en el Ciclo 2. | X10: No ejecutado
A11: CP-07 | B11: Funcional | C11: EP-01 Autenticación y control de acceso | D11: HU-004 | E11: CA-01 | F11: RF-052, RF-053, RNF-01 | G11: Cambio de contraseña correcto | H11: Media | I11: El usuario tiene sesión activa y conoce su contraseña actual. | J11: Menú de usuario, Cambiar contraseña: escribir la actual y una nueva de 8 o más caracteres; confirmar. | K11: Nueva: "OtraClave123" | L11: Mensaje de éxito. La nueva contraseña queda guardada como hash con sal; el siguiente inicio de sesión funciona solo con la nueva. | M11: Valores límite (8 caracteres) | N11: Manual + automatizada (e2e) | O11: 25/10/2026 | P11: Sofia Ortiz Daza (asistida por Claude) | Q11: Cambio aceptado (HTTP 200); después se usó la nueva contraseña como actual y también se aceptó. | R11: PASS | S11: tests/e2e/e2e.sh, 47/47 pasos (25/10/2026); backend/tests/auth.changePassword.test.ts | X11: No ejecutado
A12: CP-08 | B12: Funcional | C12: EP-01 Autenticación y control de acceso | D12: HU-004 | E12: CA-02 | F12: RF-052, RF-053, RNF-01 | G12: Cambio de contraseña con la actual errada | H12: Media | I12: El usuario tiene sesión activa. | J12: Escribir una contraseña actual incorrecta y una nueva válida; confirmar. | K12: Actual: "mala" | L12: Mensaje "La contraseña actual es incorrecta." y la contraseña no cambia. | M12: Partición de equivalencia | N12: Manual + automatizada (e2e) | O12: 25/10/2026 | P12: Sofia Ortiz Daza (asistida por Claude) | Q12: HTTP 400 con "La contraseña actual es incorrecta."; la contraseña no cambió. | R12: PASS | S12: tests/e2e/e2e.sh, 47/47 pasos (25/10/2026) | X12: No ejecutado
A13: CP-09 | B13: Funcional | C13: EP-01 Autenticación y control de acceso | D13: HU-022 | E13: CA-01 | F13: RF-054, RNF-06, RNF-07 | G13: Bloqueo tras 5 intentos fallidos | H13: Alta | I13: Una cuenta activa de prueba. | J13: Fallar la contraseña 5 veces seguidas y en el sexto intento usar la correcta. | K13: Usuario de prueba creado para el caso | L13: El sexto intento se rechaza con el mensaje de cuenta bloqueada temporalmente y los minutos que faltan. | M13: Valores límite (5 y 6 intentos) | N13: Manual + automatizada (e2e) | O13: 25/10/2026 | P13: Sofia Ortiz Daza (asistida por Claude) | Q13: Tras 5 intentos fallidos, el sexto con la contraseña correcta respondió 423 (cuenta bloqueada). | R13: PASS | S13: tests/e2e/e2e.sh, 47/47 pasos (25/10/2026) | X13: No ejecutado
A14: CP-10 | B14: Funcional | C14: EP-01 Autenticación y control de acceso | D14: HU-022 | E14: CA-02 | F14: RF-054, RNF-06, RNF-07 | G14: Desbloqueo pasados 15 minutos | H14: Media | I14: La cuenta del caso anterior está bloqueada. | J14: Esperar 15 minutos e iniciar sesión con la contraseña correcta. | K14: El mismo usuario de prueba | L14: El sistema continúa con el envío del código y el contador de intentos vuelve a cero. | M14: Valores límite (15 minutos) | N14: Manual | O14: 25/10/2026 | P14: Sofia Ortiz Daza (asistida por Claude) | Q14: Prueba unitaria: con el bloqueo vencido, el inicio de sesión continúa (HTTP 200). La espera real de 15 minutos queda para el Ciclo 2. | R14: PASS | S14: backend/tests/auth.login.test.ts, "bloqueo ya vencido" | X14: No ejecutado
A15: CP-11 | B15: Funcional | C15: EP-01 Autenticación y control de acceso | D15: HU-022 | E15: CA-03 | F15: RF-054, RNF-06, RNF-07 | G15: Registro de intentos fallidos | H15: Media | I15: Un usuario escribe credenciales incorrectas. | J15: Enviar el formulario con una contraseña errada y revisar el registro de intentos. | K15: Contraseña errada | L15: Queda registrado el correo, la fecha, la hora y el motivo, sin guardar la contraseña. Pendiente de implementar (DEF-03). | M15: Casos de uso | N15: Manual | O15: 27/10/2026 | P15: Sofia Ortiz Daza (asistida por Claude) | Q15: Re-prueba tras corregir DEF-03: cada intento fallido queda en login_attempts con correo, motivo y fecha, sin la contraseña; se borra a los 90 días. | R15: PASS | S15: backend/tests/auth.login.test.ts; consulta a MongoDB del 27/10/2026 | T15: DEF-03 | X15: No ejecutado
A16: CP-12 | B16: Funcional | C16: EP-01 Autenticación y control de acceso | D16: HU-022 | E16: CA-04 | F16: RF-054, RNF-06, RNF-07 | G16: Cierre por inactividad | H16: Media | I16: El usuario tiene una sesión activa. | J16: No usar el sistema durante 15 minutos y luego intentar una acción. | K16: Cualquier rol | L16: La sesión se cierra y el sistema exige iniciar sesión de nuevo. | M16: Valores límite (15 minutos) | N16: Manual + automatizada (unitaria) | O16: 25/10/2026 | P16: Sofia Ortiz Daza (asistida por Claude) | Q16: Prueba unitaria: una sesión con 16 minutos sin actividad responde 401 y se elimina. | R16: PASS | S16: backend/tests/auth.middleware.test.ts | X16: No ejecutado
A17: CP-13 | B17: Funcional | C17: EP-01 Autenticación y control de acceso | D17: HU-023 | E17: CA-01 | F17: RF-055, Ley 1581 de 2012 | G17: Política de datos en el primer ingreso | H17: Alta | I17: Un usuario inicia sesión por primera vez. | J17: Completar el inicio de sesión y el código. | K17: Usuario nuevo | L17: Se presenta la política de tratamiento de datos y no se habilita nada más hasta aceptarla. Pendiente de implementar (DEF-04). | M17: Casos de uso | N17: Manual | O17: 27/10/2026 | P17: Sofia Ortiz Daza (asistida por Claude) | Q17: Re-prueba tras corregir DEF-04: en el primer ingreso aparece la política (versión 1.0) y el botón queda deshabilitado hasta marcar la casilla. | R17: PASS | S17: docs/evidencias/politica-datos-primer-ingreso.jpg | T17: DEF-04 | X17: No ejecutado
A18: CP-14 | B18: Funcional | C18: EP-01 Autenticación y control de acceso | D18: HU-023 | E18: CA-02 | F18: RF-055, Ley 1581 de 2012 | G18: Aceptación de la política | H18: Alta | I18: El usuario ve la política de tratamiento de datos. | J18: Pulsar Aceptar. | K18: Usuario nuevo | L18: Se registra usuario, fecha, hora y versión aceptada, y se abre su panel. Pendiente de implementar (DEF-04). | M18: Casos de uso | N18: Manual | O18: 27/10/2026 | P18: Sofia Ortiz Daza (asistida por Claude) | Q18: Al aceptar, se guarda usuario, fecha, hora y versión 1.0, y se abre el panel del rol. | R18: PASS | S18: backend/tests/auth.policy.test.ts; registro en MongoDB del 27/10/2026 | T18: DEF-04 | X18: No ejecutado
A19: CP-15 | B19: Funcional | C19: EP-01 Autenticación y control de acceso | D19: HU-023 | E19: CA-03 | F19: RF-055, Ley 1581 de 2012 | G19: Acceso sin aceptar la política | H19: Alta | I19: El usuario no ha aceptado la política. | J19: Intentar abrir otra pantalla del sistema. | K19: Usuario nuevo | L19: El sistema lo impide y mantiene la solicitud de aceptación. Pendiente de implementar (DEF-04). | M19: Transición de estados | N19: Manual | O19: 27/10/2026 | P19: Sofia Ortiz Daza (asistida por Claude) | Q19: Sin aceptar, toda ruta de negocio responde 403 POLICY_REQUIRED y la interfaz vuelve a la política. | R19: PASS | S19: backend/tests/auth.policy.test.ts; prueba por API del 27/10/2026 | T19: DEF-04 | X19: No ejecutado
A20: CP-16 | B20: Funcional | C20: EP-02 Registro y gestión documental (Empleado) | D20: HU-005 | E20: CA-01 | F20: RF-008 a RF-012, RNF-23, RNF-24 | G20: Carga de un PDF válido de 10 MB | H20: Alta | I20: El Empleado está en Cargar documento. | J20: Seleccionar un PDF de 10 MB y pulsar Cargar y generar SHA-256. | K20: PDF sintético de 10 MB | L20: El archivo se acepta y continúa el registro. | M20: Partición de equivalencia | N20: Manual | Q20: No se ha probado con un PDF de 10 MB. | R20: No ejecutado | X20: No ejecutado
A21: CP-17 | B21: Funcional | C21: EP-02 Registro y gestión documental (Empleado) | D21: HU-005 | E21: CA-02 | F21: RF-008 a RF-012, RNF-23, RNF-24 | G21: Rechazo de DOCX o PDF de 25 MB | H21: Alta | I21: El Empleado está en Cargar documento. | J21: Intentar cargar un archivo .docx y luego un PDF de 25 MB. | K21: archivo.docx; PDF de 25 MB | L21: Ambos se rechazan con el motivo: solo PDF de hasta 20 MB. | M21: Valores límite (20 MB) | N21: Manual + automatizada (e2e) | O21: 25/10/2026 | P21: Sofia Ortiz Daza (asistida por Claude) | Q21: Archivo que no es PDF: HTTP 400. PDF de 25 MB: HTTP 413 con "El archivo debe ser un único PDF de hasta 20MB." | R21: PASS | S21: tests/e2e/e2e.sh, 47/47 pasos (25/10/2026); prueba del proxy nginx del 25/10/2026 | X21: No ejecutado
A22: CP-18 | B22: Funcional | C22: EP-02 Registro y gestión documental (Empleado) | D22: HU-006 | E22: CA-01 | F22: RF-013 a RF-015, RNF-11, RNF-13 | G22: Metadatos y huella automáticos | H22: Alta | I22: Un PDF superó las validaciones de carga. | J22: Completar la carga. | K22: C01 de los documentos de prueba | L22: Se muestran identificador, nombre, responsable, fecha y la huella SHA-256 (enmascarada para el Empleado). | M22: Casos de uso | N22: Manual + automatizada (e2e) | O22: 25/10/2026 | P22: Sofia Ortiz Daza (asistida por Claude) | Q22: Se mostraron identificador, nombre, fecha de registro y huella SHA-256 enmascarada. | R22: PASS | S22: Recorrido en navegador con capturas (Figuras del plan de pruebas), Fig. 4 | X22: No ejecutado
A23: CP-19 | B23: Funcional | C23: EP-02 Registro y gestión documental (Empleado) | D23: HU-006 | E23: CA-02 | F23: RF-013 a RF-015, RNF-11, RNF-13 | G23: La huella no cambia para el mismo contenido | H23: Alta | I23: Un documento ya registrado. | J23: Verificar ese mismo archivo (el sistema recalcula su huella). | K23: Archivo original sin cambios | L23: El hash recalculado es exactamente igual al registrado: "Integridad confirmada". | M23: Casos de uso | N23: Manual + automatizada (integridad) | O23: 25/10/2026 | P23: Sofia Ortiz Daza (asistida por Claude) | Q23: Los 20 originales, al verificarse, dieron exactamente el mismo hash registrado (Verificado). | R23: PASS | S23: tests/integrity, corrida 2026-10-25-18-05 | X23: No ejecutado
A24: CP-20 | B24: Funcional | C24: EP-02 Registro y gestión documental (Empleado) | D24: HU-007 | E24: CA-01 | F24: RF-016, RF-017, RNF-04, RNF-05, RNF-20 | G24: Registro en la blockchain con txID | H24: Alta | I24: La huella del documento fue generada. | J24: Completar la carga y abrir Mi trazabilidad. | K24: Documento recién cargado | L24: Aparece el evento Carga de documento con su identificador de transacción (TX). | M24: Casos de uso | N24: Manual + automatizada (e2e) | O24: 25/10/2026 | P24: Sofia Ortiz Daza (asistida por Claude) | Q24: Mi trazabilidad mostró el evento "Carga de documento" con su TX. | R24: PASS | S24: Recorrido en navegador con capturas (Figuras del plan de pruebas), Fig. 6; tests/e2e/e2e.sh, 47/47 pasos (25/10/2026) | X24: No ejecutado
A25: CP-21 | B25: Funcional | C25: EP-02 Registro y gestión documental (Empleado) | D25: HU-007 | E25: CA-02 | F25: RF-016, RF-017, RNF-04, RNF-05, RNF-20 | G25: Falla de la red blockchain | H25: Alta | I25: La red Fabric no está disponible (se detiene el peer en el entorno local). | J25: Intentar cargar un PDF. | K25: Peer detenido (solo entorno local) | L25: No aparece mensaje de éxito; se informa que la red blockchain no está disponible. | M25: Adivinación de errores | N25: Automatizada (unitaria) + manual local | O25: 25/10/2026 | P25: Sofia Ortiz Daza (asistida por Claude) | Q25: Prueba unitaria: con la red caída, la carga responde 502 "La red blockchain no está disponible..." y no hay mensaje de éxito. | R25: PASS | S25: backend/tests/events.test.ts y documents.test.ts. Prueba manual deteniendo el peer pendiente. | X25: No ejecutado
A26: CP-22 | B26: Funcional | C26: EP-02 Registro y gestión documental (Empleado) | D26: HU-008 | E26: CA-01 | F26: RF-018 a RF-020, RNF-09 | G26: Mis documentos muestra solo los propios | H26: Alta | I26: Dos Empleados con documentos cargados. | J26: Cada Empleado abre Mis documentos. | K26: Empleado 1 y Empleado 2 | L26: Cada uno ve únicamente sus documentos con su estado actual. | M26: Tabla de decisión | N26: Manual + automatizada (e2e) | O26: 25/10/2026 | P26: Sofia Ortiz Daza (asistida por Claude) | Q26: Cada Empleado vio solo sus documentos; el Empleado 2 vio 0 documentos de María López. | R26: PASS | S26: tests/e2e/e2e.sh, 47/47 pasos (25/10/2026); Recorrido en navegador con capturas (Figuras del plan de pruebas), Fig. 5 | X26: No ejecutado
A27: CP-23 | B27: Funcional | C27: EP-02 Registro y gestión documental (Empleado) | D27: HU-008 | E27: CA-02 | F27: RF-018 a RF-020, RNF-09 | G27: Estado inicial Pendiente | H27: Media | I27: Un documento sin verificaciones. | J27: Abrir Mis documentos. | K27: Documento recién cargado | L27: El documento aparece con estado Pendiente. | M27: Transición de estados | N27: Manual + automatizada (e2e) | O27: 25/10/2026 | P27: Sofia Ortiz Daza (asistida por Claude) | Q27: El documento recién cargado apareció como "pendiente". | R27: PASS | S27: Recorrido en navegador con capturas (Figuras del plan de pruebas), Fig. 5 (ver DEF-05 por la minúscula) | X27: No ejecutado
A28: CP-24 | B28: Funcional | C28: EP-02 Registro y gestión documental (Empleado) | D28: HU-009 | E28: CA-01 | F28: RF-021, RF-022, RNF-06, RNF-26, RNF-27 | G28: Trazabilidad de mis documentos | H28: Alta | I28: Un documento con carga y verificaciones. | J28: Abrir Mi trazabilidad. | K28: Documento C01 | L28: Historial en orden cronológico con documento, acción, fecha, hora, TX y resultado. | M28: Casos de uso | N28: Manual + automatizada (e2e) | O28: 25/10/2026 | P28: Sofia Ortiz Daza (asistida por Claude) | Q28: Historial en orden cronológico con acción, fecha, hora, TX y resultado. | R28: PASS | S28: Recorrido en navegador con capturas (Figuras del plan de pruebas), Fig. 6 | X28: No ejecutado
A29: CP-25 | B29: Funcional | C29: EP-02 Registro y gestión documental (Empleado) | D29: HU-009 | E29: CA-02 | F29: RF-021, RF-022, RNF-06, RNF-26, RNF-27 | G29: Trazabilidad de un documento ajeno | H29: Alta | I29: Un documento de otro Empleado. | J29: Pedir su trazabilidad (por la API con la sesión del Empleado 2). | K29: Identificador de un documento del Empleado 1 | L29: El sistema deniega el acceso (403). | M29: Tabla de decisión | N29: Automatizada (e2e) | O29: 25/10/2026 | P29: Sofia Ortiz Daza (asistida por Claude) | Q29: La trazabilidad de un documento ajeno respondió 403. | R29: PASS | S29: tests/e2e/e2e.sh, 47/47 pasos (25/10/2026) | X29: No ejecutado
A30: CP-26 | B30: Funcional | C30: EP-03 Verificación de integridad documental (Verificador) | D30: HU-010 | E30: CA-01 | F30: RF-023 a RF-025 | G30: Selección de un documento registrado | H30: Alta | I30: Existen documentos registrados. | J30: Elegir la persona responsable y luego el contrato (o pegar el identificador). | K30: Documento C01 | L30: El sistema confirma el documento y habilita la carga del archivo a comparar. | M30: Casos de uso | N30: Manual + automatizada (e2e) | O30: 25/10/2026 | P30: Sofia Ortiz Daza (asistida por Claude) | Q30: Se eligió el documento por persona y contrato, y también pegando el identificador; se habilitó la carga a comparar. | R30: PASS | S30: Recorrido en navegador con capturas (Figuras del plan de pruebas), Fig. 7 y 8 | X30: No ejecutado
A31: CP-27 | B31: Funcional | C31: EP-03 Verificación de integridad documental (Verificador) | D31: HU-010 | E31: CA-02 | F31: RF-023 a RF-025 | G31: Identificador inexistente | H31: Media | I31: El Verificador está en Verificar integridad. | J31: Pegar un identificador que no existe y pulsar Buscar. | K31: 00000000-0000-0000-0000-000000000000 | L31: Mensaje "El documento no está registrado." | M31: Partición de equivalencia | N31: Manual + automatizada (e2e) | O31: 25/10/2026 | P31: Sofia Ortiz Daza (asistida por Claude) | Q31: Un identificador inexistente respondió 404 "El documento no está registrado." | R31: PASS | S31: tests/e2e/e2e.sh, 47/47 pasos (25/10/2026) | X31: No ejecutado
A32: CP-28 | B32: Funcional | C32: EP-03 Verificación de integridad documental (Verificador) | D32: HU-011 | E32: CA-01 | F32: RF-026, RF-027, RNF-08 | G32: Huella completa para el Verificador | H32: Alta | I32: Un documento existente. | J32: Seleccionarlo en Verificar integridad. | K32: Documento C01 | L32: Se muestra el hash SHA-256 registrado completo (64 caracteres). | M32: Tabla de decisión | N32: Manual + automatizada (e2e) | O32: 25/10/2026 | P32: Sofia Ortiz Daza (asistida por Claude) | Q32: El Verificador vio la huella completa de 64 caracteres. | R32: PASS | S32: Recorrido en navegador con capturas (Figuras del plan de pruebas), Fig. 8; tests/e2e/e2e.sh, 47/47 pasos (25/10/2026) | X32: No ejecutado
A33: CP-29 | B33: Funcional | C33: EP-03 Verificación de integridad documental (Verificador) | D33: HU-011 | E33: CA-02 | F33: RF-026, RF-027, RNF-08 | G33: Empleado sin acceso a la huella ajena | H33: Alta | I33: Un Empleado y un documento de otra persona. | J33: Consultar el documento ajeno por la API con la sesión del Empleado. | K33: Sesión del Empleado 2 | L33: El acceso se deniega; el Empleado solo ve huellas enmascaradas de lo suyo. | M33: Tabla de decisión | N33: Automatizada (e2e) | O33: 27/10/2026 | P33: Sofia Ortiz Daza (asistida por Claude) | Q33: Re-prueba tras corregir DEF-06: el Empleado 2 recibe 403 al pedir el documento de María López. | R33: PASS | S33: backend/tests/documents.test.ts; GET /documents/{id} del 27/10/2026 | T33: DEF-06 | X33: No ejecutado
A34: CP-30 | B34: Funcional | C34: EP-03 Verificación de integridad documental (Verificador) | D34: HU-012 | E34: CA-01 | F34: RF-028, RF-029, RNF-23, RNF-24 | G34: Carga del archivo a comparar | H34: Media | I34: Documento seleccionado. | J34: Cargar un PDF válido en el paso 2. | K34: PDF válido | L34: El archivo aparece como Listo y se habilita Comparar huellas SHA-256. | M34: Casos de uso | N34: Manual | O34: 25/10/2026 | P34: Sofia Ortiz Daza (asistida por Claude) | Q34: El archivo apareció como "Listo" y se habilitó "Comparar huellas SHA-256". | R34: PASS | S34: Recorrido en navegador con capturas (Figuras del plan de pruebas), Fig. 8 | X34: No ejecutado
A35: CP-31 | B35: Funcional | C35: EP-03 Verificación de integridad documental (Verificador) | D35: HU-012 | E35: CA-02 | F35: RF-028, RF-029, RNF-23, RNF-24 | G35: Archivo a comparar de 30 MB | H35: Media | I35: Documento seleccionado. | J35: Intentar cargar un PDF de 30 MB. | K35: PDF de 30 MB | L35: Se rechaza informando el límite de 20 MB. | M35: Valores límite (20 MB) | N35: Manual | Q35: No se ha probado con un PDF de 30 MB en la verificación. | R35: No ejecutado | X35: No ejecutado
A36: CP-32 | B36: Funcional | C36: EP-03 Verificación de integridad documental (Verificador) | D36: HU-013 | E36: CA-01 | F36: RF-030 a RF-033, RNF-10, RNF-14 | G36: Huellas idénticas | H36: Alta | I36: Documento seleccionado y el mismo archivo original. | J36: Pulsar Comparar huellas SHA-256. | K36: Original de C01 | L36: Mensaje "Integridad confirmada: los hashes son idénticos" con ambas huellas. | M36: Casos de uso | N36: Manual + automatizada (integridad) | O36: 25/10/2026 | P36: Sofia Ortiz Daza (asistida por Claude) | Q36: "Integridad confirmada: los hashes son idénticos" con ambas huellas. | R36: PASS | S36: Recorrido en navegador con capturas (Figuras del plan de pruebas), Fig. 9 | X36: No ejecutado
A37: CP-33 | B37: Funcional | C37: EP-03 Verificación de integridad documental (Verificador) | D37: HU-013 | E37: CA-02 | F37: RF-030 a RF-033, RNF-10, RNF-14 | G37: Huellas distintas | H37: Alta | I37: Documento seleccionado y una copia alterada. | J37: Pulsar Comparar huellas SHA-256. | K37: Alterado de C01 (salario) | L37: Mensaje "Integridad comprometida: los hashes no coinciden" y se muestran las dos huellas. | M37: Casos de uso | N37: Manual + automatizada (integridad) | O37: 25/10/2026 | P37: Sofia Ortiz Daza (asistida por Claude) | Q37: "Integridad comprometida: los hashes no coinciden" con las dos huellas distintas. | R37: PASS | S37: Recorrido en navegador con capturas (Figuras del plan de pruebas), Fig. 10 | X37: No ejecutado
A38: CP-34 | B38: Funcional | C38: EP-03 Verificación de integridad documental (Verificador) | D38: HU-014 | E38: CA-01 | F38: RF-034 a RF-036, RNF-05, RNF-27 | G38: Estado Verificado y evento en el ledger | H38: Alta | I38: Una verificación con huellas iguales. | J38: Revisar el estado del documento y la trazabilidad. | K38: Documento C01 | L38: El estado cambia a Verificado y aparece el evento con su TX y resultado OK. | M38: Transición de estados | N38: Manual + automatizada (e2e) | O38: 25/10/2026 | P38: Sofia Ortiz Daza (asistida por Claude) | Q38: El estado pasó a Verificado y el evento quedó en el ledger con su TX. | R38: PASS | S38: tests/e2e/e2e.sh, 47/47 pasos (25/10/2026); tests/integrity (trazabilidad 20/20) | X38: No ejecutado
A39: CP-35 | B39: Funcional | C39: EP-03 Verificación de integridad documental (Verificador) | D39: HU-014 | E39: CA-02 | F39: RF-034 a RF-036, RNF-05, RNF-27 | G39: Nueva verificación | H39: Baja | I39: El Verificador terminó una verificación. | J39: Pulsar Nueva verificación. | K39: N/A | L39: Vuelve el formulario vacío de selección de documento. | M39: Casos de uso | N39: Manual | O39: 25/10/2026 | P39: Sofia Ortiz Daza (asistida por Claude) | Q39: "Nueva verificación" volvió al formulario vacío de selección. | R39: PASS | S39: Recorrido en navegador con capturas (Figuras del plan de pruebas). Ver DEF-01 (la lista conserva el estado anterior) | X39: No ejecutado
A40: CP-36 | B40: Funcional | C40: EP-03 Verificación de integridad documental (Verificador) | D40: HU-015 | E40: CA-01 | F40: RF-037, RF-038, RNF-08 | G40: Listado general de documentos | H40: Media | I40: El Verificador inicia sesión. | J40: Abrir Documentos. | K40: N/A | L40: Se ven todos los documentos con sus seis campos: nombre, responsable, fecha, identificador, huella y estado. | M40: Casos de uso | N40: Manual + automatizada (e2e) | O40: 25/10/2026 | P40: Sofia Ortiz Daza (asistida por Claude) | Q40: Listado con nombre, responsable, fecha, identificador, huella y estado. | R40: PASS | S40: Recorrido en navegador con capturas (Figuras del plan de pruebas), Fig. 11 | X40: No ejecutado
...

Sheet Defectos
A1: Registro de defectos (informe de incidentes)
A2: Campos según ISO/IEC/IEEE 29119-3: momento, originador, contexto, descripción, severidad, prioridad, riesgo y estado.
A4: ID | B4: Fecha de reporte | C4: Reportado por | D4: Caso | E4: Módulo | F4: Entorno | G4: Título | H4: Pasos para reproducir | I4: Resultado esperado | J4: Resultado obtenido | K4: Severidad | L4: Prioridad | M4: Riesgo si no se corrige | N4: Estado | O4: Asignado a | P4: Fecha de corrección | Q4: Fecha de cierre | R4: Evidencia
A5: DEF-01 | B5: 25/10/2026 | C5: Sofia Ortiz Daza (asistida por Claude) | D5: CP-35 | E5: EP-03 Verificación | F5: Local, Chrome | G5: La lista de contratos del Verificador no se actualiza después de verificar | H5: 1. Entrar como Verificador. 2. Verificar un documento Pendiente. 3. Pulsar Nueva verificación. 4. Abrir la lista de contratos. | I5: El documento muestra su nuevo estado (Verificado o Alterado). | J5: Sigue apareciendo como Pendiente hasta recargar la página. | K5: Baja | L5: P3 Media | M5: El Verificador puede creer que un documento no se ha verificado. | N5: Nuevo | O5: Laura Sofia Diaz Suarez | R5: Captura del selector (Fig. 7); la lista se carga una sola vez al abrir la pantalla
A6: DEF-02 | B6: 25/10/2026 | C6: Sofia Ortiz Daza (asistida por Claude) | D6: CP-03 | E6: EP-01 Autenticación | F6: Local, Chrome | G6: "Reenviar código" no envía un código nuevo | H6: 1. Iniciar sesión con credenciales válidas. 2. En la pantalla del código, pulsar Reenviar código. | I6: Se envía un nuevo código al correo. | J6: Solo se borran los campos del código; no llega ningún correo nuevo. | K6: Media | L6: P2 Alta | M6: Si el código vence o no llega, el usuario debe volver a iniciar sesión. | N6: Nuevo | O6: Laura Sofia Diaz Suarez | R6: frontend/src/pages/OtpPage.tsx (el botón solo limpia el código)
A7: DEF-03 | B7: 25/10/2026 | C7: Sofia Ortiz Daza (asistida por Claude) | D7: CP-11 | E7: EP-01 Autenticación | F7: Local | G7: No se registran los intentos fallidos de inicio de sesión | H7: 1. Iniciar sesión con una contraseña errada. 2. Buscar el registro del intento. | I7: Queda registrado el correo, la fecha, la hora y el motivo, sin la contraseña. | J7: Solo se cuenta el intento para el bloqueo; no hay registro consultable. | K7: Media | L7: P2 Alta | M7: No se pueden auditar accesos sospechosos (HU-022 CA-03, RNF-06). | N7: Corregido | O7: Sofia Ortiz Daza | P7: 27/10/2026 | R7: Revisión de backend/src/services/authService.ts
A8: DEF-04 | B8: 25/10/2026 | C8: Sofia Ortiz Daza (asistida por Claude) | D8: CP-13 a CP-15 | E8: EP-01 Autenticación | F8: Local | G8: No existe la aceptación de la política de tratamiento de datos | H8: 1. Crear un usuario. 2. Iniciar sesión por primera vez. | I8: Se muestra la política y no se habilita nada hasta aceptarla; se registra la aceptación. | J8: El usuario entra directo a su panel. | K8: Alta | L8: P1 Urgente | M8: Incumple la autorización previa de la Ley 1581 de 2012 (RF-055). | N8: Corregido | O8: Sofia y Laura | P8: 27/10/2026 | R8: Funcionalidad no implementada
A9: DEF-05 | B9: 25/10/2026 | C9: Sofia Ortiz Daza (asistida por Claude) | D9: CP-22 | E9: EP-02 Gestión documental | F9: Local, Chrome | G9: Los estados se muestran en minúscula | H9: 1. Abrir Mis documentos. | I9: Pendiente, Verificado, Alterado (como en el resto del sistema). | J9: pendiente, alterado. | K9: Baja | L9: P4 Baja | M9: Inconsistencia visual. | N9: Nuevo | O9: Laura Sofia Diaz Suarez | R9: Fig. 5
A10: DEF-06 | B10: 25/10/2026 | C10: Sofia Ortiz Daza (asistida por Claude) | D10: CP-29 | E10: EP-03 Verificación | F10: Local, API | G10: Un Empleado puede consultar los datos de un documento ajeno | H10: 1. Iniciar sesión como Empleado 2. 2. Pedir GET /documents/{id} de un documento de María López. | I10: Acceso denegado (403). | J10: HTTP 200 con nombre, responsable, fecha y estado del documento ajeno (la huella sí sale enmascarada). | K10: Media | L10: P2 Alta | M10: Exposición de datos personales de otros empleados (RNF-08, Ley 1581 de 2012). | N10: Corregido | O10: Sofia Ortiz Daza | P10: 27/10/2026 | R10: Respuesta HTTP 200 registrada el 25/10/2026

Sheet Trazabilidad
A1: Matriz de trazabilidad y cumplimiento de requerimientos
A2: Todo lo numérico se calcula desde la hoja "Casos de prueba". El estado oficial es el del Ciclo 2 (Azure).
A4: Historia / requerimiento | B4: Descripción | C4: RF | D4: RNF / norma | E4: Casos | F4: N.° de casos | G4: PASS ciclo 1 | H4: FAIL ciclo 1 | I4: PASS ciclo 2 | J4: FAIL ciclo 2 | K4: Pendientes ciclo 2 | L4: Cobertura (ciclo 1) | M4: Cumplimiento (ciclo 2)
A5: HU-001 | B5: Selección de rol e inicio con credenciales corporativas | C5: RF-001, RF-002 | D5: RNF-02 | E5: CP-01, CP-02 | F5: =COUNTIF('Casos de prueba'!$D$5:$D$66,A5) -> 2 | G5: =COUNTIFS('Casos de prueba'!$D$5:$D$66,A5,'Casos de prueba'!$R$5:$R$66,"PASS") -> 2 | H5: =COUNTIFS('Casos de prueba'!$D$5:$D$66,A5,'Casos de prueba'!$R$5:$R$66,"FAIL") -> 0 | I5: =COUNTIFS('Casos de prueba'!$D$5:$D$66,A5,'Casos de prueba'!$X$5:$X$66,"PASS") -> 0 | J5: =COUNTIFS('Casos de prueba'!$D$5:$D$66,A5,'Casos de prueba'!$X$5:$X$66,"FAIL") -> 0 | K5: =F5-I5-J5 -> 2 | L5: =IF(F5=0,"Sin casos",IF(H5>0,"Con fallas",IF(G5=F5,"Cubierto","Parcial"))) -> Cubierto | M5: =IF(F5=0,"Sin casos",IF(J5>0,"No cumple",IF(I5=F5,"Cumple","Pendiente"))) -> Pendiente
A6: HU-002 | B6: Autenticación de doble factor y acceso por rol | C6: RF-003 a RF-006 | D6: RNF-02, RNF-03 | E6: CP-03, CP-04 | F6: =COUNTIF('Casos de prueba'!$D$5:$D$66,A6) -> 2 | G6: =COUNTIFS('Casos de prueba'!$D$5:$D$66,A6,'Casos de prueba'!$R$5:$R$66,"PASS") -> 1 | H6: =COUNTIFS('Casos de prueba'!$D$5:$D$66,A6,'Casos de prueba'!$R$5:$R$66,"FAIL") -> 0 | I6: =COUNTIFS('Casos de prueba'!$D$5:$D$66,A6,'Casos de prueba'!$X$5:$X$66,"PASS") -> 0 | J6: =COUNTIFS('Casos de prueba'!$D$5:$D$66,A6,'Casos de prueba'!$X$5:$X$66,"FAIL") -> 0 | K6: =F6-I6-J6 -> 2 | L6: =IF(F6=0,"Sin casos",IF(H6>0,"Con fallas",IF(G6=F6,"Cubierto","Parcial"))) -> Parcial | M6: =IF(F6=0,"Sin casos",IF(J6>0,"No cumple",IF(I6=F6,"Cumple","Pendiente"))) -> Pendiente
A7: HU-003 | B7: Cierre de sesión seguro | C7: RF-007 | D7: RNF-07 | E7: CP-05, CP-06 | F7: =COUNTIF('Casos de prueba'!$D$5:$D$66,A7) -> 2 | G7: =COUNTIFS('Casos de prueba'!$D$5:$D$66,A7,'Casos de prueba'!$R$5:$R$66,"PASS") -> 2 | H7: =COUNTIFS('Casos de prueba'!$D$5:$D$66,A7,'Casos de prueba'!$R$5:$R$66,"FAIL") -> 0 | I7: =COUNTIFS('Casos de prueba'!$D$5:$D$66,A7,'Casos de prueba'!$X$5:$X$66,"PASS") -> 0 | J7: =COUNTIFS('Casos de prueba'!$D$5:$D$66,A7,'Casos de prueba'!$X$5:$X$66,"FAIL") -> 0 | K7: =F7-I7-J7 -> 2 | L7: =IF(F7=0,"Sin casos",IF(H7>0,"Con fallas",IF(G7=F7,"Cubierto","Parcial"))) -> Cubierto | M7: =IF(F7=0,"Sin casos",IF(J7>0,"No cumple",IF(I7=F7,"Cumple","Pendiente"))) -> Pendiente
A8: HU-004 | B8: Cambio de contraseña | C8: RF-052, RF-053 | D8: RNF-01 | E8: CP-07, CP-08 | F8: =COUNTIF('Casos de prueba'!$D$5:$D$66,A8) -> 2 | G8: =COUNTIFS('Casos de prueba'!$D$5:$D$66,A8,'Casos de prueba'!$R$5:$R$66,"PASS") -> 2 | H8: =COUNTIFS('Casos de prueba'!$D$5:$D$66,A8,'Casos de prueba'!$R$5:$R$66,"FAIL") -> 0 | I8: =COUNTIFS('Casos de prueba'!$D$5:$D$66,A8,'Casos de prueba'!$X$5:$X$66,"PASS") -> 0 | J8: =COUNTIFS('Casos de prueba'!$D$5:$D$66,A8,'Casos de prueba'!$X$5:$X$66,"FAIL") -> 0 | K8: =F8-I8-J8 -> 2 | L8: =IF(F8=0,"Sin casos",IF(H8>0,"Con fallas",IF(G8=F8,"Cubierto","Parcial"))) -> Cubierto | M8: =IF(F8=0,"Sin casos",IF(J8>0,"No cumple",IF(I8=F8,"Cumple","Pendiente"))) -> Pendiente
A9: HU-005 | B9: Carga y validación de documentos contractuales | C9: RF-008 a RF-012 | D9: RNF-23, RNF-24 | E9: CP-16, CP-17 | F9: =COUNTIF('Casos de prueba'!$D$5:$D$66,A9) -> 2 | G9: =COUNTIFS('Casos de prueba'!$D$5:$D$66,A9,'Casos de prueba'!$R$5:$R$66,"PASS") -> 1 | H9: =COUNTIFS('Casos de prueba'!$D$5:$D$66,A9,'Casos de prueba'!$R$5:$R$66,"FAIL") -> 0 | I9: =COUNTIFS('Casos de prueba'!$D$5:$D$66,A9,'Casos de prueba'!$X$5:$X$66,"PASS") -> 0 | J9: =COUNTIFS('Casos de prueba'!$D$5:$D$66,A9,'Casos de prueba'!$X$5:$X$66,"FAIL") -> 0 | K9: =F9-I9-J9 -> 2 | L9: =IF(F9=0,"Sin casos",IF(H9>0,"Con fallas",IF(G9=F9,"Cubierto","Parcial"))) -> Parcial | M9: =IF(F9=0,"Sin casos",IF(J9>0,"No cumple",IF(I9=F9,"Cumple","Pendiente"))) -> Pendiente
A10: HU-006 | B10: Registro de metadatos y generación de huella criptográfica | C10: RF-013 a RF-015 | D10: RNF-11, RNF-13 | E10: CP-18, CP-19 | F10: =COUNTIF('Casos de prueba'!$D$5:$D$66,A10) -> 2 | G10: =COUNTIFS('Casos de prueba'!$D$5:$D$66,A10,'Casos de prueba'!$R$5:$R$66,"PASS") -> 2 | H10: =COUNTIFS('Casos de prueba'!$D$5:$D$66,A10,'Casos de prueba'!$R$5:$R$66,"FAIL") -> 0 | I10: =COUNTIFS('Casos de prueba'!$D$5:$D$66,A10,'Casos de prueba'!$X$5:$X$66,"PASS") -> 0 | J10: =COUNTIFS('Casos de prueba'!$D$5:$D$66,A10,'Casos de prueba'!$X$5:$X$66,"FAIL") -> 0 | K10: =F10-I10-J10 -> 2 | L10: =IF(F10=0,"Sin casos",IF(H10>0,"Con fallas",IF(G10=F10,"Cubierto","Parcial"))) -> Cubierto | M10: =IF(F10=0,"Sin casos",IF(J10>0,"No cumple",IF(I10=F10,"Cumple","Pendiente"))) -> Pendiente
A11: HU-007 | B11: Registro de la huella en la red blockchain | C11: RF-016, RF-017 | D11: RNF-04, RNF-05, RNF-20 | E11: CP-20, CP-21 | F11: =COUNTIF('Casos de prueba'!$D$5:$D$66,A11) -> 2 | G11: =COUNTIFS('Casos de prueba'!$D$5:$D$66,A11,'Casos de prueba'!$R$5:$R$66,"PASS") -> 2 | H11: =COUNTIFS('Casos de prueba'!$D$5:$D$66,A11,'Casos de prueba'!$R$5:$R$66,"FAIL") -> 0 | I11: =COUNTIFS('Casos de prueba'!$D$5:$D$66,A11,'Casos de prueba'!$X$5:$X$66,"PASS") -> 0 | J11: =COUNTIFS('Casos de prueba'!$D$5:$D$66,A11,'Casos de prueba'!$X$5:$X$66,"FAIL") -> 0 | K11: =F11-I11-J11 -> 2 | L11: =IF(F11=0,"Sin casos",IF(H11>0,"Con fallas",IF(G11=F11,"Cubierto","Parcial"))) -> Cubierto | M11: =IF(F11=0,"Sin casos",IF(J11>0,"No cumple",IF(I11=F11,"Cumple","Pendiente"))) -> Pendiente
A12: HU-008 | B12: Consulta de mis documentos y su estado | C12: RF-018 a RF-020 | D12: RNF-09 | E12: CP-22, CP-23 | F12: =COUNTIF('Casos de prueba'!$D$5:$D$66,A12) -> 2 | G12: =COUNTIFS('Casos de prueba'!$D$5:$D$66,A12,'Casos de prueba'!$R$5:$R$66,"PASS") -> 2 | H12: =COUNTIFS('Casos de prueba'!$D$5:$D$66,A12,'Casos de prueba'!$R$5:$R$66,"FAIL") -> 0 | I12: =COUNTIFS('Casos de prueba'!$D$5:$D$66,A12,'Casos de prueba'!$X$5:$X$66,"PASS") -> 0 | J12: =COUNTIFS('Casos de prueba'!$D$5:$D$66,A12,'Casos de prueba'!$X$5:$X$66,"FAIL") -> 0 | K12: =F12-I12-J12 -> 2 | L12: =IF(F12=0,"Sin casos",IF(H12>0,"Con fallas",IF(G12=F12,"Cubierto","Parcial"))) -> Cubierto | M12: =IF(F12=0,"Sin casos",IF(J12>0,"No cumple",IF(I12=F12,"Cumple","Pendiente"))) -> Pendiente
A13: HU-009 | B13: Consulta de trazabilidad de mis documentos | C13: RF-021, RF-022 | D13: RNF-06, RNF-26, RNF-27 | E13: CP-24, CP-25 | F13: =COUNTIF('Casos de prueba'!$D$5:$D$66,A13) -> 2 | G13: =COUNTIFS('Casos de prueba'!$D$5:$D$66,A13,'Casos de prueba'!$R$5:$R$66,"PASS") -> 2 | H13: =COUNTIFS('Casos de prueba'!$D$5:$D$66,A13,'Casos de prueba'!$R$5:$R$66,"FAIL") -> 0 | I13: =COUNTIFS('Casos de prueba'!$D$5:$D$66,A13,'Casos de prueba'!$X$5:$X$66,"PASS") -> 0 | J13: =COUNTIFS('Casos de prueba'!$D$5:$D$66,A13,'Casos de prueba'!$X$5:$X$66,"FAIL") -> 0 | K13: =F13-I13-J13 -> 2 | L13: =IF(F13=0,"Sin casos",IF(H13>0,"Con fallas",IF(G13=F13,"Cubierto","Parcial"))) -> Cubierto | M13: =IF(F13=0,"Sin casos",IF(J13>0,"No cumple",IF(I13=F13,"Cumple","Pendiente"))) -> Pendiente
A14: HU-010 | B14: Selección del documento a verificar | C14: RF-023 a RF-025 | E14: CP-26, CP-27 | F14: =COUNTIF('Casos de prueba'!$D$5:$D$66,A14) -> 2 | G14: =COUNTIFS('Casos de prueba'!$D$5:$D$66,A14,'Casos de prueba'!$R$5:$R$66,"PASS") -> 2 | H14: =COUNTIFS('Casos de prueba'!$D$5:$D$66,A14,'Casos de prueba'!$R$5:$R$66,"FAIL") -> 0 | I14: =COUNTIFS('Casos de prueba'!$D$5:$D$66,A14,'Casos de prueba'!$X$5:$X$66,"PASS") -> 0 | J14: =COUNTIFS('Casos de prueba'!$D$5:$D$66,A14,'Casos de prueba'!$X$5:$X$66,"FAIL") -> 0 | K14: =F14-I14-J14 -> 2 | L14: =IF(F14=0,"Sin casos",IF(H14>0,"Con fallas",IF(G14=F14,"Cubierto","Parcial"))) -> Cubierto | M14: =IF(F14=0,"Sin casos",IF(J14>0,"No cumple",IF(I14=F14,"Cumple","Pendiente"))) -> Pendiente
A15: HU-011 | B15: Consulta de la huella registrada con control de visibilidad | C15: RF-026, RF-027 | D15: RNF-08 | E15: CP-28, CP-29 | F15: =COUNTIF('Casos de prueba'!$D$5:$D$66,A15) -> 2 | G15: =COUNTIFS('Casos de prueba'!$D$5:$D$66,A15,'Casos de prueba'!$R$5:$R$66,"PASS") -> 2 | H15: =COUNTIFS('Casos de prueba'!$D$5:$D$66,A15,'Casos de prueba'!$R$5:$R$66,"FAIL") -> 0 | I15: =COUNTIFS('Casos de prueba'!$D$5:$D$66,A15,'Casos de prueba'!$X$5:$X$66,"PASS") -> 0 | J15: =COUNTIFS('Casos de prueba'!$D$5:$D$66,A15,'Casos de prueba'!$X$5:$X$66,"FAIL") -> 0 | K15: =F15-I15-J15 -> 2 | L15: =IF(F15=0,"Sin casos",IF(H15>0,"Con fallas",IF(G15=F15,"Cubierto","Parcial"))) -> Cubierto | M15: =IF(F15=0,"Sin casos",IF(J15>0,"No cumple",IF(I15=F15,"Cumple","Pendiente"))) -> Pendiente
A16: HU-012 | B16: Carga del documento a comparar | C16: RF-028, RF-029 | D16: RNF-23, RNF-24 | E16: CP-30, CP-31 | F16: =COUNTIF('Casos de prueba'!$D$5:$D$66,A16) -> 2 | G16: =COUNTIFS('Casos de prueba'!$D$5:$D$66,A16,'Casos de prueba'!$R$5:$R$66,"PASS") -> 1 | H16: =COUNTIFS('Casos de prueba'!$D$5:$D$66,A16,'Casos de prueba'!$R$5:$R$66,"FAIL") -> 0 | I16: =COUNTIFS('Casos de prueba'!$D$5:$D$66,A16,'Casos de prueba'!$X$5:$X$66,"PASS") -> 0 | J16: =COUNTIFS('Casos de prueba'!$D$5:$D$66,A16,'Casos de prueba'!$X$5:$X$66,"FAIL") -> 0 | K16: =F16-I16-J16 -> 2 | L16: =IF(F16=0,"Sin casos",IF(H16>0,"Con fallas",IF(G16=F16,"Cubierto","Parcial"))) -> Parcial | M16: =IF(F16=0,"Sin casos",IF(J16>0,"No cumple",IF(I16=F16,"Cumple","Pendiente"))) -> Pendiente
A17: HU-013 | B17: Comparación de huellas y resultado de la verificación | C17: RF-030 a RF-033 | D17: RNF-10, RNF-14 | E17: CP-32, CP-33 | F17: =COUNTIF('Casos de prueba'!$D$5:$D$66,A17) -> 2 | G17: =COUNTIFS('Casos de prueba'!$D$5:$D$66,A17,'Casos de prueba'!$R$5:$R$66,"PASS") -> 2 | H17: =COUNTIFS('Casos de prueba'!$D$5:$D$66,A17,'Casos de prueba'!$R$5:$R$66,"FAIL") -> 0 | I17: =COUNTIFS('Casos de prueba'!$D$5:$D$66,A17,'Casos de prueba'!$X$5:$X$66,"PASS") -> 0 | J17: =COUNTIFS('Casos de prueba'!$D$5:$D$66,A17,'Casos de prueba'!$X$5:$X$66,"FAIL") -> 0 | K17: =F17-I17-J17 -> 2 | L17: =IF(F17=0,"Sin casos",IF(H17>0,"Con fallas",IF(G17=F17,"Cubierto","Parcial"))) -> Cubierto | M17: =IF(F17=0,"Sin casos",IF(J17>0,"No cumple",IF(I17=F17,"Cumple","Pendiente"))) -> Pendiente
A18: HU-014 | B18: Actualización de estado y registro de la verificación | C18: RF-034 a RF-036 | D18: RNF-05, RNF-27 | E18: CP-34, CP-35 | F18: =COUNTIF('Casos de prueba'!$D$5:$D$66,A18) -> 2 | G18: =COUNTIFS('Casos de prueba'!$D$5:$D$66,A18,'Casos de prueba'!$R$5:$R$66,"PASS") -> 2 | H18: =COUNTIFS('Casos de prueba'!$D$5:$D$66,A18,'Casos de prueba'!$R$5:$R$66,"FAIL") -> 0 | I18: =COUNTIFS('Casos de prueba'!$D$5:$D$66,A18,'Casos de prueba'!$X$5:$X$66,"PASS") -> 0 | J18: =COUNTIFS('Casos de prueba'!$D$5:$D$66,A18,'Casos de prueba'!$X$5:$X$66,"FAIL") -> 0 | K18: =F18-I18-J18 -> 2 | L18: =IF(F18=0,"Sin casos",IF(H18>0,"Con fallas",IF(G18=F18,"Cubierto","Parcial"))) -> Cubierto | M18: =IF(F18=0,"Sin casos",IF(J18>0,"No cumple",IF(I18=F18,"Cumple","Pendiente"))) -> Pendiente
A19: HU-015 | B19: Consulta general de documentos registrados | C19: RF-037, RF-038 | D19: RNF-08 | E19: CP-36, CP-37 | F19: =COUNTIF('Casos de prueba'!$D$5:$D$66,A19) -> 2 | G19: =COUNTIFS('Casos de prueba'!$D$5:$D$66,A19,'Casos de prueba'!$R$5:$R$66,"PASS") -> 2 | H19: =COUNTIFS('Casos de prueba'!$D$5:$D$66,A19,'Casos de prueba'!$R$5:$R$66,"FAIL") -> 0 | I19: =COUNTIFS('Casos de prueba'!$D$5:$D$66,A19,'Casos de prueba'!$X$5:$X$66,"PASS") -> 0 | J19: =COUNTIFS('Casos de prueba'!$D$5:$D$66,A19,'Casos de prueba'!$X$5:$X$66,"FAIL") -> 0 | K19: =F19-I19-J19 -> 2 | L19: =IF(F19=0,"Sin casos",IF(H19>0,"Con fallas",IF(G19=F19,"Cubierto","Parcial"))) -> Cubierto | M19: =IF(F19=0,"Sin casos",IF(J19>0,"No cumple",IF(I19=F19,"Cumple","Pendiente"))) -> Pendiente
A20: HU-016 | B20: Consulta general de trazabilidad | C20: RF-039, RF-040 | D20: RNF-26, RNF-27 | E20: CP-38, CP-39 | F20: =COUNTIF('Casos de prueba'!$D$5:$D$66,A20) -> 2 | G20: =COUNTIFS('Casos de prueba'!$D$5:$D$66,A20,'Casos de prueba'!$R$5:$R$66,"PASS") -> 2 | H20: =COUNTIFS('Casos de prueba'!$D$5:$D$66,A20,'Casos de prueba'!$R$5:$R$66,"FAIL") -> 0 | I20: =COUNTIFS('Casos de prueba'!$D$5:$D$66,A20,'Casos de prueba'!$X$5:$X$66,"PASS") -> 0 | J20: =COUNTIFS('Casos de prueba'!$D$5:$D$66,A20,'Casos de prueba'!$X$5:$X$66,"FAIL") -> 0 | K20: =F20-I20-J20 -> 2 | L20: =IF(F20=0,"Sin casos",IF(H20>0,"Con fallas",IF(G20=F20,"Cubierto","Parcial"))) -> Cubierto | M20: =IF(F20=0,"Sin casos",IF(J20>0,"No cumple",IF(I20=F20,"Cumple","Pendiente"))) -> Pendiente
A21: HU-017 | B21: Panel general con resumen documental | C21: RF-041, RF-042 | E21: CP-40, CP-41 | F21: =COUNTIF('Casos de prueba'!$D$5:$D$66,A21) -> 2 | G21: =COUNTIFS('Casos de prueba'!$D$5:$D$66,A21,'Casos de prueba'!$R$5:$R$66,"PASS") -> 2 | H21: =COUNTIFS('Casos de prueba'!$D$5:$D$66,A21,'Casos de prueba'!$R$5:$R$66,"FAIL") -> 0 | I21: =COUNTIFS('Casos de prueba'!$D$5:$D$66,A21,'Casos de prueba'!$X$5:$X$66,"PASS") -> 0 | J21: =COUNTIFS('Casos de prueba'!$D$5:$D$66,A21,'Casos de prueba'!$X$5:$X$66,"FAIL") -> 0 | K21: =F21-I21-J21 -> 2 | L21: =IF(F21=0,"Sin casos",IF(H21>0,"Con fallas",IF(G21=F21,"Cubierto","Parcial"))) -> Cubierto | M21: =IF(F21=0,"Sin casos",IF(J21>0,"No cumple",IF(I21=F21,"Cumple","Pendiente"))) -> Pendiente
A22: HU-018 | B22: Gestión del ciclo de vida de usuarios | C22: RF-043 a RF-047 | D22: RNF-03 | E22: CP-42, CP-43 | F22: =COUNTIF('Casos de prueba'!$D$5:$D$66,A22) -> 2 | G22: =COUNTIFS('Casos de prueba'!$D$5:$D$66,A22,'Casos de prueba'!$R$5:$R$66,"PASS") -> 1 | H22: =COUNTIFS('Casos de prueba'!$D$5:$D$66,A22,'Casos de prueba'!$R$5:$R$66,"FAIL") -> 0 | I22: =COUNTIFS('Casos de prueba'!$D$5:$D$66,A22,'Casos de prueba'!$X$5:$X$66,"PASS") -> 0 | J22: =COUNTIFS('Casos de prueba'!$D$5:$D$66,A22,'Casos de prueba'!$X$5:$X$66,"FAIL") -> 0 | K22: =F22-I22-J22 -> 2 | L22: =IF(F22=0,"Sin casos",IF(H22>0,"Con fallas",IF(G22=F22,"Cubierto","Parcial"))) -> Parcial | M22: =IF(F22=0,"Sin casos",IF(J22>0,"No cumple",IF(I22=F22,"Cumple","Pendiente"))) -> Pendiente
A23: HU-019 | B23: Consulta administrativa de documentos | C23: RF-048, RF-049 | D23: RNF-04, RNF-08 | E23: CP-44, CP-45 | F23: =COUNTIF('Casos de prueba'!$D$5:$D$66,A23) -> 2 | G23: =COUNTIFS('Casos de prueba'!$D$5:$D$66,A23,'Casos de prueba'!$R$5:$R$66,"PASS") -> 2 | H23: =COUNTIFS('Casos de prueba'!$D$5:$D$66,A23,'Casos de prueba'!$R$5:$R$66,"FAIL") -> 0 | I23: =COUNTIFS('Casos de prueba'!$D$5:$D$66,A23,'Casos de prueba'!$X$5:$X$66,"PASS") -> 0 | J23: =COUNTIFS('Casos de prueba'!$D$5:$D$66,A23,'Casos de prueba'!$X$5:$X$66,"FAIL") -> 0 | K23: =F23-I23-J23 -> 2 | L23: =IF(F23=0,"Sin casos",IF(H23>0,"Con fallas",IF(G23=F23,"Cubierto","Parcial"))) -> Cubierto | M23: =IF(F23=0,"Sin casos",IF(J23>0,"No cumple",IF(I23=F23,"Cumple","Pendiente"))) -> Pendiente
A24: HU-020 | B24: Consulta administrativa de trazabilidad | C24: RF-050, RF-051 | D24: RNF-26, RNF-27 | E24: CP-46, CP-47 | F24: =COUNTIF('Casos de prueba'!$D$5:$D$66,A24) -> 2 | G24: =COUNTIFS('Casos de prueba'!$D$5:$D$66,A24,'Casos de prueba'!$R$5:$R$66,"PASS") -> 2 | H24: =COUNTIFS('Casos de prueba'!$D$5:$D$66,A24,'Casos de prueba'!$R$5:$R$66,"FAIL") -> 0 | I24: =COUNTIFS('Casos de prueba'!$D$5:$D$66,A24,'Casos de prueba'!$X$5:$X$66,"PASS") -> 0 | J24: =COUNTIFS('Casos de prueba'!$D$5:$D$66,A24,'Casos de prueba'!$X$5:$X$66,"FAIL") -> 0 | K24: =F24-I24-J24 -> 2 | L24: =IF(F24=0,"Sin casos",IF(H24>0,"Con fallas",IF(G24=F24,"Cubierto","Parcial"))) -> Cubierto | M24: =IF(F24=0,"Sin casos",IF(J24>0,"No cumple",IF(I24=F24,"Cumple","Pendiente"))) -> Pendiente
A25: HU-021 | B25: Despliegue de la red blockchain y del entorno con Docker | D25: RNF-19 a RNF-22 | E25: CP-50, CP-51 | F25: =COUNTIF('Casos de prueba'!$D$5:$D$66,A25) -> 2 | G25: =COUNTIFS('Casos de prueba'!$D$5:$D$66,A25,'Casos de prueba'!$R$5:$R$66,"PASS") -> 2 | H25: =COUNTIFS('Casos de prueba'!$D$5:$D$66,A25,'Casos de prueba'!$R$5:$R$66,"FAIL") -> 0 | I25: =COUNTIFS('Casos de prueba'!$D$5:$D$66,A25,'Casos de prueba'!$X$5:$X$66,"PASS") -> 0 | J25: =COUNTIFS('Casos de prueba'!$D$5:$D$66,A25,'Casos de prueba'!$X$5:$X$66,"FAIL") -> 0 | K25: =F25-I25-J25 -> 2 | L25: =IF(F25=0,"Sin casos",IF(H25>0,"Con fallas",IF(G25=F25,"Cubierto","Parcial"))) -> Cubierto | M25: =IF(F25=0,"Sin casos",IF(J25>0,"No cumple",IF(I25=F25,"Cumple","Pendiente"))) -> Pendiente
A26: HU-022 | B26: Protección ante intentos fallidos de acceso | C26: RF-054 | D26: RNF-06, RNF-07 | E26: CP-09, CP-10, CP-11, CP-12 | F26: =COUNTIF('Casos de prueba'!$D$5:$D$66,A26) -> 4 | G26: =COUNTIFS('Casos de prueba'!$D$5:$D$66,A26,'Casos de prueba'!$R$5:$R$66,"PASS") -> 4 | H26: =COUNTIFS('Casos de prueba'!$D$5:$D$66,A26,'Casos de prueba'!$R$5:$R$66,"FAIL") -> 0 | I26: =COUNTIFS('Casos de prueba'!$D$5:$D$66,A26,'Casos de prueba'!$X$5:$X$66,"PASS") -> 0 | J26: =COUNTIFS('Casos de prueba'!$D$5:$D$66,A26,'Casos de prueba'!$X$5:$X$66,"FAIL") -> 0 | K26: =F26-I26-J26 -> 4 | L26: =IF(F26=0,"Sin casos",IF(H26>0,"Con fallas",IF(G26=F26,"Cubierto","Parcial"))) -> Cubierto | M26: =IF(F26=0,"Sin casos",IF(J26>0,"No cumple",IF(I26=F26,"Cumple","Pendiente"))) -> Pendiente
