Workbook
Name LST_CONFIRMACION: Listas!$H$7:$H$8
Name LST_ESTADO_HU: Listas!$L$7:$L$10
Name LST_ESTADO_REQ: Listas!$F$7:$F$11
Name LST_ID_HU: Historias_Usuario!$A$7:$A$107
Name LST_ID_RF: RF!$A$7:$A$107
Name LST_ID_RNF: RNF!$A$7:$A$107
Name LST_IMPORTANCIA: Listas!$E$7:$E$9
Name LST_MOSCOW: Listas!$D$7:$D$10
Name LST_PUNTOS: Listas!$I$7:$I$13
Name LST_RESULTADO: Listas!$K$7:$K$9
Name LST_SUBCARACTERISTICA: Listas!$A$7:$A$46
Name LST_TIPO_ESCENARIO: Listas!$J$7:$J$9
Name LST_VERIFICACION: Listas!$G$7:$G$10

Sheet Portada
B10: Plantilla de requisitos y de historias de usuario
B11: Especificación conforme a ISO/IEC/IEEE 29148:2018 · Atributos de calidad según ISO/IEC 25010:2023
B13: IDENTIFICACIÓN DEL PROYECTO
B14: Proyecto o sistema | C14: MVP de un sistema web para la verificación de integridad y trazabilidad documental en contratos laborales mediante blockchain permisionada
B15: Organización o cliente | C15: Empresa de servicios tecnológicos en Bogotá (caso de aplicación) / Universidad Católica de Colombia
B16: Equipo de trabajo | C16: Laura Sofia Diaz Suarez; Sofia Ortiz Daza
B17: Responsable de la especificación | C17: Laura Sofia Diaz Suarez; Sofia Ortiz Daza
B18: Versión del documento | C18: 2.0
B19: Fecha de la versión | C19: 46265
B21: CONTENIDO REGISTRADO EN EL LIBRO
B22: Requisitos funcionales | C22: =COUNTIF(RF!$A$7:$A$107,"?*") -> 53
B23: Requisitos no funcionales | C23: =COUNTIF(RNF!$A$7:$A$107,"?*") -> 30
B24: Historias de usuario | C24: =COUNTIF(Historias_Usuario!$A$7:$A$107,"?*") -> 21
B25: Escenarios de aceptación en Gherkin | C25: =COUNTIF(Criterios_Gherkin!$B$7:$B$206,"?*") -> 42
B27: Universidad Católica de Colombia · Facultad de Ingeniería · Ingeniería de Sistemas y Computación · Solangie Garavito

Sheet Instrucciones
A1: Instrucciones de uso
A2: Léelas antes de diligenciar. Las convenciones aplican a todas las hojas de captura.
B5: HOJAS DEL LIBRO
B6: Hoja | C6: Qué se registra allí | D6: Quién la usa
B7: Portada | C7: Datos del proyecto y conteo automático de lo ya capturado. | D7: Equipo, al iniciar y al cerrar cada entrega
B8: Instrucciones | C8: Convenciones de color, numeración de identificadores y criterios de calidad exigidos. | D8: Todo el equipo, antes de capturar
B9: RF | C9: Una fila por capacidad que el sistema debe ofrecer: flujo, reglas y criterios verificables. | D9: Analista de requisitos
B10: RNF | C10: Una fila por restricción de calidad, con la medida, el umbral y el método que la comprueba. | D10: Analista de requisitos y arquitecto
B11: Ficha_RF | C11: Vista de un requisito funcional en formato de una página, para imprimir o anexar. | D11: Quien prepara el informe
B12: Ficha_RNF | C12: Vista de un requisito no funcional en formato de una página, para imprimir o anexar. | D12: Quien prepara el informe
B13: Historias_Usuario | C13: Narrativa, trazabilidad hacia requisitos, estimación y verificación de INVEST y de terminado. | D13: Responsable del producto y equipo
B14: Criterios_Gherkin | C14: Un escenario por fila, asociado a la historia mediante su identificador. | D14: Equipo de desarrollo y pruebas
B15: Definición_Terminado | C15: Acuerdo sobre cuándo una historia se da por concluida y con qué evidencia se sustenta. | D15: Equipo completo, una sola vez
B16: Listas | C16: Catálogos que alimentan las listas desplegables; se amplían aquí, nunca dentro de la captura. | D16: Quien administra el libro
B18: CONVENCIONES DE COLOR
B19: Formato de la celda | C19: Qué significa | D19: Acción esperada
B20: Fondo blanco con borde | C20: Campo de captura libre. | D20: Escribe el contenido.
B21: Fondo gris | C21: Campo derivado de otra celda del libro. | D21: No escribas: se recalcula solo.
B22: Fondo ámbar | C22: Campo que gobierna lo que muestra el resto de la hoja. | D22: Elige un valor de la lista.
B24: NUMERACIÓN DE IDENTIFICADORES
B25: Elemento | C25: Patrón | D25: Regla
B26: Requisito funcional | C26: RF-001, RF-002, ... | D26: Consecutivo en la hoja RF; un identificador retirado no se reutiliza.
B27: Requisito no funcional | C27: RNF-001, RNF-002, ... | D27: Consecutivo en la hoja RNF; un identificador retirado no se reutiliza.
B28: Historia de usuario | C28: HU-001, HU-002, ... | D28: Consecutivo en el backlog, independiente del sprint en que se ejecute.
B29: Épica | C29: EP-01, EP-02, ... | D29: Agrupa historias que comparten un mismo objetivo de negocio.
B30: Escenario de aceptación | C30: CA-01, CA-02, ... | D30: Reinicia en cada historia; la pareja historia y escenario es única.
B31: Regla de negocio | C31: RN-01, RN-02, ... | D31: Se enuncia dentro del requisito funcional que la impone.
B33: CRITERIOS DE CALIDAD EXIGIDOS A CADA REQUISITO
B34: Característica | C34: Cómo se comprueba en la revisión | D34: Señal de incumplimiento
B35: Necesario | C35: Al retirarlo queda sin cubrir una necesidad declarada por una parte interesada. | D35: Nadie reclama su ausencia.
B36: Apropiado | C36: Corresponde al alcance del sistema especificado y no al de un componente interno. | D36: Impone una tecnología o un detalle de implementación.
B37: No ambiguo | C37: Dos lectores distintos extraen la misma conclusión sobre lo exigido. | D37: Aparecen adjetivos sin medida como rápido, amigable o robusto.
B38: Completo | C38: Se entiende sin consultar otro documento ni recordar una conversación previa. | D38: Requiere preguntar al autor para saber qué hace el sistema.
B39: Singular | C39: Enuncia una sola capacidad o restricción. | D39: Une varias exigencias con la conjunción y.
B40: Factible | C40: Es realizable con el costo, el plazo y la técnica disponibles, con riesgo aceptable. | D40: Nadie puede estimar su esfuerzo.
B41: Verificable | C41: Existe una prueba, un análisis, una inspección o una demostración que decide si se cumple. | D41: No se sabe qué evidencia lo daría por satisfecho.
B42: Correcto | C42: Refleja fielmente la necesidad de la que proviene. | D42: La parte interesada no se reconoce en el enunciado.
B43: Conforme | C43: Respeta la plantilla y el vocabulario acordados para el proyecto. | D43: Mezcla formatos o inventa términos propios.
B45: REFERENCIAS
B46: ISO/IEC/IEEE 29148:2018. Systems and software engineering. Life cycle processes. Requirements engineering.
...

Sheet RF
A1: Requisitos funcionales
A2: Una fila por requisito. Estructura tomada de la plantilla SRS conforme a ISO/IEC/IEEE 29148:2018.
A3: La fila 7 es un ejemplo: sobrescríbela o bórrala antes de entregar. Las columnas con lista desplegable solo aceptan valores del catálogo.
A5: IDENTIFICACIÓN | F5: 1. CONTEXTO Y JUSTIFICACIÓN | I5: 2. CLASIFICACIÓN | L5: 3. ESPECIFICACIÓN DETALLADA | Q5: 4. RELACIONES
A6: ID del requisito | B6: Título | C6: Versión | D6: Fecha de versión | E6: Autor | F6: Descripción general | G6: Fuente o parte interesada | H6: Justificación | I6: Prioridad (MoSCoW) | J6: Importancia | K6: Estado | L6: Precondiciones | M6: Disparador | N6: Flujo principal | O6: Reglas de negocio y validaciones | P6: Criterios de aceptación verificables | Q6: Dependencias | R6: Requisitos hijos | S6: Comentarios
A7: RF-001 | B7: Inicio de sesión | C7: 2.0 | D7: 46265 | E7: Laura Sofia Diaz Suarez; Sofia Ortiz Daza | F7: Permite al usuario iniciar sesión ingresando únicamente su correo electrónico corporativo y su contraseña, sin seleccionar previamente un rol. | G7: Área de TI - Seguridad de la información | H7: El rol deja de ser un dato ingresado por el usuario y pasa a ser un atributo de su cuenta, lo que habilita el control de acceso por rol (RBAC) exigido en RNF-03. | I7: Debe (Must) | J7: Alta | K7: Aprobado | L7: El usuario no tiene sesión activa. | M7: El usuario ingresa a la URL del sistema. | N7: 1. El sistema muestra el formulario de inicio de sesión con los campos correo electrónico y contraseña. 2. El usuario ingresa sus datos. 3. El sistema continúa con la validación de credenciales de RF-002. | O7: RN-01: El sistema no solicita ni acepta la selección de rol por parte del usuario. RN-02: Los roles válidos del sistema son Administrador, Empleado y Verificador. | P7: CA-01: Dado que el usuario está en la pantalla de inicio, cuando la visualiza, entonces el sistema muestra únicamente los campos de correo electrónico y contraseña, sin selector de rol. | Q7: Ninguna | R7: RF-002 | S7: Nota de cambio: se elimina la selección manual de rol; el rol se determina a partir de la cuenta del usuario.
A8: RF-002 | B8: Autenticación mediante credenciales | C8: 2.0 | D8: 46265 | E8: Laura Sofia Diaz Suarez; Sofia Ortiz Daza | F8: Solicita correo electrónico y contraseña corporativos como primer factor de autenticación. | G8: Área de TI - Seguridad de la información | H8: Es la base del control de acceso y se complementa con el segundo factor de RF-003, conforme a RNF-02. | I8: Debe (Must) | J8: Alta | K8: Aprobado | L8: El usuario visualiza el formulario de inicio de sesión (RF-001). | M8: El usuario visualiza el formulario de credenciales. | N8: 1. El sistema solicita correo electrónico y contraseña. 2. El usuario los ingresa y envía el formulario. 3. El sistema valida las credenciales contra el registro de usuarios y continúa con RF-003. | O8: RN-01: Las contraseñas se validan contra el hash almacenado (RNF-01), nunca en texto plano. | P8: CA-01: Dado credenciales válidas, cuando se envía el formulario, entonces el sistema solicita el token de segundo factor. CA-02: Dado credenciales inválidas, cuando se envía el formulario, entonces el sistema muestra un mensaje de error sin indicar cuál dato es incorrecto. | Q8: RF-001 | R8: RF-003
A9: RF-003 | B9: Autenticación de segundo factor | C9: 2.0 | D9: 46265 | E9: Laura Sofia Diaz Suarez; Sofia Ortiz Daza | F9: Envía un token de verificación al correo corporativo registrado del usuario como segundo factor. | G9: Área de TI - Seguridad de la información | H9: Refuerza la autenticación exigida por RNF-02 y reduce el riesgo de suplantación en el acceso a evidencia documental sensible. | I9: Debe (Must) | J9: Alta | K9: Aprobado | L9: Las credenciales ingresadas en RF-002 fueron validadas. | M9: El sistema valida correctamente correo electrónico y contraseña. | N9: 1. El sistema genera un token de un solo uso. 2. El sistema lo envía al correo corporativo registrado. 3. El sistema muestra el campo para ingresar el token. | O9: RN-01: El token tiene un tiempo de expiración definido y solo puede usarse una vez. | P9: CA-01: Dado que las credenciales son válidas, cuando el sistema las procesa, entonces envía el token al correo registrado del usuario en menos de un minuto. | Q9: RF-002 | R9: RF-004 | S9: Pendiente de validar el canal exclusivo de correo corporativo frente a alternativas (SMS, app autenticadora); ver nota en RNF-02.
A10: RF-004 | B10: Validación del token | C10: 2.0 | D10: 46265 | E10: Laura Sofia Diaz Suarez; Sofia Ortiz Daza | F10: Valida el token de segundo factor ingresado por el usuario antes de conceder acceso. | G10: Área de TI - Seguridad de la información | H10: Es el paso que cierra el ciclo de autenticación de doble factor exigido en RNF-02. | I10: Debe (Must) | J10: Alta | K10: Aprobado | L10: El token fue enviado (RF-003). | M10: El usuario ingresa el token recibido. | N10: 1. El usuario ingresa el token. 2. El sistema compara el token ingresado contra el generado. 3. Si coincide y no ha expirado, el sistema continúa con RF-005. | O10: RN-01: Un token expirado o incorrecto no concede acceso. RN-02: Se define un número máximo de intentos antes de bloquear temporalmente el proceso. | P10: CA-01: Dado un token correcto y vigente, cuando se valida, entonces el sistema concede acceso. CA-02: Dado un token incorrecto o expirado, cuando se valida, entonces el sistema deniega el acceso y lo informa al usuario. | Q10: RF-003 | R10: RF-005
A11: RF-005 | B11: Asignación de rol y control de acceso | C11: 2.0 | D11: 46265 | E11: Laura Sofia Diaz Suarez; Sofia Ortiz Daza | F11: Permite el acceso únicamente cuando credenciales y token son válidos, e identifica automáticamente el rol del usuario (Administrador, Empleado o Verificador) a partir de su cuenta. Cada usuario tiene un único rol asignado. | G11: Área de TI - Seguridad de la información | H11: Materializa el esquema RBAC exigido por RNF-03 al determinar el rol desde la cuenta del usuario y no desde un dato enviado por el cliente. | I11: Debe (Must) | J11: Alta | K11: Aprobado | L11: El token fue validado (RF-004). | M11: El sistema concluye la validación del token. | N11: 1. El sistema consulta el rol asignado al usuario en la base de datos. 2. Si el usuario está activo y tiene un rol válido, el sistema concede acceso con ese rol. 3. Si el usuario está inactivo o no tiene un rol válido, el sistema deniega el acceso. | O11: RN-01: Cada usuario tiene un único rol, asignado por el Administrador. RN-02: Un usuario sin rol válido o inactivo no puede acceder, aunque sus credenciales sean válidas. | P11: CA-01: Dado un usuario con credenciales y token válidos y rol Verificador, cuando el sistema valida el acceso, entonces lo concede con rol Verificador. CA-02: Dado un usuario inactivo o sin rol válido, cuando el sistema valida el acceso, entonces lo deniega y muestra un mensaje de error. | Q11: RF-004 | R11: RF-006
A12: RF-006 | B12: Redirección según rol | C12: 2.0 | D12: 46265 | E12: Laura Sofia Diaz Suarez; Sofia Ortiz Daza | F12: Muestra al usuario el panel principal y las funcionalidades correspondientes a su rol tras autenticarse. | G12: Área de TI / Usuarios finales de cada rol | H12: Garantiza que cada usuario solo visualice las funcionalidades autorizadas para su rol, en línea con RNF-08. | I12: Debería (Should) | J12: Media | K12: Aprobado | L12: El acceso fue concedido (RF-005). | M12: El sistema concede el acceso. | N12: 1. El sistema identifica el rol asignado a la cuenta del usuario autenticado. 2. El sistema redirige al panel correspondiente (Empleado, Verificador o Administrador). | O12: RN-01: El contenido del panel se limita a las funcionalidades habilitadas para el rol. | P12: CA-01: Dado un usuario con rol Empleado, cuando inicia sesión, entonces ve el panel de carga y consulta de documentos, sin las opciones administrativas. | Q12: RF-005 | R12: Ninguno
A13: RF-007 | B13: Cierre de sesión | C13: 2.0 | D13: 46265 | E13: Laura Sofia Diaz Suarez; Sofia Ortiz Daza | F13: Permite a cualquier usuario autenticado cerrar su sesión de forma segura. | G13: Área de TI - Seguridad de la información | H13: Complementa la gestión segura de sesiones exigida en RNF-07. | I13: Debe (Must) | J13: Alta | K13: Aprobado | L13: El usuario tiene una sesión activa. | M13: El usuario selecciona la opción Cerrar sesión. | N13: 1. El usuario selecciona cerrar sesión. 2. El sistema invalida el token de sesión activo. 3. El sistema redirige a la pantalla de inicio de sesión (RF-001). | O13: RN-01: Una sesión cerrada no puede reutilizarse para acceder a funcionalidades protegidas. | P13: CA-01: Dado que el usuario cierra sesión, cuando intenta acceder de nuevo a una funcionalidad protegida sin autenticarse, entonces el sistema lo redirige al inicio de sesión. | Q13: Ninguna | R13: Ninguno
A14: RF-008 | B14: Carga de documentos | C14: 2.0 | D14: 46265 | E14: Laura Sofia Diaz Suarez; Sofia Ortiz Daza | F14: Permite al usuario con rol Empleado cargar documentos contractuales en PDF para su registro y posterior verificación de integridad. | G14: Área de Gestión Humana / Empleado firmante | H14: Es la funcionalidad central del MVP: da inicio al proceso de generación de evidencia de integridad documental descrito en el alcance del proyecto. | I14: Debe (Must) | J14: Alta | K14: Aprobado | L14: El usuario está autenticado con rol Empleado. | M14: El empleado selecciona Cargar documento. | N14: 1. El sistema muestra el formulario de carga. 2. El empleado selecciona el archivo PDF. 3. El sistema ejecuta las validaciones de RF-009 a RF-012 antes de continuar con RF-013. | O14: RN-01: Solo un usuario con rol Empleado puede iniciar la carga. | P14: CA-01: Dado un archivo PDF válido, cuando el empleado lo carga, entonces el sistema inicia el proceso de registro. | Q14: RF-005 | R14: RF-009, RF-010, RF-011, RF-012
A15: RF-009 | B15: Restricción de formato | C15: 2.0 | D15: 46265 | E15: Laura Sofia Diaz Suarez; Sofia Ortiz Daza | F15: El sistema acepta exclusivamente archivos con formato PDF. | G15: Alcance técnico del proyecto (documentos contractuales en PDF) | H15: El alcance del MVP delimita la gestión documental exclusivamente a contratos laborales y acuerdos de confidencialidad en formato PDF. | I15: Debe (Must) | J15: Alta | K15: Aprobado | L15: El empleado seleccionó un archivo para cargar. | M15: El sistema recibe el archivo seleccionado. | N15: 1. El sistema verifica la extensión y el tipo MIME del archivo. 2. Si es PDF, continúa el proceso; si no, rechaza la carga. | O15: RN-01: Formatos distintos a PDF (DOCX, XML, imágenes) son rechazados, conforme a las limitaciones del proyecto. | P15: CA-01: Dado un archivo con extensión .docx, cuando se intenta cargar, entonces el sistema lo rechaza e informa el motivo. | Q15: RF-008 | R15: Ninguno | S15: Alineado con RNF-23 y con la limitación funcional del proyecto (solo PDF).
A16: RF-010 | B16: Restricción de carga individual | C16: 2.0 | D16: 46265 | E16: Laura Sofia Diaz Suarez; Sofia Ortiz Daza | F16: Permite la carga de un único documento por operación; no admite cargas masivas o por lotes. | G16: Alcance técnico del proyecto | H16: El MVP no contempla procesamiento masivo, conforme a las limitaciones definidas (sin pruebas de carga a escala empresarial). | I16: Debe (Must) | J16: Alta | K16: Aprobado | L16: El empleado accede al formulario de carga. | M16: El empleado intenta seleccionar archivos. | N16: 1. El formulario permite seleccionar un solo archivo. 2. Si el usuario intenta seleccionar más de uno, el sistema conserva solo el primero o muestra un aviso. | O16: RN-01: No se permite selección múltiple de archivos en el control de carga. | P16: CA-01: Dado que el empleado intenta seleccionar varios archivos a la vez, cuando confirma la selección, entonces el sistema le solicita elegir un único archivo. | Q16: RF-008 | R16: Ninguno
A17: RF-011 | B17: Restricción de tamaño | C17: 2.0 | D17: 46265 | E17: Laura Sofia Diaz Suarez; Sofia Ortiz Daza | F17: Acepta únicamente archivos PDF con tamaño igual o inferior a 20 MB. | G17: Decisión técnica del equipo de desarrollo (arquitectura y capacidad de procesamiento) | H17: Limita el consumo de recursos de hashing y de almacenamiento de metadatos, preservando el rendimiento definido en RNF-09 y RNF-10. | I17: Debe (Must) | J17: Alta | K17: Aprobado | L17: El archivo fue seleccionado y es formato PDF (RF-009). | M17: El sistema recibe el archivo para su validación. | N17: 1. El sistema mide el tamaño del archivo. 2. Si es ≤20 MB, continúa el proceso; si no, lo rechaza. | O17: RN-01: Archivos mayores a 20 MB no se procesan. | P17: CA-01: Dado un archivo PDF de 25 MB, cuando se intenta cargar, entonces el sistema lo rechaza e informa el límite permitido. | Q17: RF-009 | R17: Ninguno | S17: Corresponde al umbral definido en RNF-24; es una decisión de diseño del proyecto, no proviene de una norma externa.
A18: RF-012 | B18: Validación previa de documentos | C18: 2.0 | D18: 46265 | E18: Laura Sofia Diaz Suarez; Sofia Ortiz Daza | F18: Valida el formato y tamaño del archivo antes de iniciar su registro. | G18: Equipo de desarrollo | H18: Evita procesar documentos que no cumplen las restricciones del sistema antes de invertir recursos en el registro (RF-013 a RF-016). | I18: Debe (Must) | J18: Alta | K18: Aprobado | L18: El archivo fue seleccionado. | M18: El empleado confirma la carga del archivo. | N18: 1. El sistema ejecuta en conjunto las validaciones de formato (RF-009) y tamaño (RF-011). 2. Si ambas se cumplen, continúa con RF-013; si alguna falla, detiene el proceso y notifica el error. | O18: RN-01: El registro (RF-013) no inicia si alguna validación previa falla. | P18: CA-01: Dado un archivo que no cumple formato o tamaño, cuando se valida, entonces el sistema detiene el proceso antes de generar metadatos o huella. | Q18: RF-009, RF-011 | R18: RF-013
A19: RF-013 | B19: Registro del documento | C19: 2.0 | D19: 46265 | E19: Laura Sofia Diaz Suarez; Sofia Ortiz Daza | F19: Registra los metadatos asociados al documento cargado (identificador, nombre, usuario responsable y fecha de registro, como mínimo). | G19: Empleado / Área de Gestión Humana | H19: Provee la información operativa necesaria para la consulta (RF-018, RF-019) y la trazabilidad (RF-021, RF-022) del documento. | I19: Debe (Must) | J19: Alta | K19: Aprobado | L19: El archivo pasó las validaciones previas (RF-012). | M19: El sistema confirma que el archivo es válido. | N19: 1. El sistema genera un identificador único para el documento. 2. El sistema almacena en la base de datos no relacional el nombre, identificador, usuario responsable y fecha de registro. 3. El sistema continúa con RF-014. | O19: RN-01: El contenido del documento no se almacena en la blockchain (ver RNF-04); solo se conservan metadatos y huella criptográfica. | P19: CA-01: Dado un documento válido, cuando se registra, entonces el sistema le asigna un identificador único y guarda sus metadatos. | Q19: RF-012 | R19: RF-014
A20: RF-014 | B20: Generación de huella criptográfica | C20: 2.0 | D20: 46265 | E20: Laura Sofia Diaz Suarez; Sofia Ortiz Daza | F20: Genera automáticamente una huella criptográfica mediante SHA-256 a partir del contenido del documento cargado. | G20: Alcance técnico del proyecto | H20: El uso de SHA-256 está definido en el alcance técnico del proyecto y es el mecanismo central de verificación de integridad documental [34]. | I20: Debe (Must) | J20: Alta | K20: Aprobado | L20: El documento fue registrado (RF-013). | M20: El sistema concluye el registro de metadatos. | N20: 1. El sistema procesa el contenido binario del documento con el algoritmo SHA-256. 2. El sistema obtiene la huella digital de 256 bits. | O20: RN-01: La huella se genera sobre el contenido completo del documento, de forma automática, sin intervención manual (RNF-11). | P20: CA-01: Dado un documento registrado, cuando se genera su huella, entonces dos ejecuciones sobre el mismo contenido producen exactamente el mismo hash. | Q20: RF-013 | R20: RF-015 | S20: SHA-256 pertenece a la familia SHA-2 estandarizada por el NIST [34]; se eligió por ser el algoritmo utilizado internamente por Hyperledger Fabric [19].
A21: RF-015 | B21: Registro de la huella criptográfica | C21: 2.0 | D21: 46265 | E21: Laura Sofia Diaz Suarez; Sofia Ortiz Daza | F21: Registra la huella criptográfica generada como evidencia de integridad del documento. | G21: Alcance técnico del proyecto | H21: Provee la evidencia técnica verificable exigida por la Ley 527 de 1999 para sostener la integridad de un mensaje de datos [10]. | I21: Debe (Must) | J21: Alta | K21: Aprobado | L21: La huella fue generada (RF-014). | M21: El sistema obtiene el hash SHA-256 del documento. | N21: 1. El sistema asocia la huella al identificador del documento. 2. El sistema envía la huella al módulo de registro en blockchain (RF-016). | O21: RN-01: La huella registrada es la única evidencia de integridad reconocida por el sistema para comparaciones posteriores. | P21: CA-01: Dado que la huella fue generada, cuando se registra, entonces queda asociada de forma unívoca al identificador del documento. | Q21: RF-014 | R21: RF-016
A22: RF-016 | B22: Registro en blockchain | C22: 2.0 | D22: 46265 | E22: Laura Sofia Diaz Suarez; Sofia Ortiz Daza | F22: Registra en la red blockchain permisionada (Hyperledger Fabric) la huella criptográfica y los eventos asociados al documento, sin almacenar el archivo PDF directamente en la blockchain. | G22: Alcance técnico del proyecto | H22: Corresponde al modelo de persistencia híbrida definido en el proyecto: la blockchain conserva evidencia inmutable sin exponer el contenido del documento [19], [31]. | I22: Debe (Must) | J22: Alta | K22: Aprobado | L22: La huella fue registrada en el módulo documental (RF-015). | M22: El sistema envía la huella al chaincode. | N22: 1. El backend invoca al chaincode mediante el Fabric SDK. 2. El chaincode registra la huella y el evento registro en el ledger. 3. La red retorna un identificador de transacción (txID). | O22: RN-01: El chaincode nunca recibe ni almacena el archivo PDF, solo la huella y los metadatos del evento. RN-02: Toda transacción generada obtiene un txID único. | P22: CA-01: Dado que la huella fue enviada al chaincode, cuando se registra en el ledger, entonces el sistema recibe un txID válido. | Q22: RF-015 | R22: RF-017 | S22: Corresponde a RNF-04, RNF-05 y RNF-20.
A23: RF-017 | B23: Confirmación de registro | C23: 2.0 | D23: 46265 | E23: Laura Sofia Diaz Suarez; Sofia Ortiz Daza | F23: Informa al empleado cuando el documento fue registrado correctamente y su huella criptográfica fue generada. | G23: Empleado | H23: Brinda retroalimentación clara al usuario sobre el resultado de la operación, conforme a RNF-17. | I23: Debería (Should) | J23: Media | K23: Aprobado | L23: El registro en blockchain fue exitoso (RF-016). | M23: El sistema recibe el txID de confirmación del ledger. | N23: 1. El sistema recibe la confirmación del chaincode. 2. El sistema muestra al empleado un mensaje de éxito con el identificador del documento. | O23: RN-01: Si el registro en blockchain falla, el sistema no debe mostrar un mensaje de éxito. | P23: CA-01: Dado un registro exitoso, cuando concluye, entonces el empleado ve un mensaje de confirmación con el identificador del documento. | Q23: RF-016 | R23: Ninguno
A24: RF-018 | B24: Consulta de documentos | C24: 2.0 | D24: 46265 | E24: Laura Sofia Diaz Suarez; Sofia Ortiz Daza | F24: Permite al empleado consultar los documentos que ha registrado en la plataforma. | G24: Empleado | H24: Da visibilidad al empleado sobre el estado de sus propios documentos, sin necesidad de mecanismos externos de seguimiento. | I24: Debe (Must) | J24: Alta | K24: Aprobado | L24: El empleado está autenticado y tiene al menos un documento registrado. | M24: El empleado selecciona Mis documentos. | N24: 1. El sistema consulta los documentos cuyo usuario responsable es el empleado autenticado. 2. El sistema muestra el listado (RF-019). | O24: RN-01: El empleado solo visualiza documentos que él mismo registró. | P24: CA-01: Dado un empleado con documentos registrados, cuando consulta su listado, entonces solo ve los documentos que él cargó. | Q24: RF-013 | R24: RF-019, RF-020
A25: RF-019 | B25: Información del documento | C25: 2.0 | D25: 46265 | E25: Laura Sofia Diaz Suarez; Sofia Ortiz Daza | F25: Muestra, como mínimo, el nombre del documento, identificador, fecha de registro y estado actual. | G25: Empleado | H25: Provee la información mínima necesaria para identificar y dar seguimiento a cada documento. | I25: Debe (Must) | J25: Alta | K25: Aprobado | L25: El empleado consultó su listado de documentos (RF-018). | M25: El sistema muestra el listado de documentos. | N25: 1. El sistema recupera los metadatos de cada documento. 2. El sistema los presenta en una tabla con nombre, identificador, fecha de registro y estado. | O25: RN-01: Los campos mínimos mostrados son nombre, identificador, fecha de registro y estado. | P25: CA-01: Dado un documento registrado, cuando se lista, entonces se muestran los cuatro campos mínimos definidos. | Q25: RF-018 | R25: Ninguno
A26: RF-020 | B26: Estado del documento | C26: 2.0 | D26: 46265 | E26: Laura Sofia Diaz Suarez; Sofia Ortiz Daza | F26: Muestra para cada documento uno de los siguientes estados: Pendiente, Verificado o Alterado. | G26: Empleado / Verificador | H26: Da trazabilidad visual inmediata sobre el resultado de la verificación de integridad, sin requerir consultar directamente la blockchain. | I26: Debe (Must) | J26: Alta | K26: Aprobado | L26: El documento fue registrado (RF-013). | M26: El sistema muestra la información del documento (RF-019). | N26: 1. El sistema consulta el último resultado de verificación asociado al documento. 2. Si no existe verificación previa, el estado es Pendiente; si la última comparación coincidió, Verificado; si no coincidió, Alterado. | O26: RN-01: El estado solo puede tomar uno de los tres valores definidos. RN-02: El estado se actualiza automáticamente según RF-034. | P26: CA-01: Dado un documento sin verificaciones previas, cuando se consulta, entonces su estado es Pendiente. | Q26: RF-013, RF-034 | R26: Ninguno
A27: RF-021 | B27: Consulta de trazabilidad | C27: 2.0 | D27: 46265 | E27: Laura Sofia Diaz Suarez; Sofia Ortiz Daza | F27: Permite al empleado consultar el historial de acciones asociadas a sus documentos. | G27: Empleado | H27: Da al empleado visibilidad sobre lo ocurrido con sus documentos, reforzando la confianza en el sistema (RNF-06, RNF-26). | I27: Debe (Must) | J27: Alta | K27: Aprobado | L27: El empleado tiene al menos un documento registrado. | M27: El empleado selecciona Ver trazabilidad sobre un documento. | N27: 1. El sistema consulta en el ledger de Hyperledger Fabric los eventos asociados al documento. 2. El sistema presenta el historial (RF-022). | O27: RN-01: El empleado solo puede consultar la trazabilidad de los documentos que él registró. | P27: CA-01: Dado un documento con eventos registrados, cuando el empleado consulta su trazabilidad, entonces ve el historial completo de acciones sobre ese documento. | Q27: RF-018 | R27: RF-022
A28: RF-022 | B28: Información de trazabilidad | C28: 2.0 | D28: 46265 | E28: Laura Sofia Diaz Suarez; Sofia Ortiz Daza | F28: Muestra en la trazabilidad el documento asociado, la acción realizada, el usuario responsable, el identificador de transacción (txID) generado en Hyperledger Fabric, y la fecha y hora del evento. | G28: Empleado | H28: El campo txID se agrega para alinear el requerimiento con RNF-27, que exige conservar el identificador de transacción como evidencia de auditoría. | I28: Debe (Must) | J28: Alta | K28: Propuesto | L28: El empleado consultó la trazabilidad de un documento (RF-021). | M28: El sistema recupera los eventos del ledger. | N28: 1. El sistema recupera cada evento con sus atributos (documento, acción, usuario, txID, fecha y hora). 2. El sistema los presenta en orden cronológico. | O28: RN-01: El orden de los eventos siempre es cronológico y no puede alterarse desde la interfaz. | P28: CA-01: Dado un documento con tres eventos registrados, cuando se consulta su trazabilidad, entonces se listan los tres eventos en orden cronológico con los cinco campos definidos. | Q28: RF-021 | R28: Ninguno | S28: Nota de cambio (v2): se agrega el campo txID respecto a la v1, para dar cobertura a RNF-27.
A29: RF-023 | B29: Acceso al módulo de verificación | C29: 2.0 | D29: 46265 | E29: Laura Sofia Diaz Suarez; Sofia Ortiz Daza | F29: Permite al usuario con rol Verificador acceder al módulo de verificación de integridad documental. | G29: Área Jurídica y de Cumplimiento (rol Verificador) | H29: Habilita la funcionalidad central del rol Verificador, definida en el alcance funcional del proyecto. | I29: Debe (Must) | J29: Alta | K29: Aprobado | L29: El usuario está autenticado con rol Verificador. | M29: El verificador selecciona Verificar documento en su panel. | N29: 1. El sistema valida que el usuario tenga rol Verificador. 2. El sistema muestra el módulo de verificación. | O29: RN-01: Solo el rol Verificador y el rol Administrador pueden acceder a este módulo (ver RF-027). | P29: CA-01: Dado un usuario con rol Verificador autenticado, cuando accede al módulo, entonces el sistema le muestra la opción de seleccionar un documento a verificar. | Q29: RF-005 | R29: RF-024
A30: RF-024 | B30: Selección del documento registrado | C30: 2.0 | D30: 46265 | E30: Laura Sofia Diaz Suarez; Sofia Ortiz Daza | F30: Permite al verificador seleccionar un documento previamente registrado en el sistema para realizar su verificación. | G30: Verificador | H30: Es el primer paso del flujo de verificación de integridad documental. | I30: Debe (Must) | J30: Alta | K30: Aprobado | L30: El verificador accedió al módulo de verificación (RF-023). | M30: El verificador busca o selecciona un documento de la lista. | N30: 1. El sistema muestra los documentos registrados disponibles. 2. El verificador selecciona el documento a validar o ingresa su identificador. | O30: RN-01: Solo pueden seleccionarse documentos previamente registrados en el sistema. | P30: CA-01: Dado un documento registrado, cuando el verificador lo selecciona, entonces el sistema continúa con la validación de existencia (RF-025). | Q30: RF-023 | R30: RF-025
A31: RF-025 | B31: Validación de existencia | C31: 2.0 | D31: 46265 | E31: Laura Sofia Diaz Suarez; Sofia Ortiz Daza | F31: Consulta mediante el identificador del documento si este se encuentra previamente registrado en el sistema. | G31: Verificador | H31: Evita iniciar un proceso de verificación sobre un documento inexistente. | I31: Debe (Must) | J31: Alta | K31: Aprobado | L31: El verificador seleccionó o ingresó un identificador de documento (RF-024). | M31: El sistema recibe el identificador del documento. | N31: 1. El sistema busca el identificador en la base de datos de metadatos. 2. Si existe, continúa con RF-026; si no, muestra un mensaje de error. | O31: RN-01: Un identificador inexistente no puede continuar el flujo de verificación. | P31: CA-01: Dado un identificador que no existe, cuando se consulta, entonces el sistema informa que el documento no está registrado. | Q31: RF-024 | R31: RF-026
A32: RF-026 | B32: Consulta de huella registrada | C32: 2.0 | D32: 46265 | E32: Laura Sofia Diaz Suarez; Sofia Ortiz Daza | F32: Muestra al verificador la huella criptográfica registrada para el documento seleccionado. | G32: Verificador | H32: Es la evidencia base contra la cual se comparará la huella del documento a verificar. | I32: Debe (Must) | J32: Alta | K32: Aprobado | L32: El documento existe en el sistema (RF-025). | M32: El sistema confirma la existencia del documento. | N32: 1. El sistema recupera la huella registrada desde el ledger o desde el registro de metadatos. 2. El sistema la muestra al verificador conforme a RF-027. | O32: RN-01: La huella mostrada corresponde a la registrada en el momento del registro inicial (RF-015), no a una recalculada. | P32: CA-01: Dado un documento existente, cuando se consulta su huella, entonces el sistema muestra el hash SHA-256 registrado. | Q32: RF-025 | R32: RF-027
A33: RF-027 | B33: Restricción de visualización del hash | C33: 2.0 | D33: 46265 | E33: Laura Sofia Diaz Suarez; Sofia Ortiz Daza | F33: La huella criptográfica completa es visible únicamente para los usuarios autorizados, de acuerdo con las reglas de acceso definidas para el rol Verificador y Administrador. | G33: Área de TI - Seguridad de la información | H33: Limita la exposición de información sensible conforme a RNF-08, evitando que roles no autorizados (Empleado) vean la huella completa fuera de su propio documento. | I33: Debe (Must) | J33: Alta | K33: Aprobado | L33: La huella fue recuperada (RF-026). | M33: El sistema muestra el resultado de la consulta de huella. | N33: 1. El sistema valida el rol del usuario autenticado. 2. Si es Verificador o Administrador, muestra la huella completa; en otro caso, la oculta o restringe. | O33: RN-01: Solo los roles Verificador y Administrador visualizan la huella completa de cualquier documento. | P33: CA-01: Dado un usuario con rol Empleado, cuando intenta ver la huella completa de un documento ajeno, entonces el sistema le deniega el acceso. | Q33: RF-026 | R33: Ninguno
A34: RF-028 | B34: Carga del documento a verificar | C34: 2.0 | D34: 46265 | E34: Laura Sofia Diaz Suarez; Sofia Ortiz Daza | F34: Permite al verificador cargar el documento PDF que será comparado con la versión previamente registrada. | G34: Verificador | H34: Es el insumo necesario para generar la huella de comparación (RF-030). | I34: Debe (Must) | J34: Alta | K34: Aprobado | L34: La huella registrada fue consultada (RF-026). | M34: El verificador selecciona Cargar documento a comparar. | N34: 1. El sistema muestra el formulario de carga. 2. El verificador selecciona el archivo PDF. 3. El sistema ejecuta las validaciones de RF-029. | O34: RN-01: Solo se admite un archivo por operación de verificación (equivalente a RF-010). | P34: CA-01: Dado un archivo PDF cargado, cuando se envía, entonces el sistema inicia su validación. | Q34: RF-026 | R34: RF-029
A35: RF-029 | B35: Validación del documento de comparación | C35: 2.0 | D35: 46265 | E35: Laura Sofia Diaz Suarez; Sofia Ortiz Daza | F35: Verifica que el documento utilizado para la comparación cumpla con las restricciones de formato PDF y tamaño máximo de 20 MB. | G35: Verificador | H35: Aplica las mismas restricciones de RF-009 y RF-011 al documento de comparación, garantizando consistencia en el procesamiento. | I35: Debe (Must) | J35: Alta | K35: Aprobado | L35: El verificador cargó un archivo (RF-028). | M35: El sistema recibe el archivo cargado. | N35: 1. El sistema valida formato PDF. 2. El sistema valida tamaño ≤20 MB. 3. Si ambas validaciones pasan, continúa con RF-030. | O35: RN-01: Un archivo que no cumpla formato o tamaño detiene el proceso de verificación. | P35: CA-01: Dado un archivo de 30 MB, cuando se valida, entonces el sistema lo rechaza e informa el límite permitido. | Q35: RF-028 | R35: RF-030
A36: RF-030 | B36: Generación de hash del documento de comparación | C36: 2.0 | D36: 46265 | E36: Laura Sofia Diaz Suarez; Sofia Ortiz Daza | F36: Genera mediante SHA-256 la huella criptográfica del documento cargado para la verificación. | G36: Verificador | H36: Es el dato que se comparará contra la huella registrada (RF-031), aplicando el mismo algoritmo usado en el registro (RF-014). | I36: Debe (Must) | J36: Alta | K36: Aprobado | L36: El documento de comparación fue validado (RF-029). | M36: El sistema confirma que el archivo es válido. | N36: 1. El sistema procesa el contenido del archivo con SHA-256. 2. El sistema obtiene la huella del documento cargado. | O36: RN-01: La huella se calcula con el mismo algoritmo y parámetros utilizados en el registro original (RF-014). | P36: CA-01: Dado un documento de comparación válido, cuando se procesa, entonces el sistema obtiene su huella SHA-256. | Q36: RF-029 | R36: RF-031
A37: RF-031 | B37: Comparación de huellas | C37: 2.0 | D37: 46265 | E37: Laura Sofia Diaz Suarez; Sofia Ortiz Daza | F37: Permite al verificador ejecutar la comparación entre la huella criptográfica registrada y la huella generada a partir del documento cargado. | G37: Verificador | H37: Es la operación central de verificación de integridad documental del sistema. | I37: Debe (Must) | J37: Alta | K37: Aprobado | L37: Se cuenta con la huella registrada (RF-026) y la huella del documento cargado (RF-030). | M37: El verificador selecciona Comparar. | N37: 1. El sistema toma ambas huellas. 2. El sistema ejecuta la comparación byte a byte de los valores hash. 3. El sistema continúa con RF-032. | O37: RN-01: La comparación es exclusivamente entre los valores hash, nunca entre los contenidos de los archivos. | P37: CA-01: Dado dos huellas idénticas, cuando se comparan, entonces el resultado es coinciden. CA-02: Dado dos huellas distintas, cuando se comparan, entonces el resultado es no coinciden. | Q37: RF-026, RF-030 | R37: RF-032
A38: RF-032 | B38: Resultado de la verificación | C38: 2.0 | D38: 46265 | E38: Laura Sofia Diaz Suarez; Sofia Ortiz Daza | F38: Determina automáticamente el resultado de la comparación y muestra si la integridad del documento es confirmada o comprometida. | G38: Verificador | H38: Traduce el resultado técnico de la comparación (RF-031) en un mensaje comprensible para el usuario, conforme a RNF-15. | I38: Debe (Must) | J38: Alta | K38: Aprobado | L38: La comparación fue ejecutada (RF-031). | M38: El sistema concluye la comparación de huellas. | N38: 1. El sistema evalúa el resultado de la comparación. 2. Si las huellas coinciden, muestra Integridad confirmada; si no coinciden, muestra Integridad comprometida. | O38: RN-01: El resultado solo puede ser confirmada o comprometida, sin estados intermedios. | P38: CA-01: Dado un resultado de comparación positivo, cuando se muestra, entonces el mensaje indica integridad confirmada. | Q38: RF-031 | R38: RF-033, RF-034
A39: RF-033 | B39: Visualización de evidencia | C39: 2.0 | D39: 46265 | E39: Laura Sofia Diaz Suarez; Sofia Ortiz Daza | F39: Muestra al verificador la huella criptográfica original y la huella criptográfica obtenida del documento actual como evidencia del resultado de la comparación. | G39: Verificador | H39: Refuerza el valor probatorio del resultado al exhibir ambas evidencias, en línea con RNF-17. | I39: Debería (Should) | J39: Media | K39: Aprobado | L39: El resultado de la verificación fue determinado (RF-032). | M39: El sistema muestra el resultado de la verificación. | N39: 1. El sistema presenta lado a lado la huella original y la huella obtenida. 2. El verificador puede revisar ambos valores. | O39: RN-01: Ambas huellas se muestran completas cuando el usuario tiene el rol autorizado (RF-027). | P39: CA-01: Dado un resultado de verificación, cuando se visualiza, entonces se muestran ambas huellas comparadas. | Q39: RF-032 | R39: Ninguno
A40: RF-034 | B40: Actualización del estado | C40: 2.0 | D40: 46265 | E40: Laura Sofia Diaz Suarez; Sofia Ortiz Daza | F40: Actualiza automáticamente el estado del documento a Verificado cuando las huellas coincidan o a Alterado cuando las huellas sean diferentes. | G40: Verificador / Empleado | H40: Mantiene consistente el estado visible del documento (RF-020) con el resultado real de la última verificación. | I40: Debe (Must) | J40: Alta | K40: Aprobado | L40: El resultado de la verificación fue determinado (RF-032). | M40: El sistema concluye la evaluación del resultado. | N40: 1. El sistema toma el resultado de la comparación. 2. El sistema actualiza el campo estado del documento en la base de datos. | O40: RN-01: El estado se actualiza automáticamente; no puede modificarse manualmente por ningún rol. | P40: CA-01: Dado un resultado no coinciden, cuando se procesa, entonces el estado del documento cambia a Alterado. | Q40: RF-032 | R40: Ninguno
A41: RF-035 | B41: Registro de la verificación | C41: 2.0 | D41: 46265 | E41: Laura Sofia Diaz Suarez; Sofia Ortiz Daza | F41: Registra en la trazabilidad la acción de verificación, el usuario que la realizó, la fecha y hora, el identificador de transacción (txID) generado en Hyperledger Fabric, y el resultado obtenido. | G41: Verificador | H41: El campo txID se agrega por la misma razón indicada en RF-022, para dar soporte a RNF-27. | I41: Debe (Must) | J41: Alta | K41: Propuesto | L41: El estado del documento fue actualizado (RF-034). | M41: El sistema concluye la actualización de estado. | N41: 1. El sistema envía al chaincode el evento de verificación con su resultado. 2. El chaincode registra el evento en el ledger y retorna un txID. | O41: RN-01: Todo proceso de verificación genera un evento en el ledger, independientemente de su resultado. | P41: CA-01: Dado que una verificación concluyó, cuando se registra, entonces el ledger contiene el evento con su txID y resultado. | Q41: RF-034 | R41: RF-036 | S41: Nota de cambio (v2): se agrega el campo txID respecto a la v1.
...

Sheet RNF
A1: Requisitos no funcionales
A2: Una fila por requisito. La característica de calidad se deriva de la subcaracterística elegida (ISO/IEC 25010:2023).
A3: La fila 7 es un ejemplo: sobrescríbela o bórrala antes de entregar. Sin métrica, unidad y umbral el requisito no es verificable.
A5: IDENTIFICACIÓN | F5: 1. CONTEXTO Y JUSTIFICACIÓN | I5: 2. CLASIFICACIÓN | N5: 3. ESPECIFICACIÓN DE LA MEDIDA | S5: 4. RELACIONES
A6: ID del requisito | B6: Título | C6: Versión | D6: Fecha de versión | E6: Autor | F6: Descripción general | G6: Fuente o parte interesada | H6: Justificación | I6: Característica ISO/IEC 25010:2023 | J6: Subcaracterística ISO/IEC 25010:2023 | K6: Prioridad (MoSCoW) | L6: Importancia | M6: Estado | N6: Métrica | O6: Unidad de medida | P6: Umbral de aceptación | Q6: Condición de medición | R6: Método de verificación | S6: Requisitos funcionales afectados | T6: Dependencias | U6: Comentarios
A7: RNF-001 | B7: Protección de contraseñas mediante hashing seguro | C7: 2.0 | D7: 46265 | E7: Laura Sofia Diaz Suarez; Sofia Ortiz Daza | F7: Las contraseñas se almacenan utilizando un mecanismo de hashing seguro con sal, nunca en texto plano. | G7: Área de TI - Seguridad de la información | H7: Previene la exposición de credenciales ante un acceso no autorizado a la base de datos, conforme a buenas prácticas de seguridad de la información referenciadas en el Anexo A de ISO/IEC 27001:2022 [23]. | I7: =IFERROR(INDEX(Listas!$B$7:$B$46,MATCH(J7,Listas!$A$7:$A$46,0)),"") -> Seguridad (security) | J7: Confidencialidad | K7: Debe (Must) | L7: Alta | M7: Aprobado | N7: Verificación binaria de que el campo de contraseña almacenado corresponde a un hash con sal (no a texto plano) | O7: Cumple / No cumple | P7: Cumple (100 % de las contraseñas almacenadas como hash con sal, mediante bcrypt) | Q7: Inspección de la base de datos de usuarios en el entorno de pruebas Docker | R7: Inspección | S7: RF-002, RF-045, RF-052, RF-053 | T7: Ninguna | U7: BCRYPT incorpora automáticamente sal y múltiples iteraciones, según se define en el glosario del proyecto.
A8: RNF-002 | B8: Autenticación de doble factor | C8: 2.0 | D8: 46265 | E8: Laura Sofia Diaz Suarez; Sofia Ortiz Daza | F8: El sistema implementa autenticación mediante credenciales y un segundo factor de verificación mediante token. | G8: Área de TI - Seguridad de la información | H8: Se mantiene sin cambios respecto a la v1, sujeta a la misma validación pendiente indicada en RF-003 sobre el canal exclusivo de token por correo, y se alinea con el Decreto 2364 de 2012, que reconoce la validez de mecanismos tecnológicos de autenticación como la firma electrónica [36]. | I8: =IFERROR(INDEX(Listas!$B$7:$B$46,MATCH(J8,Listas!$A$7:$A$46,0)),"") -> Seguridad (security) | J8: Autenticidad | K8: Debe (Must) | L8: Alta | M8: Propuesto | N8: Verificación de que el acceso requiere credenciales válidas y un token de segundo factor vigente | O8: Cumple / No cumple | P8: Cumple (100 % de los inicios de sesión exigen ambos factores) | Q8: Prueba funcional del flujo de autenticación (RF-002 a RF-005) en el entorno Docker de pruebas | R8: Prueba | S8: RF-002, RF-003, RF-004, RF-005 | T8: Ninguna | U8: Pendiente de validar con el tutor si el canal exclusivo de correo corporativo es suficiente o si se debe evaluar un canal alterno.
A9: RNF-003 | B9: Control de acceso basado en roles (RBAC) | C9: 2.0 | D9: 46265 | E9: Laura Sofia Diaz Suarez; Sofia Ortiz Daza | F9: El sistema aplica un esquema de control de acceso basado en roles, garantizando que cada usuario únicamente pueda acceder a las funcionalidades y datos autorizados para su rol. | G9: Área de TI - Seguridad de la información | H9: Es un control fundamental de acceso lógico alineado con el Anexo A de ISO/IEC 27001:2022, tomado como referencia de diseño en el proyecto [23]. | I9: =IFERROR(INDEX(Listas!$B$7:$B$46,MATCH(J9,Listas!$A$7:$A$46,0)),"") -> Seguridad (security) | J9: Confidencialidad | K9: Debe (Must) | L9: Alta | M9: Aprobado | N9: Porcentaje de intentos de acceso a funcionalidades no autorizadas para el rol que son bloqueados | O9: Porcentaje (%) | P9: 100 % de los intentos no autorizados bloqueados | Q9: Suite de pruebas funcionales de caja negra ejecutando los tres roles sobre los cinco módulos del sistema | R9: Prueba | S9: RF-005, RF-006, RF-023, RF-027, RF-041 a RF-051 | T9: RNF-002
A10: RNF-004 | B10: No almacenamiento del contenido documental en blockchain | C10: 2.0 | D10: 46265 | E10: Laura Sofia Diaz Suarez; Sofia Ortiz Daza | F10: El sistema no almacena el contenido de los contratos laborales ni acuerdos de confidencialidad directamente en la red blockchain. La blockchain almacena únicamente las huellas criptográficas y los eventos necesarios para la trazabilidad. | G10: Alcance técnico del proyecto | H10: Corresponde directamente al modelo de persistencia definido en el proyecto y responde a las exigencias de minimización de datos de la Ley 1581 de 2012 [9]. | I10: =IFERROR(INDEX(Listas!$B$7:$B$46,MATCH(J10,Listas!$A$7:$A$46,0)),"") -> Seguridad (security) | J10: Confidencialidad | K10: Debe (Must) | L10: Alta | M10: Aprobado | N10: Verificación de que ningún registro del ledger contiene el contenido binario o textual del documento | O10: Cumple / No cumple | P10: Cumple (0 documentos con contenido almacenado en el ledger) | Q10: Inspección del ledger de Hyperledger Fabric tras el registro de los 20 documentos sintéticos de prueba | R10: Inspección | S10: RF-013, RF-016 | T10: Ninguna
A11: RNF-005 | B11: Inmutabilidad de las huellas registradas | C11: 2.0 | D11: 46265 | E11: Laura Sofia Diaz Suarez; Sofia Ortiz Daza | F11: Las huellas criptográficas registradas en la blockchain se conservan de manera inmutable, de forma que no puedan ser modificadas mediante las operaciones normales del sistema. | G11: Alcance técnico del proyecto | H11: Es la propiedad central de la infraestructura blockchain permisionada, base de la validez probatoria exigida por la Ley 527 de 1999 [10]. La reciente jurisprudencia de la Corte Suprema de Justicia (Sentencia SP248-2025) confirma que la ausencia de un hash no invalida la evidencia digital, pero sí afecta su fuerza probatoria, lo que refuerza la importancia de este control [7]. | I11: =IFERROR(INDEX(Listas!$B$7:$B$46,MATCH(J11,Listas!$A$7:$A$46,0)),"") -> Seguridad (security) | J11: Integridad | K11: Debe (Must) | L11: Alta | M11: Aprobado | N11: Porcentaje de intentos de modificación de una huella ya registrada que son rechazados por el sistema | O11: Porcentaje (%) | P11: 100 % de los intentos de modificación rechazados | Q11: Pruebas de mutación documental sobre los 20 documentos sintéticos, intentando alterar registros ya confirmados en el ledger | R11: Prueba | S11: RF-016, RF-026 | T11: Ninguna
A12: RNF-006 | B12: Registro de operaciones relevantes | C12: 2.0 | D12: 46265 | E12: Laura Sofia Diaz Suarez; Sofia Ortiz Daza | F12: El sistema registra las operaciones relevantes realizadas sobre los documentos, incluyendo usuario, acción, fecha, hora y resultado cuando corresponda. | G12: Alcance técnico del proyecto | H12: Sustenta la trazabilidad documental exigida por el alcance del proyecto y por RNF-26. | I12: =IFERROR(INDEX(Listas!$B$7:$B$46,MATCH(J12,Listas!$A$7:$A$46,0)),"") -> Seguridad (security) | J12: Rendición de cuentas | K12: Debe (Must) | L12: Alta | M12: Aprobado | N12: Porcentaje de operaciones sobre documentos (registro, verificación) que generan un evento de trazabilidad | O12: Porcentaje (%) | P12: 100 % de las operaciones generan evento de trazabilidad | Q12: Prueba de trazabilidad e inmutabilidad, comparando las acciones ejecutadas contra el historial recuperado del ledger | R12: Prueba | S12: RF-016, RF-035 | T12: RNF-005
A13: RNF-007 | B13: Gestión segura de sesiones | C13: 2.0 | D13: 46265 | E13: Laura Sofia Diaz Suarez; Sofia Ortiz Daza | F13: El sistema gestiona las sesiones de usuario de manera segura e impide el acceso a funcionalidades protegidas una vez finalizada la sesión. | G13: Área de TI - Seguridad de la información | H13: Complementa el control de acceso (RNF-03) evitando el uso de sesiones expiradas o cerradas para acceder a información sensible. | I13: =IFERROR(INDEX(Listas!$B$7:$B$46,MATCH(J13,Listas!$A$7:$A$46,0)),"") -> Seguridad (security) | J13: Confidencialidad | K13: Debe (Must) | L13: Alta | M13: Aprobado | N13: Verificación de que una sesión cerrada o expirada no permite acceder a funcionalidades protegidas | O13: Cumple / No cumple | P13: Cumple (0 accesos exitosos con sesión cerrada o expirada) | Q13: Prueba funcional de caja negra sobre RF-007, cerrando sesión e intentando acceder a rutas protegidas | R13: Prueba | S13: RF-007 | T13: RNF-002
A14: RNF-008 | B14: Limitación de exposición de información documental | C14: 2.0 | D14: 46265 | E14: Laura Sofia Diaz Suarez; Sofia Ortiz Daza | F14: El sistema limita la exposición de información documental y de las huellas criptográficas de acuerdo con los permisos establecidos para cada rol. | G14: Área de TI - Seguridad de la información | H14: Da cumplimiento a los principios de finalidad y minimización de la Ley 1581 de 2012 [9] y a los lineamientos de la Circular Externa 005 de 2017 de la Superintendencia de Industria y Comercio [8], además del control A.8.24 del Anexo A de ISO/IEC 27001:2022 [23]. | I14: =IFERROR(INDEX(Listas!$B$7:$B$46,MATCH(J14,Listas!$A$7:$A$46,0)),"") -> Seguridad (security) | J14: Confidencialidad | K14: Debe (Must) | L14: Alta | M14: Aprobado | N14: Porcentaje de campos restringidos (huella completa, datos de otros usuarios) que no son visibles para roles no autorizados | O14: Porcentaje (%) | P14: 100 % de los campos restringidos ocultos para roles no autorizados | Q14: Prueba funcional de caja negra sobre RF-018, RF-027 y RF-038 con los tres roles | R14: Prueba | S14: RF-018, RF-027, RF-038, RF-049 | T14: RNF-003
A15: RNF-009 | B15: Tiempo de respuesta de las operaciones principales | C15: 2.0 | D15: 46265 | E15: Laura Sofia Diaz Suarez; Sofia Ortiz Daza | F15: El sistema responde a las operaciones principales de consulta y verificación en un tiempo adecuado para garantizar una interacción fluida con el usuario. | G15: Verificador / Empleado | H15: Sustenta la usabilidad general del sistema (RNF-15) y se detalla de forma cuantitativa en RNF-10 para la operación crítica de verificación. | I15: =IFERROR(INDEX(Listas!$B$7:$B$46,MATCH(J15,Listas!$A$7:$A$46,0)),"") -> Eficiencia de desempeño | J15: Comportamiento temporal | K15: Debería (Should) | L15: Media | M15: Aprobado | N15: Tiempo de respuesta percibido en las operaciones de consulta de documentos y trazabilidad | O15: Milisegundos (ms) | P15: Menor o igual a 3.000 ms | Q15: 50 peticiones consecutivas sobre el entorno Docker local de pruebas | R15: Prueba | S15: RF-018, RF-021, RF-037, RF-039 | T15: Ninguna | U15: Se alinea con el mismo umbral definido para RNF-10, tomado del KPI del proyecto (Tabla 1).
A16: RNF-010 | B16: Latencia de la verificación de integridad | C16: 2.0 | D16: 46265 | E16: Laura Sofia Diaz Suarez; Sofia Ortiz Daza | F16: La operación de verificación de integridad cumple como meta un percentil 95 de latencia igual o inferior a 3.000 ms en 50 peticiones consecutivas, de acuerdo con el KPI definido en el proyecto. | G16: KPI OE3 del proyecto (Tabla 1) | H16: Corresponde directamente al KPI Percentil 95 (P95) de latencia del endpoint de verificación definido para el objetivo específico de desarrollo del MVP. | I16: =IFERROR(INDEX(Listas!$B$7:$B$46,MATCH(J16,Listas!$A$7:$A$46,0)),"") -> Eficiencia de desempeño | J16: Comportamiento temporal | K16: Debe (Must) | L16: Alta | M16: Aprobado | N16: Percentil 95 (P95) de la latencia del endpoint de verificación (RF-031) | O16: Milisegundos (ms) | P16: P95 ≤ 3.000 ms | Q16: 50 peticiones consecutivas sobre el endpoint de verificación en el entorno Docker local | R16: Prueba | S16: RF-028 a RF-034 | T16: RNF-009
A17: RNF-011 | B17: Automatización del cálculo de huellas | C17: 2.0 | D17: 46265 | E17: Laura Sofia Diaz Suarez; Sofia Ortiz Daza | F17: La generación y comparación de las huellas SHA-256 se realiza de manera automática sin requerir intervención manual del usuario. | G17: Alcance técnico del proyecto | H17: Reduce el riesgo de error humano en el cálculo de la evidencia de integridad, reforzando la propiedad de efecto avalancha de SHA-256 [34]. | I17: =IFERROR(INDEX(Listas!$B$7:$B$46,MATCH(J17,Listas!$A$7:$A$46,0)),"") -> Eficiencia de desempeño | J17: Comportamiento temporal | K17: Debe (Must) | L17: Alta | M17: Aprobado | N17: Verificación de que el usuario no ejecuta ningún paso manual durante el cálculo o la comparación de huellas | O17: Cumple / No cumple | P17: Cumple (0 pasos manuales requeridos en el cálculo de huellas) | Q17: Revisión del flujo de RF-014 y RF-030 en el entorno de pruebas | R17: Inspección | S17: RF-014, RF-030 | T17: Ninguna
A18: RNF-012 | B18: Disponibilidad durante el periodo de pruebas | C18: 2.0 | D18: 46265 | E18: Laura Sofia Diaz Suarez; Sofia Ortiz Daza | F18: El sistema permanece disponible durante el periodo definido para las pruebas y validación del MVP. | G18: Alcance del proyecto (despliegue en Microsoft Azure) | H18: El despliegue en Azure se realiza durante un periodo de prueba de un mes; su disponibilidad es necesaria para ejecutar el plan de pruebas de software (PPS). | I18: =IFERROR(INDEX(Listas!$B$7:$B$46,MATCH(J18,Listas!$A$7:$A$46,0)),"") -> Fiabilidad | J18: Disponibilidad | K18: Debería (Should) | L18: Media | M18: Aprobado | N18: Porcentaje de tiempo en que el sistema responde correctamente durante el periodo de validación | O18: Porcentaje (%) | P18: Mayor o igual a 95 % durante el mes de pruebas | Q18: Monitoreo del entorno desplegado en la máquina virtual de Azure durante la fase 4 del proyecto | R18: Prueba | S18: Todos los módulos funcionales | T18: Ninguna | U18: No aplica para un entorno productivo; corresponde exclusivamente a la validación del MVP.
A19: RNF-013 | B19: Consistencia entre MongoDB y Hyperledger Fabric | C19: 2.0 | D19: 46265 | E19: Laura Sofia Diaz Suarez; Sofia Ortiz Daza | F19: La información registrada en la base de datos no relacional (MongoDB) y la evidencia almacenada en la red blockchain permisionada (Hyperledger Fabric) mantienen correspondencia respecto a los documentos, identificadores y eventos registrados. | G19: Alcance técnico del proyecto | H19: Se reemplaza el término genérico base de datos por base de datos no relacional (MongoDB) y se nombra explícitamente Hyperledger Fabric, para anclar el requerimiento al marco tecnológico definido en el proyecto. | I19: =IFERROR(INDEX(Listas!$B$7:$B$46,MATCH(J19,Listas!$A$7:$A$46,0)),"") -> Adecuación funcional | J19: Corrección funcional | K19: Debe (Must) | L19: Alta | M19: Propuesto | N19: Porcentaje de documentos cuyo identificador y huella coinciden entre MongoDB y el ledger de Hyperledger Fabric | O19: Porcentaje (%) | P19: 100 % de correspondencia | Q19: Comparación cruzada de los 20 documentos sintéticos entre la base de datos y el ledger, al cierre de las pruebas de integridad | R19: Prueba | S19: RF-013, RF-015, RF-016 | T19: Ninguna | U19: Nota de cambio (v2) respecto a la v1.
A20: RNF-014 | B20: Detección de alteraciones documentales | C20: 2.0 | D20: 46265 | E20: Laura Sofia Diaz Suarez; Sofia Ortiz Daza | F20: El sistema detecta las alteraciones realizadas sobre los documentos utilizados durante las pruebas de integridad. Como meta del proyecto, debe detectar el 100 % de las alteraciones realizadas sobre los 20 documentos definidos para la validación. | G20: KPI OE4 del proyecto (Tabla 1) | H20: Corresponde directamente al KPI Tasa de detección de alteraciones documentales y se respalda en los resultados reportados por Mier Bello et al., quienes lograron una tasa de detección del 100 % en un sistema análogo basado en blockchain [30]. | I20: =IFERROR(INDEX(Listas!$B$7:$B$46,MATCH(J20,Listas!$A$7:$A$46,0)),"") -> Adecuación funcional | J20: Corrección funcional | K20: Debe (Must) | L20: Alta | M20: Aprobado | N20: Tasa de detección de alteraciones sobre el conjunto de documentos sintéticos alterados | O20: Porcentaje (%) | P20: 100 % de los 20 documentos alterados detectados como no íntegros | Q20: Pruebas de mutación documental (cambios en texto, firmas y metadatos) sobre los 20 documentos sintéticos definidos en el plan de pruebas | R20: Prueba | S20: RF-031, RF-032, RF-034 | T20: RNF-005
